Workbook
Name _____I2: {"PVGraph2",#N/A,FALSE,"PV Data"}
Name _____I3: {"PVGraph2",#N/A,FALSE,"PV Data"}
Name _____w1: {"PVGraph2",#N/A,FALSE,"PV Data"}
Name _____w2: {"PVGraph2",#N/A,FALSE,"PV Data"}
Name _____w3: {"PVGraph2",#N/A,FALSE,"PV Data"}
Name _____y2: {"PVGraph2",#N/A,FALSE,"PV Data"}
Name ___I2: {"PVGraph2",#N/A,FALSE,"PV Data"}
Name ___I3: {"PVGraph2",#N/A,FALSE,"PV Data"}
Name ___w1: {"PVGraph2",#N/A,FALSE,"PV Data"}
Name ___w2: {"PVGraph2",#N/A,FALSE,"PV Data"}
Name ___w3: {"PVGraph2",#N/A,FALSE,"PV Data"}
Name ___y2: {"PVGraph2",#N/A,FALSE,"PV Data"}
Name __FDS_HYPERLINK_TOGGLE_STATE__: "ON"
Name __IntlFixup: TRUE
Name __QTD1: {"Nil","Nil",FALSE,"Detail P&L-M";"Nil","Nil",FALSE,"Dep & Amort-M";"Nil","Nil",FALSE,"Equity-M";"Nil","Nil",FALSE,"Debt & Cash Flow-M";"Nil","Nil",FALSE,"Interest-M"}
Name _ass1: {#N/A,#N/A,FALSE,"Aging Summary";#N/A,#N/A,FALSE,"Ratio Analysis";#N/A,#N/A,FALSE,"Test 120 Day Accts";#N/A,#N/A,FALSE,"Tickmarks"}
Name _I2: {"PVGraph2",#N/A,FALSE,"PV Data"}
Name _I3: {"PVGraph2",#N/A,FALSE,"PV Data"}
Name _new2: {"COM1996",#N/A,FALSE,"ANNUAL COMMISSIONS";"COM1997",#N/A,FALSE,"ANNUAL COMMISSIONS"}
Name _new3: {"COM1996",#N/A,FALSE,"ANNUAL COMMISSIONS";"COM1997",#N/A,FALSE,"ANNUAL COMMISSIONS"}
Name _Order1: 255
Name _Order1a: 0
Name _Order2: 255
Name _QTD1: {"Nil","Nil",FALSE,"Detail P&L-M";"Nil","Nil",FALSE,"Dep & Amort-M";"Nil","Nil",FALSE,"Equity-M";"Nil","Nil",FALSE,"Debt & Cash Flow-M";"Nil","Nil",FALSE,"Interest-M"}
Name _Regression_Int: 1
Name _rod1: {#N/A,#N/A,FALSE,"Projections";#N/A,#N/A,FALSE,"Multiples Valuation";#N/A,#N/A,FALSE,"LBO";#N/A,#N/A,FALSE,"Multiples_Sensitivity";#N/A,#N/A,FALSE,"Summary"}
Name _SDU2: {#N/A,#N/A,FALSE,"Aging Summary";#N/A,#N/A,FALSE,"Ratio Analysis";#N/A,#N/A,FALSE,"Test 120 Day Accts";#N/A,#N/A,FALSE,"Tickmarks"}
Name _w1: {"PVGraph2",#N/A,FALSE,"PV Data"}
Name _w2: {"PVGraph2",#N/A,FALSE,"PV Data"}
Name _w3: {"PVGraph2",#N/A,FALSE,"PV Data"}
Name _wrn2: {#N/A,#N/A,FALSE,"ASSUMPTIONS";#N/A,#N/A,FALSE,"Valuation Summary";"page1",#N/A,FALSE,"PRESENTATION";"page2",#N/A,FALSE,"PRESENTATION";#N/A,#N/A,FALSE,"ORIGINAL_ROLLBACK"}
Name _wrn3: {#N/A,#N/A,FALSE,"ASSUMPTIONS";#N/A,#N/A,FALSE,"Valuation Summary";"page1",#N/A,FALSE,"PRESENTATION";"page2",#N/A,FALSE,"PRESENTATION";#N/A,#N/A,FALSE,"ORIGINAL_ROLLBACK"}
Name _x1: {#N/A,#N/A,FALSE,"FY97";#N/A,#N/A,FALSE,"FY98";#N/A,#N/A,FALSE,"FY99";#N/A,#N/A,FALSE,"FY00";#N/A,#N/A,FALSE,"FY01"}
Name _y2: {"PVGraph2",#N/A,FALSE,"PV Data"}
Name a: {#N/A,#N/A,FALSE,"Projections";#N/A,#N/A,FALSE,"Multiples Valuation";#N/A,#N/A,FALSE,"LBO";#N/A,#N/A,FALSE,"Multiples_Sensitivity";#N/A,#N/A,FALSE,"Summary"}
Name aa: {#N/A,#N/A,FALSE,"Projections";#N/A,#N/A,FALSE,"Multiples Valuation";#N/A,#N/A,FALSE,"LBO";#N/A,#N/A,FALSE,"Multiples_Sensitivity";#N/A,#N/A,FALSE,"Summary"}
Name aaa: {#N/A,#N/A,FALSE,"Projections";#N/A,#N/A,FALSE,"Multiples Valuation";#N/A,#N/A,FALSE,"LBO";#N/A,#N/A,FALSE,"Multiples_Sensitivity";#N/A,#N/A,FALSE,"Summary"}
Name AAA_DOCTOPS: "AAA_SET"
Name AAA_duser: "OFF"
Name aaaaaaa: {"Outflow 1",#N/A,FALSE,"Outflows-Inflows";"Outflow 2",#N/A,FALSE,"Outflows-Inflows";"Inflow 1",#N/A,FALSE,"Outflows-Inflows";"Inflow 2",#N/A,FALSE,"Outflows-Inflows"}
Name AAB_Addin5: "AAB_Description for addin 5,Description for addin 5,Description for addin 5,Description for addin 5,Description for addin 5,Description for addin 5"
Name AAB_GSPPG: "AAB_Goldman Sachs PPG Chart Utilities 1.0g"
Name aabb: {#N/A,#N/A,FALSE,"Projections";#N/A,#N/A,FALSE,"Multiples Valuation";#N/A,#N/A,FALSE,"LBO";#N/A,#N/A,FALSE,"Multiples_Sensitivity";#N/A,#N/A,FALSE,"Summary"}
Name aas: "c4426"
Name aasdfa: {"rtn",#N/A,FALSE,"RTN";"tables",#N/A,FALSE,"RTN";"cf",#N/A,FALSE,"CF";"stats",#N/A,FALSE,"Stats";"prop",#N/A,FALSE,"Prop"}
Name AccessDatabase: "C:\DATA\Kevin\Kevin's Model.mdb"
Name ads: {#N/A,#N/A,FALSE,"AD_Purch";#N/A,#N/A,FALSE,"Projections";#N/A,#N/A,FALSE,"DCF";#N/A,#N/A,FALSE,"Mkt Val"}
Name adsf: {#N/A,#N/A,FALSE,"AD_Purch";#N/A,#N/A,FALSE,"Projections";#N/A,#N/A,FALSE,"DCF";#N/A,#N/A,FALSE,"Mkt Val"}
Name Annual: {"Outflow 1",#N/A,FALSE,"Outflows-Inflows";"Outflow 2",#N/A,FALSE,"Outflows-Inflows";"Inflow 1",#N/A,FALSE,"Outflows-Inflows";"Inflow 2",#N/A,FALSE,"Outflows-Inflows"}
Name anscount: 1
Name argqe: {#N/A,#N/A,FALSE,"puboff";#N/A,#N/A,FALSE,"financials";#N/A,#N/A,FALSE,"valuation";#N/A,#N/A,FALSE,"split"}
Name as: {"Outflow 1",#N/A,FALSE,"Outflows-Inflows";"Outflow 2",#N/A,FALSE,"Outflows-Inflows";"Inflow 1",#N/A,FALSE,"Outflows-Inflows";"Inflow 2",#N/A,FALSE,"Outflows-Inflows"}
Name AS2DocOpenMode: "AS2DocumentEdit"
Name AS2NamedRange: 196
Name AS2ReportLS: 1
Name AS2SyncStepLS: 0
Name AS2VersionLS: 300
Name asdf: 40379.4506944444
Name asdfas: {"print 1.6",#N/A,FALSE,"Sheet1";"print 2.6",#N/A,FALSE,"Sheet1";"print 3.6",#N/A,FALSE,"Sheet1";"print 4.6",#N/A,FALSE,"Sheet1";"print 5.6",#N/A,FALSE,"Sheet1";"print 6.6",#N/A,FALSE,"Sheet1"}
Name asdfasaa: {"print 1.6",#N/A,FALSE,"Sheet1";"print 2.6",#N/A,FALSE,"Sheet1";"print 3.6",#N/A,FALSE,"Sheet1";"print 4.6",#N/A,FALSE,"Sheet1";"print 5.6",#N/A,FALSE,"Sheet1";"print 6.6",#N/A,FALSE,"Sheet1"}

Sheet COO P&L
A1: Total COO Departments
A2: 2026 Actuals/Forecast & 2027 Budget
B7: Actual | C7: Actual | D7: Actual | E7: Actual | F7: Actual | G7: Actual | H7: Actual | I7: Actual | J7: Forecast | K7: Forecast | L7: Forecast | M7: Forecast | N7: Forecast | O7: Forecast | U7: Budget | V7: Budget | W7: Budget | X7: Budget | Y7: Budget | Z7: Budget | AA7: Budget | AB7: Budget | AC7: Budget | AD7: Budget | AE7: Budget | AF7: Budget | AG7: Budget | AH7: Budget | AJ7: YOY
B8: Jan | C8: Feb | D8: Mar | E8: Apr | F8: May | G8: Jun | H8: Jul | I8: Aug | J8: Sep | K8: Oct | L8: Nov | M8: Dec | N8: 2026 | O8: % Total Rev | U8: Jan | V8: Feb | W8: Mar | X8: Apr | Y8: May | Z8: Jun | AA8: Jul | AB8: Aug | AC8: Sep | AD8: Oct | AE8: Nov | AF8: Dec | AG8: 2027 | AH8: % Total Rev | AJ8: Fav / (Unfav)
A9: Ordinary Income/Expense
A10: Income
A11: 4000 - Sales
A12: 4100 - Subscription/Platform Fees | B12: =SUM(FO!B12,PO!B12,CO!B12,FE!B12,PE!B12) -> 534716.78 | C12: =SUM(FO!C12,PO!C12,CO!C12,FE!C12,PE!C12) -> 494949.28 | D12: =SUM(FO!D12,PO!D12,CO!D12,FE!D12,PE!D12) -> 468603.55 | E12: =SUM(FO!E12,PO!E12,CO!E12,FE!E12,PE!E12) -> 481426.2 | F12: =SUM(FO!F12,PO!F12,CO!F12,FE!F12,PE!F12) -> 501668.11 | G12: =SUM(FO!G12,PO!G12,CO!G12,FE!G12,PE!G12) -> 473687.43 | H12: =SUM(FO!H12,PO!H12,CO!H12,FE!H12,PE!H12) -> 454042.16 | I12: =SUM(FO!I12,PO!I12,CO!I12,FE!I12,PE!I12) -> 467055.56 | ... M12: =SUM(FO!M12,PO!M12,CO!M12,FE!M12,PE!M12) -> 676940.67 | N12: =SUM(B12:M12) -> 6363078.4 | O12: =IFERROR(N12/N$16,"") -> 0.85710267 | U12: =SUM(FO!U12,PO!U12,CO!U12,FE!U12,PE!U12) -> 0 | V12: =SUM(FO!V12,PO!V12,CO!V12,FE!V12,PE!V12) -> 0 | W12: =SUM(FO!W12,PO!W12,CO!W12,FE!W12,PE!W12) -> 0 | X12: =SUM(FO!X12,PO!X12,CO!X12,FE!X12,PE!X12) -> 0 | Y12: =SUM(FO!Y12,PO!Y12,CO!Y12,FE!Y12,PE!Y12) -> 0 | Z12: =SUM(FO!Z12,PO!Z12,CO!Z12,FE!Z12,PE!Z12) -> 0 | AA12: =SUM(FO!AA12,PO!AA12,CO!AA12,FE!AA12,PE!AA12) -> 0 | AB12: =SUM(FO!AB12,PO!AB12,CO!AB12,FE!AB12,PE!AB12) -> 0 | ... AF12: =SUM(FO!AF12,PO!AF12,CO!AF12,FE!AF12,PE!AF12) -> 0 | AG12: =SUM(U12:AF12) -> 0 | AH12: =IFERROR(AG12/AG$16,"") | AJ12: =AG12-N12 -> -6363078.4
A13: 4500 - Implementation Fees | B13: =SUM(FO!B13,PO!B13,CO!B13,FE!B13,PE!B13) -> 8277.78 | C13: =SUM(FO!C13,PO!C13,CO!C13,FE!C13,PE!C13) -> 8277.78 | D13: =SUM(FO!D13,PO!D13,CO!D13,FE!D13,PE!D13) -> 18277.78 | E13: =SUM(FO!E13,PO!E13,CO!E13,FE!E13,PE!E13) -> 18277.78 | F13: =SUM(FO!F13,PO!F13,CO!F13,FE!F13,PE!F13) -> 18277.78 | G13: =SUM(FO!G13,PO!G13,CO!G13,FE!G13,PE!G13) -> 6055.57 | H13: =SUM(FO!H13,PO!H13,CO!H13,FE!H13,PE!H13) -> 2166.67 | I13: =SUM(FO!I13,PO!I13,CO!I13,FE!I13,PE!I13) -> 4250 | ... M13: =SUM(FO!M13,PO!M13,CO!M13,FE!M13,PE!M13) -> 500 | N13: =SUM(B13:M13) -> 85861.14 | O13: =IFERROR(N13/N$16,"") -> 0.011565442 | U13: =SUM(FO!U13,PO!U13,CO!U13,FE!U13,PE!U13) -> 0 | V13: =SUM(FO!V13,PO!V13,CO!V13,FE!V13,PE!V13) -> 0 | W13: =SUM(FO!W13,PO!W13,CO!W13,FE!W13,PE!W13) -> 0 | X13: =SUM(FO!X13,PO!X13,CO!X13,FE!X13,PE!X13) -> 0 | Y13: =SUM(FO!Y13,PO!Y13,CO!Y13,FE!Y13,PE!Y13) -> 0 | Z13: =SUM(FO!Z13,PO!Z13,CO!Z13,FE!Z13,PE!Z13) -> 0 | AA13: =SUM(FO!AA13,PO!AA13,CO!AA13,FE!AA13,PE!AA13) -> 0 | AB13: =SUM(FO!AB13,PO!AB13,CO!AB13,FE!AB13,PE!AB13) -> 0 | ... AF13: =SUM(FO!AF13,PO!AF13,CO!AF13,FE!AF13,PE!AF13) -> 0 | AG13: =SUM(U13:AF13) -> 0 | AH13: =IFERROR(AG13/AG$16,"") | AJ13: =AG13-N13 -> -85861.14
A14: Total - 4000 - Sales | B14: =SUM(B12:B13) -> 542994.56 | C14: =SUM(C12:C13) -> 503227.06 | D14: =SUM(D12:D13) -> 486881.33 | E14: =SUM(E12:E13) -> 499703.98 | F14: =SUM(F12:F13) -> 519945.89 | G14: =SUM(G12:G13) -> 479743 | H14: =SUM(H12:H13) -> 456208.83 | I14: =SUM(I12:I13) -> 471305.56 | ... M14: =SUM(M12:M13) -> 677440.67 | N14: =SUM(B14:M14) -> 6448939.5 | O14: =SUM(O12:O13) -> 0.86866811 | U14: =SUM(U12:U13) -> 0 | V14: =SUM(V12:V13) -> 0 | W14: =SUM(W12:W13) -> 0 | X14: =SUM(X12:X13) -> 0 | Y14: =SUM(Y12:Y13) -> 0 | Z14: =SUM(Z12:Z13) -> 0 | AA14: =SUM(AA12:AA13) -> 0 | AB14: =SUM(AB12:AB13) -> 0 | ... AF14: =SUM(AF12:AF13) -> 0 | AG14: =SUM(U14:AF14) -> 0 | AH14: =SUM(AH12:AH13) -> 0 | AJ14: =AG14-N14 -> -6448939.5
A15: 4900 - One-Time Revenue | B15: =SUM(FO!B15,PO!B15,CO!B15,FE!B15,PE!B15) -> 0 | C15: =SUM(FO!C15,PO!C15,CO!C15,FE!C15,PE!C15) -> 0 | D15: =SUM(FO!D15,PO!D15,CO!D15,FE!D15,PE!D15) -> 60000 | E15: =SUM(FO!E15,PO!E15,CO!E15,FE!E15,PE!E15) -> 250000 | F15: =SUM(FO!F15,PO!F15,CO!F15,FE!F15,PE!F15) -> 0 | G15: =SUM(FO!G15,PO!G15,CO!G15,FE!G15,PE!G15) -> 0 | H15: =SUM(FO!H15,PO!H15,CO!H15,FE!H15,PE!H15) -> 185000 | I15: =SUM(FO!I15,PO!I15,CO!I15,FE!I15,PE!I15) -> 0 | ... M15: =SUM(FO!M15,PO!M15,CO!M15,FE!M15,PE!M15) -> 120000 | N15: =SUM(B15:M15) -> 975000 | O15: =IFERROR(N15/N$16,"") -> 0.13133189 | U15: =SUM(FO!U15,PO!U15,CO!U15,FE!U15,PE!U15) -> 0 | V15: =SUM(FO!V15,PO!V15,CO!V15,FE!V15,PE!V15) -> 0 | W15: =SUM(FO!W15,PO!W15,CO!W15,FE!W15,PE!W15) -> 0 | X15: =SUM(FO!X15,PO!X15,CO!X15,FE!X15,PE!X15) -> 0 | Y15: =SUM(FO!Y15,PO!Y15,CO!Y15,FE!Y15,PE!Y15) -> 0 | Z15: =SUM(FO!Z15,PO!Z15,CO!Z15,FE!Z15,PE!Z15) -> 0 | AA15: =SUM(FO!AA15,PO!AA15,CO!AA15,FE!AA15,PE!AA15) -> 0 | AB15: =SUM(FO!AB15,PO!AB15,CO!AB15,FE!AB15,PE!AB15) -> 0 | ... AF15: =SUM(FO!AF15,PO!AF15,CO!AF15,FE!AF15,PE!AF15) -> 0 | AG15: =SUM(U15:AF15) -> 0 | AH15: =IFERROR(AG15/AG$16,"") | AJ15: =AG15-N15 -> -975000
A16: Total - Income | B16: =B14+B15 -> 542994.56 | C16: =C14+C15 -> 503227.06 | D16: =D14+D15 -> 546881.33 | E16: =E14+E15 -> 749703.98 | F16: =F14+F15 -> 519945.89 | G16: =G14+G15 -> 479743 | H16: =H14+H15 -> 641208.83 | I16: =I14+I15 -> 471305.56 | ... M16: =M14+M15 -> 797440.67 | N16: =SUM(B16:M16) -> 7423939.5 | O16: =SUM(O14:O15) -> 1 | U16: =U14+U15 -> 0 | V16: =V14+V15 -> 0 | W16: =W14+W15 -> 0 | X16: =X14+X15 -> 0 | Y16: =Y14+Y15 -> 0 | Z16: =Z14+Z15 -> 0 | AA16: =AA14+AA15 -> 0 | AB16: =AB14+AB15 -> 0 | ... AF16: =AF14+AF15 -> 0 | AG16: =SUM(U16:AF16) -> 0 | AH16: =SUM(AH14:AH15) -> 0 | AJ16: =AG16-N16 -> -7423939.5
A17: Cost Of Sales
A18: 5000 - Robot Production and Deployment
A19: 5010 - SlipBot Depreciation | B19: =SUM(FO!B19,PO!B19,CO!B19,FE!B19,PE!B19) -> 141122.35 | C19: =SUM(FO!C19,PO!C19,CO!C19,FE!C19,PE!C19) -> 122211.9 | D19: =SUM(FO!D19,PO!D19,CO!D19,FE!D19,PE!D19) -> 126630.2 | E19: =SUM(FO!E19,PO!E19,CO!E19,FE!E19,PE!E19) -> 128215.48 | F19: =SUM(FO!F19,PO!F19,CO!F19,FE!F19,PE!F19) -> 133968.64 | G19: =SUM(FO!G19,PO!G19,CO!G19,FE!G19,PE!G19) -> 133968.64 | H19: =SUM(FO!H19,PO!H19,CO!H19,FE!H19,PE!H19) -> 127510 | I19: =SUM(FO!I19,PO!I19,CO!I19,FE!I19,PE!I19) -> 127510 | ... M19: =SUM(FO!M19,PO!M19,CO!M19,FE!M19,PE!M19) -> 112797.85 | N19: =SUM(B19:M19) -> 1492328.6 | O19: =IFERROR(N19/N$16,"") -> 0.20101573 | U19: =SUM(FO!U19,PO!U19,CO!U19,FE!U19,PE!U19) -> 0 | V19: =SUM(FO!V19,PO!V19,CO!V19,FE!V19,PE!V19) -> 0 | W19: =SUM(FO!W19,PO!W19,CO!W19,FE!W19,PE!W19) -> 0 | X19: =SUM(FO!X19,PO!X19,CO!X19,FE!X19,PE!X19) -> 0 | Y19: =SUM(FO!Y19,PO!Y19,CO!Y19,FE!Y19,PE!Y19) -> 0 | Z19: =SUM(FO!Z19,PO!Z19,CO!Z19,FE!Z19,PE!Z19) -> 0 | AA19: =SUM(FO!AA19,PO!AA19,CO!AA19,FE!AA19,PE!AA19) -> 0 | AB19: =SUM(FO!AB19,PO!AB19,CO!AB19,FE!AB19,PE!AB19) -> 0 | ... AF19: =SUM(FO!AF19,PO!AF19,CO!AF19,FE!AF19,PE!AF19) -> 0 | AG19: =SUM(U19:AF19) -> 0 | AH19: =IFERROR(AG19/AG$16,"") | AJ19: =N19-AG19 -> 1492328.6
A20: 5011 - SlipLift Depreciation | B20: =SUM(FO!B20,PO!B20,CO!B20,FE!B20,PE!B20) -> 0 | C20: =SUM(FO!C20,PO!C20,CO!C20,FE!C20,PE!C20) -> 0 | D20: =SUM(FO!D20,PO!D20,CO!D20,FE!D20,PE!D20) -> 1677.96 | E20: =SUM(FO!E20,PO!E20,CO!E20,FE!E20,PE!E20) -> 3263.24 | F20: =SUM(FO!F20,PO!F20,CO!F20,FE!F20,PE!F20) -> 3263.24 | G20: =SUM(FO!G20,PO!G20,CO!G20,FE!G20,PE!G20) -> 11653.04 | H20: =SUM(FO!H20,PO!H20,CO!H20,FE!H20,PE!H20) -> 7458.14 | I20: =SUM(FO!I20,PO!I20,CO!I20,FE!I20,PE!I20) -> 9836.06 | ... M20: =SUM(FO!M20,PO!M20,CO!M20,FE!M20,PE!M20) -> 20444.9 | N20: =SUM(B20:M20) -> 100359.85 | O20: =IFERROR(N20/N$16,"") -> 0.013518409 | U20: =SUM(FO!U20,PO!U20,CO!U20,FE!U20,PE!U20) -> 0 | V20: =SUM(FO!V20,PO!V20,CO!V20,FE!V20,PE!V20) -> 0 | W20: =SUM(FO!W20,PO!W20,CO!W20,FE!W20,PE!W20) -> 0 | X20: =SUM(FO!X20,PO!X20,CO!X20,FE!X20,PE!X20) -> 0 | Y20: =SUM(FO!Y20,PO!Y20,CO!Y20,FE!Y20,PE!Y20) -> 0 | Z20: =SUM(FO!Z20,PO!Z20,CO!Z20,FE!Z20,PE!Z20) -> 0 | AA20: =SUM(FO!AA20,PO!AA20,CO!AA20,FE!AA20,PE!AA20) -> 0 | AB20: =SUM(FO!AB20,PO!AB20,CO!AB20,FE!AB20,PE!AB20) -> 0 | ... AF20: =SUM(FO!AF20,PO!AF20,CO!AF20,FE!AF20,PE!AF20) -> 0 | AG20: =SUM(U20:AF20) -> 0 | AH20: =IFERROR(AG20/AG$16,"") | AJ20: =N20-AG20 -> 100359.85
A21: 5012 - SlipCarrier Depreciation | B21: =SUM(FO!B21,PO!B21,CO!B21,FE!B21,PE!B21) -> 0 | C21: =SUM(FO!C21,PO!C21,CO!C21,FE!C21,PE!C21) -> 0 | D21: =SUM(FO!D21,PO!D21,CO!D21,FE!D21,PE!D21) -> 0 | E21: =SUM(FO!E21,PO!E21,CO!E21,FE!E21,PE!E21) -> 1791.23 | F21: =SUM(FO!F21,PO!F21,CO!F21,FE!F21,PE!F21) -> 3124.54 | G21: =SUM(FO!G21,PO!G21,CO!G21,FE!G21,PE!G21) -> 4796.43 | H21: =SUM(FO!H21,PO!H21,CO!H21,FE!H21,PE!H21) -> 3293.79 | I21: =SUM(FO!I21,PO!I21,CO!I21,FE!I21,PE!I21) -> 3909.48 | ... M21: =SUM(FO!M21,PO!M21,CO!M21,FE!M21,PE!M21) -> 6502.64 | N21: =SUM(B21:M21) -> 36992.697 | O21: =IFERROR(N21/N$16,"") -> 0.004982893 | U21: =SUM(FO!U21,PO!U21,CO!U21,FE!U21,PE!U21) -> 0 | V21: =SUM(FO!V21,PO!V21,CO!V21,FE!V21,PE!V21) -> 0 | W21: =SUM(FO!W21,PO!W21,CO!W21,FE!W21,PE!W21) -> 0 | X21: =SUM(FO!X21,PO!X21,CO!X21,FE!X21,PE!X21) -> 0 | Y21: =SUM(FO!Y21,PO!Y21,CO!Y21,FE!Y21,PE!Y21) -> 0 | Z21: =SUM(FO!Z21,PO!Z21,CO!Z21,FE!Z21,PE!Z21) -> 0 | AA21: =SUM(FO!AA21,PO!AA21,CO!AA21,FE!AA21,PE!AA21) -> 0 | AB21: =SUM(FO!AB21,PO!AB21,CO!AB21,FE!AB21,PE!AB21) -> 0 | ... AF21: =SUM(FO!AF21,PO!AF21,CO!AF21,FE!AF21,PE!AF21) -> 0 | AG21: =SUM(U21:AF21) -> 0 | AH21: =IFERROR(AG21/AG$16,"") | AJ21: =N21-AG21 -> 36992.697
A22: 5020 - Robot Peripherals Depreciation | B22: =SUM(FO!B22,PO!B22,CO!B22,FE!B22,PE!B22) -> 8211.9 | C22: =SUM(FO!C22,PO!C22,CO!C22,FE!C22,PE!C22) -> 10913.63 | D22: =SUM(FO!D22,PO!D22,CO!D22,FE!D22,PE!D22) -> 10939.43 | E22: =SUM(FO!E22,PO!E22,CO!E22,FE!E22,PE!E22) -> 13555.74 | F22: =SUM(FO!F22,PO!F22,CO!F22,FE!F22,PE!F22) -> 13555.75 | G22: =SUM(FO!G22,PO!G22,CO!G22,FE!G22,PE!G22) -> 13770.42 | H22: =SUM(FO!H22,PO!H22,CO!H22,FE!H22,PE!H22) -> 8508.95 | I22: =SUM(FO!I22,PO!I22,CO!I22,FE!I22,PE!I22) -> 8591.56 | ... M22: =SUM(FO!M22,PO!M22,CO!M22,FE!M22,PE!M22) -> 19525.33 | N22: =SUM(B22:M22) -> 158415.37 | O22: =IFERROR(N22/N$16,"") -> 0.021338451 | U22: =SUM(FO!U22,PO!U22,CO!U22,FE!U22,PE!U22) -> 0 | V22: =SUM(FO!V22,PO!V22,CO!V22,FE!V22,PE!V22) -> 0 | W22: =SUM(FO!W22,PO!W22,CO!W22,FE!W22,PE!W22) -> 0 | X22: =SUM(FO!X22,PO!X22,CO!X22,FE!X22,PE!X22) -> 0 | Y22: =SUM(FO!Y22,PO!Y22,CO!Y22,FE!Y22,PE!Y22) -> 0 | Z22: =SUM(FO!Z22,PO!Z22,CO!Z22,FE!Z22,PE!Z22) -> 0 | AA22: =SUM(FO!AA22,PO!AA22,CO!AA22,FE!AA22,PE!AA22) -> 0 | AB22: =SUM(FO!AB22,PO!AB22,CO!AB22,FE!AB22,PE!AB22) -> 0 | ... AF22: =SUM(FO!AF22,PO!AF22,CO!AF22,FE!AF22,PE!AF22) -> 0 | AG22: =SUM(U22:AF22) -> 0 | AH22: =IFERROR(AG22/AG$16,"") | AJ22: =N22-AG22 -> 158415.37
A23: 5025 - Freight and Delivery - Production (Summary)
A24: 5025 - Freight and Delivery - Production (Summary) | B24: =SUM(FO!B24,PO!B24,CO!B24,FE!B24,PE!B24) -> 2370.3 | C24: =SUM(FO!C24,PO!C24,CO!C24,FE!C24,PE!C24) -> 3835.05 | D24: =SUM(FO!D24,PO!D24,CO!D24,FE!D24,PE!D24) -> 11053.81 | E24: =SUM(FO!E24,PO!E24,CO!E24,FE!E24,PE!E24) -> 8300.09 | F24: =SUM(FO!F24,PO!F24,CO!F24,FE!F24,PE!F24) -> 0 | G24: =SUM(FO!G24,PO!G24,CO!G24,FE!G24,PE!G24) -> -544.45 | H24: =SUM(FO!H24,PO!H24,CO!H24,FE!H24,PE!H24) -> 0 | I24: =SUM(FO!I24,PO!I24,CO!I24,FE!I24,PE!I24) -> 93.45 | ... M24: =SUM(FO!M24,PO!M24,CO!M24,FE!M24,PE!M24) -> 5400 | N24: =SUM(B24:M24) -> 50108.25 | O24: =IFERROR(N24/N$16,"") -> 0.0067495498 | U24: =SUM(FO!U24,PO!U24,CO!U24,FE!U24,PE!U24) -> 0 | V24: =SUM(FO!V24,PO!V24,CO!V24,FE!V24,PE!V24) -> 0 | W24: =SUM(FO!W24,PO!W24,CO!W24,FE!W24,PE!W24) -> 0 | X24: =SUM(FO!X24,PO!X24,CO!X24,FE!X24,PE!X24) -> 0 | Y24: =SUM(FO!Y24,PO!Y24,CO!Y24,FE!Y24,PE!Y24) -> 0 | Z24: =SUM(FO!Z24,PO!Z24,CO!Z24,FE!Z24,PE!Z24) -> 0 | AA24: =SUM(FO!AA24,PO!AA24,CO!AA24,FE!AA24,PE!AA24) -> 0 | AB24: =SUM(FO!AB24,PO!AB24,CO!AB24,FE!AB24,PE!AB24) -> 0 | ... AF24: =SUM(FO!AF24,PO!AF24,CO!AF24,FE!AF24,PE!AF24) -> 0 | AG24: =SUM(U24:AF24) -> 0 | AH24: =IFERROR(AG24/AG$16,"") | AJ24: =N24-AG24 -> 50108.25
A25: 5026 - Freight and Delivery - Production - Expedited | B25: =SUM(FO!B25,PO!B25,CO!B25,FE!B25,PE!B25) -> 0 | C25: =SUM(FO!C25,PO!C25,CO!C25,FE!C25,PE!C25) -> 250 | D25: =SUM(FO!D25,PO!D25,CO!D25,FE!D25,PE!D25) -> 2122.44 | E25: =SUM(FO!E25,PO!E25,CO!E25,FE!E25,PE!E25) -> 261.8 | F25: =SUM(FO!F25,PO!F25,CO!F25,FE!F25,PE!F25) -> 0 | G25: =SUM(FO!G25,PO!G25,CO!G25,FE!G25,PE!G25) -> -86.24 | H25: =SUM(FO!H25,PO!H25,CO!H25,FE!H25,PE!H25) -> 0 | I25: =SUM(FO!I25,PO!I25,CO!I25,FE!I25,PE!I25) -> 1638.89 | ... M25: =SUM(FO!M25,PO!M25,CO!M25,FE!M25,PE!M25) -> 0 | N25: =SUM(B25:M25) -> 4186.89 | O25: =IFERROR(N25/N$16,"") -> 0.00056397146 | U25: =SUM(FO!U25,PO!U25,CO!U25,FE!U25,PE!U25) -> 0 | V25: =SUM(FO!V25,PO!V25,CO!V25,FE!V25,PE!V25) -> 0 | W25: =SUM(FO!W25,PO!W25,CO!W25,FE!W25,PE!W25) -> 0 | X25: =SUM(FO!X25,PO!X25,CO!X25,FE!X25,PE!X25) -> 0 | Y25: =SUM(FO!Y25,PO!Y25,CO!Y25,FE!Y25,PE!Y25) -> 0 | Z25: =SUM(FO!Z25,PO!Z25,CO!Z25,FE!Z25,PE!Z25) -> 0 | AA25: =SUM(FO!AA25,PO!AA25,CO!AA25,FE!AA25,PE!AA25) -> 0 | AB25: =SUM(FO!AB25,PO!AB25,CO!AB25,FE!AB25,PE!AB25) -> 0 | ... AF25: =SUM(FO!AF25,PO!AF25,CO!AF25,FE!AF25,PE!AF25) -> 0 | AG25: =SUM(U25:AF25) -> 0 | AH25: =IFERROR(AG25/AG$16,"") | AJ25: =N25-AG25 -> 4186.89
A26: 5027 - Freight and Delivery - Production - Standard | B26: =SUM(FO!B26,PO!B26,CO!B26,FE!B26,PE!B26) -> 0 | C26: =SUM(FO!C26,PO!C26,CO!C26,FE!C26,PE!C26) -> 85 | D26: =SUM(FO!D26,PO!D26,CO!D26,FE!D26,PE!D26) -> 149.33 | E26: =SUM(FO!E26,PO!E26,CO!E26,FE!E26,PE!E26) -> 2494.26 | F26: =SUM(FO!F26,PO!F26,CO!F26,FE!F26,PE!F26) -> 177.67 | G26: =SUM(FO!G26,PO!G26,CO!G26,FE!G26,PE!G26) -> -32.02 | H26: =SUM(FO!H26,PO!H26,CO!H26,FE!H26,PE!H26) -> 852.51 | I26: =SUM(FO!I26,PO!I26,CO!I26,FE!I26,PE!I26) -> 3185.91 | ... M26: =SUM(FO!M26,PO!M26,CO!M26,FE!M26,PE!M26) -> 200 | N26: =SUM(B26:M26) -> 7712.66 | O26: =IFERROR(N26/N$16,"") -> 0.0010388905 | U26: =SUM(FO!U26,PO!U26,CO!U26,FE!U26,PE!U26) -> 0 | V26: =SUM(FO!V26,PO!V26,CO!V26,FE!V26,PE!V26) -> 0 | W26: =SUM(FO!W26,PO!W26,CO!W26,FE!W26,PE!W26) -> 0 | X26: =SUM(FO!X26,PO!X26,CO!X26,FE!X26,PE!X26) -> 0 | Y26: =SUM(FO!Y26,PO!Y26,CO!Y26,FE!Y26,PE!Y26) -> 0 | Z26: =SUM(FO!Z26,PO!Z26,CO!Z26,FE!Z26,PE!Z26) -> 0 | AA26: =SUM(FO!AA26,PO!AA26,CO!AA26,FE!AA26,PE!AA26) -> 0 | AB26: =SUM(FO!AB26,PO!AB26,CO!AB26,FE!AB26,PE!AB26) -> 0 | ... AF26: =SUM(FO!AF26,PO!AF26,CO!AF26,FE!AF26,PE!AF26) -> 0 | AG26: =SUM(U26:AF26) -> 0 | AH26: =IFERROR(AG26/AG$16,"") | AJ26: =N26-AG26 -> 7712.66
A27: Total - 5025 - Freight and Delivery - Production (Summary) | B27: =SUM(B24:B26) -> 2370.3 | C27: =SUM(C24:C26) -> 4170.05 | D27: =SUM(D24:D26) -> 13325.58 | E27: =SUM(E24:E26) -> 11056.15 | F27: =SUM(F24:F26) -> 177.67 | G27: =SUM(G24:G26) -> -662.71 | H27: =SUM(H24:H26) -> 852.51 | I27: =SUM(I24:I26) -> 4918.25 | ... M27: =SUM(M24:M26) -> 5600 | N27: =SUM(B27:M27) -> 62007.8 | O27: =IFERROR(N27/N$16,"") -> 0.0083524118 | U27: =SUM(U24:U26) -> 0 | V27: =SUM(V24:V26) -> 0 | W27: =SUM(W24:W26) -> 0 | X27: =SUM(X24:X26) -> 0 | Y27: =SUM(Y24:Y26) -> 0 | Z27: =SUM(Z24:Z26) -> 0 | AA27: =SUM(AA24:AA26) -> 0 | AB27: =SUM(AB24:AB26) -> 0 | ... AF27: =SUM(AF24:AF26) -> 0 | AG27: =SUM(U27:AF27) -> 0 | AH27: =IFERROR(AG27/AG$16,"") | AJ27: =N27-AG27 -> 62007.8
A28: 5030 - Production Tools and Supplies | B28: =SUM(FO!B28,PO!B28,CO!B28,FE!B28,PE!B28) -> 3122.9 | C28: =SUM(FO!C28,PO!C28,CO!C28,FE!C28,PE!C28) -> 4790.65 | D28: =SUM(FO!D28,PO!D28,CO!D28,FE!D28,PE!D28) -> 8308.32 | E28: =SUM(FO!E28,PO!E28,CO!E28,FE!E28,PE!E28) -> 7596.05 | F28: =SUM(FO!F28,PO!F28,CO!F28,FE!F28,PE!F28) -> 983.17 | G28: =SUM(FO!G28,PO!G28,CO!G28,FE!G28,PE!G28) -> 1367.92 | H28: =SUM(FO!H28,PO!H28,CO!H28,FE!H28,PE!H28) -> 3130.51 | I28: =SUM(FO!I28,PO!I28,CO!I28,FE!I28,PE!I28) -> 5242.04 | ... M28: =SUM(FO!M28,PO!M28,CO!M28,FE!M28,PE!M28) -> 4700 | N28: =SUM(B28:M28) -> 54841.56 | O28: =IFERROR(N28/N$16,"") -> 0.0073871237 | U28: =SUM(FO!U28,PO!U28,CO!U28,FE!U28,PE!U28) -> 10416.667 | V28: =SUM(FO!V28,PO!V28,CO!V28,FE!V28,PE!V28) -> 5416.6667 | W28: =SUM(FO!W28,PO!W28,CO!W28,FE!W28,PE!W28) -> 5416.6667 | X28: =SUM(FO!X28,PO!X28,CO!X28,FE!X28,PE!X28) -> 5416.6667 | Y28: =SUM(FO!Y28,PO!Y28,CO!Y28,FE!Y28,PE!Y28) -> 10416.667 | Z28: =SUM(FO!Z28,PO!Z28,CO!Z28,FE!Z28,PE!Z28) -> 5958.3333 | AA28: =SUM(FO!AA28,PO!AA28,CO!AA28,FE!AA28,PE!AA28) -> 6229.1667 | AB28: =SUM(FO!AB28,PO!AB28,CO!AB28,FE!AB28,PE!AB28) -> 6500 | ... AF28: =SUM(FO!AF28,PO!AF28,CO!AF28,FE!AF28,PE!AF28) -> 7583.3333 | AG28: =SUM(U28:AF28) -> 87854.167 | AH28: =IFERROR(AG28/AG$16,"") | AJ28: =N28-AG28 -> -33012.607
A29: 5040 - Freight & Delivery - Deployment | B29: =SUM(FO!B29,PO!B29,CO!B29,FE!B29,PE!B29) -> 7118.63 | C29: =SUM(FO!C29,PO!C29,CO!C29,FE!C29,PE!C29) -> 7543.76 | D29: =SUM(FO!D29,PO!D29,CO!D29,FE!D29,PE!D29) -> 4922.7 | E29: =SUM(FO!E29,PO!E29,CO!E29,FE!E29,PE!E29) -> 23173.85 | F29: =SUM(FO!F29,PO!F29,CO!F29,FE!F29,PE!F29) -> 98.92 | G29: =SUM(FO!G29,PO!G29,CO!G29,FE!G29,PE!G29) -> 114.77 | H29: =SUM(FO!H29,PO!H29,CO!H29,FE!H29,PE!H29) -> 0 | I29: =SUM(FO!I29,PO!I29,CO!I29,FE!I29,PE!I29) -> 3240.99 | ... M29: =SUM(FO!M29,PO!M29,CO!M29,FE!M29,PE!M29) -> 5000 | N29: =SUM(B29:M29) -> 85213.62 | O29: =IFERROR(N29/N$16,"") -> 0.011478221 | U29: =SUM(FO!U29,PO!U29,CO!U29,FE!U29,PE!U29) -> 0 | V29: =SUM(FO!V29,PO!V29,CO!V29,FE!V29,PE!V29) -> 0 | W29: =SUM(FO!W29,PO!W29,CO!W29,FE!W29,PE!W29) -> 0 | X29: =SUM(FO!X29,PO!X29,CO!X29,FE!X29,PE!X29) -> 0 | Y29: =SUM(FO!Y29,PO!Y29,CO!Y29,FE!Y29,PE!Y29) -> 0 | Z29: =SUM(FO!Z29,PO!Z29,CO!Z29,FE!Z29,PE!Z29) -> 0 | AA29: =SUM(FO!AA29,PO!AA29,CO!AA29,FE!AA29,PE!AA29) -> 0 | AB29: =SUM(FO!AB29,PO!AB29,CO!AB29,FE!AB29,PE!AB29) -> 0 | ... AF29: =SUM(FO!AF29,PO!AF29,CO!AF29,FE!AF29,PE!AF29) -> 0 | AG29: =SUM(U29:AF29) -> 0 | AH29: =IFERROR(AG29/AG$16,"") | AJ29: =N29-AG29 -> 85213.62
A30: 5050 - Travel - Deployment | B30: =SUM(FO!B30,PO!B30,CO!B30,FE!B30,PE!B30) -> 6383.69 | C30: =SUM(FO!C30,PO!C30,CO!C30,FE!C30,PE!C30) -> 4522.11 | D30: =SUM(FO!D30,PO!D30,CO!D30,FE!D30,PE!D30) -> 6516.64 | E30: =SUM(FO!E30,PO!E30,CO!E30,FE!E30,PE!E30) -> 4232.23 | F30: =SUM(FO!F30,PO!F30,CO!F30,FE!F30,PE!F30) -> 13531.9 | G30: =SUM(FO!G30,PO!G30,CO!G30,FE!G30,PE!G30) -> 4225.43 | H30: =SUM(FO!H30,PO!H30,CO!H30,FE!H30,PE!H30) -> 5242.75 | I30: =SUM(FO!I30,PO!I30,CO!I30,FE!I30,PE!I30) -> 8155.61 | ... M30: =SUM(FO!M30,PO!M30,CO!M30,FE!M30,PE!M30) -> 7000 | N30: =SUM(B30:M30) -> 94810.36 | O30: =IFERROR(N30/N$16,"") -> 0.012770896 | U30: =SUM(FO!U30,PO!U30,CO!U30,FE!U30,PE!U30) -> 0 | V30: =SUM(FO!V30,PO!V30,CO!V30,FE!V30,PE!V30) -> 0 | W30: =SUM(FO!W30,PO!W30,CO!W30,FE!W30,PE!W30) -> 0 | X30: =SUM(FO!X30,PO!X30,CO!X30,FE!X30,PE!X30) -> 0 | Y30: =SUM(FO!Y30,PO!Y30,CO!Y30,FE!Y30,PE!Y30) -> 0 | Z30: =SUM(FO!Z30,PO!Z30,CO!Z30,FE!Z30,PE!Z30) -> 0 | AA30: =SUM(FO!AA30,PO!AA30,CO!AA30,FE!AA30,PE!AA30) -> 0 | AB30: =SUM(FO!AB30,PO!AB30,CO!AB30,FE!AB30,PE!AB30) -> 0 | ... AF30: =SUM(FO!AF30,PO!AF30,CO!AF30,FE!AF30,PE!AF30) -> 0 | AG30: =SUM(U30:AF30) -> 0 | AH30: =IFERROR(AG30/AG$16,"") | AJ30: =N30-AG30 -> 94810.36
A31: 5060 - Meals - Deployment | B31: =SUM(FO!B31,PO!B31,CO!B31,FE!B31,PE!B31) -> 635.5 | C31: =SUM(FO!C31,PO!C31,CO!C31,FE!C31,PE!C31) -> 723.15 | D31: =SUM(FO!D31,PO!D31,CO!D31,FE!D31,PE!D31) -> 1053.77 | E31: =SUM(FO!E31,PO!E31,CO!E31,FE!E31,PE!E31) -> 890.31 | F31: =SUM(FO!F31,PO!F31,CO!F31,FE!F31,PE!F31) -> 1479.8 | G31: =SUM(FO!G31,PO!G31,CO!G31,FE!G31,PE!G31) -> 248.89 | H31: =SUM(FO!H31,PO!H31,CO!H31,FE!H31,PE!H31) -> 602.41 | I31: =SUM(FO!I31,PO!I31,CO!I31,FE!I31,PE!I31) -> 1368.86 | ... M31: =SUM(FO!M31,PO!M31,CO!M31,FE!M31,PE!M31) -> 800 | N31: =SUM(B31:M31) -> 11602.69 | O31: =IFERROR(N31/N$16,"") -> 0.0015628751 | U31: =SUM(FO!U31,PO!U31,CO!U31,FE!U31,PE!U31) -> 0 | V31: =SUM(FO!V31,PO!V31,CO!V31,FE!V31,PE!V31) -> 0 | W31: =SUM(FO!W31,PO!W31,CO!W31,FE!W31,PE!W31) -> 0 | X31: =SUM(FO!X31,PO!X31,CO!X31,FE!X31,PE!X31) -> 0 | Y31: =SUM(FO!Y31,PO!Y31,CO!Y31,FE!Y31,PE!Y31) -> 0 | Z31: =SUM(FO!Z31,PO!Z31,CO!Z31,FE!Z31,PE!Z31) -> 0 | AA31: =SUM(FO!AA31,PO!AA31,CO!AA31,FE!AA31,PE!AA31) -> 0 | AB31: =SUM(FO!AB31,PO!AB31,CO!AB31,FE!AB31,PE!AB31) -> 0 | ... AF31: =SUM(FO!AF31,PO!AF31,CO!AF31,FE!AF31,PE!AF31) -> 0 | AG31: =SUM(U31:AF31) -> 0 | AH31: =IFERROR(AG31/AG$16,"") | AJ31: =N31-AG31 -> 11602.69
A32: 5100 - Labor Expense - Production
A33: 5110 - Salaries and Wages - Production | B33: =SUM(FO!B33,PO!B33,CO!B33,FE!B33,PE!B33) -> 0 | C33: =SUM(FO!C33,PO!C33,CO!C33,FE!C33,PE!C33) -> 29333.47 | D33: =SUM(FO!D33,PO!D33,CO!D33,FE!D33,PE!D33) -> 11889.74 | E33: =SUM(FO!E33,PO!E33,CO!E33,FE!E33,PE!E33) -> 21646.72 | F33: =SUM(FO!F33,PO!F33,CO!F33,FE!F33,PE!F33) -> 17259.93 | G33: =SUM(FO!G33,PO!G33,CO!G33,FE!G33,PE!G33) -> 17454.2 | H33: =SUM(FO!H33,PO!H33,CO!H33,FE!H33,PE!H33) -> 20023.74 | I33: =SUM(FO!I33,PO!I33,CO!I33,FE!I33,PE!I33) -> 14849.42 | ... M33: =SUM(FO!M33,PO!M33,CO!M33,FE!M33,PE!M33) -> 17500 | N33: =SUM(B33:M33) -> 202457.22 | O33: =IFERROR(N33/N$16,"") -> 0.027270861 | U33: =SUM(FO!U33,PO!U33,CO!U33,FE!U33,PE!U33) -> 43450 | V33: =SUM(FO!V33,PO!V33,CO!V33,FE!V33,PE!V33) -> 43450 | W33: =SUM(FO!W33,PO!W33,CO!W33,FE!W33,PE!W33) -> 43450 | X33: =SUM(FO!X33,PO!X33,CO!X33,FE!X33,PE!X33) -> 43450 | Y33: =SUM(FO!Y33,PO!Y33,CO!Y33,FE!Y33,PE!Y33) -> 43450 | Z33: =SUM(FO!Z33,PO!Z33,CO!Z33,FE!Z33,PE!Z33) -> 43450 | AA33: =SUM(FO!AA33,PO!AA33,CO!AA33,FE!AA33,PE!AA33) -> 43450 | AB33: =SUM(FO!AB33,PO!AB33,CO!AB33,FE!AB33,PE!AB33) -> 43450 | ... AF33: =SUM(FO!AF33,PO!AF33,CO!AF33,FE!AF33,PE!AF33) -> 44753.5 | AG33: =SUM(U33:AF33) -> 525310.5 | AH33: =IFERROR(AG33/AG$16,"") | AJ33: =N33-AG33 -> -322853.28
A34: 5130 - Payroll Taxes - Production | B34: =SUM(FO!B34,PO!B34,CO!B34,FE!B34,PE!B34) -> 0 | C34: =SUM(FO!C34,PO!C34,CO!C34,FE!C34,PE!C34) -> 842.84 | D34: =SUM(FO!D34,PO!D34,CO!D34,FE!D34,PE!D34) -> 1357.58 | E34: =SUM(FO!E34,PO!E34,CO!E34,FE!E34,PE!E34) -> 703.54 | F34: =SUM(FO!F34,PO!F34,CO!F34,FE!F34,PE!F34) -> 618.04 | G34: =SUM(FO!G34,PO!G34,CO!G34,FE!G34,PE!G34) -> 634.79 | H34: =SUM(FO!H34,PO!H34,CO!H34,FE!H34,PE!H34) -> 768.4 | I34: =SUM(FO!I34,PO!I34,CO!I34,FE!I34,PE!I34) -> 592.79 | ... M34: =SUM(FO!M34,PO!M34,CO!M34,FE!M34,PE!M34) -> 648 | N34: =SUM(B34:M34) -> 8109.98 | O34: =IFERROR(N34/N$16,"") -> 0.0010924092 | U34: =SUM(FO!U34,PO!U34,CO!U34,FE!U34,PE!U34) -> 1580.2286 | V34: =SUM(FO!V34,PO!V34,CO!V34,FE!V34,PE!V34) -> 1580.2286 | W34: =SUM(FO!W34,PO!W34,CO!W34,FE!W34,PE!W34) -> 1580.2286 | X34: =SUM(FO!X34,PO!X34,CO!X34,FE!X34,PE!X34) -> 1580.2286 | Y34: =SUM(FO!Y34,PO!Y34,CO!Y34,FE!Y34,PE!Y34) -> 1580.2286 | Z34: =SUM(FO!Z34,PO!Z34,CO!Z34,FE!Z34,PE!Z34) -> 1580.2286 | AA34: =SUM(FO!AA34,PO!AA34,CO!AA34,FE!AA34,PE!AA34) -> 1580.2286 | AB34: =SUM(FO!AB34,PO!AB34,CO!AB34,FE!AB34,PE!AB34) -> 1580.2286 | ... AF34: =SUM(FO!AF34,PO!AF34,CO!AF34,FE!AF34,PE!AF34) -> 1627.6354 | AG34: =SUM(U34:AF34) -> 19104.963 | AH34: =IFERROR(AG34/AG$16,"") | AJ34: =N34-AG34 -> -10994.983
A35: 5140 - Benefits - Production | B35: =SUM(FO!B35,PO!B35,CO!B35,FE!B35,PE!B35) -> -18903.27 | C35: =SUM(FO!C35,PO!C35,CO!C35,FE!C35,PE!C35) -> -7499.98 | D35: =SUM(FO!D35,PO!D35,CO!D35,FE!D35,PE!D35) -> 1464.77 | E35: =SUM(FO!E35,PO!E35,CO!E35,FE!E35,PE!E35) -> 2876.74 | F35: =SUM(FO!F35,PO!F35,CO!F35,FE!F35,PE!F35) -> 4138.12 | G35: =SUM(FO!G35,PO!G35,CO!G35,FE!G35,PE!G35) -> 3992.14 | H35: =SUM(FO!H35,PO!H35,CO!H35,FE!H35,PE!H35) -> -6793.75 | I35: =SUM(FO!I35,PO!I35,CO!I35,FE!I35,PE!I35) -> 2732.36 | ... M35: =SUM(FO!M35,PO!M35,CO!M35,FE!M35,PE!M35) -> 4000 | N35: =SUM(B35:M35) -> -1992.87 | O35: =IFERROR(N35/N$16,"") -> -0.00026843834 | U35: =SUM(FO!U35,PO!U35,CO!U35,FE!U35,PE!U35) -> 8966.4588 | V35: =SUM(FO!V35,PO!V35,CO!V35,FE!V35,PE!V35) -> 8966.4588 | W35: =SUM(FO!W35,PO!W35,CO!W35,FE!W35,PE!W35) -> 8966.4588 | X35: =SUM(FO!X35,PO!X35,CO!X35,FE!X35,PE!X35) -> 8966.4588 | Y35: =SUM(FO!Y35,PO!Y35,CO!Y35,FE!Y35,PE!Y35) -> 8966.4588 | Z35: =SUM(FO!Z35,PO!Z35,CO!Z35,FE!Z35,PE!Z35) -> 8966.4588 | AA35: =SUM(FO!AA35,PO!AA35,CO!AA35,FE!AA35,PE!AA35) -> 8966.4588 | AB35: =SUM(FO!AB35,PO!AB35,CO!AB35,FE!AB35,PE!AB35) -> 8966.4588 | ... AF35: =SUM(FO!AF35,PO!AF35,CO!AF35,FE!AF35,PE!AF35) -> 9235.4525 | AG35: =SUM(U35:AF35) -> 108404.49 | AH35: =IFERROR(AG35/AG$16,"") | AJ35: =N35-AG35 -> -110397.36
A36: Total - 5100 - Labor Expense - Production | B36: =SUM(B33:B35) -> -18903.27 | C36: =SUM(C33:C35) -> 22676.33 | D36: =SUM(D33:D35) -> 14712.09 | E36: =SUM(E33:E35) -> 25227 | F36: =SUM(F33:F35) -> 22016.09 | G36: =SUM(G33:G35) -> 22081.13 | H36: =SUM(H33:H35) -> 13998.39 | I36: =SUM(I33:I35) -> 18174.57 | ... M36: =SUM(M33:M35) -> 22148 | N36: =SUM(B36:M36) -> 208574.33 | O36: =IFERROR(N36/N$16,"") -> 0.028094831 | U36: =SUM(U33:U35) -> 53996.687 | V36: =SUM(V33:V35) -> 53996.687 | W36: =SUM(W33:W35) -> 53996.687 | X36: =SUM(X33:X35) -> 53996.687 | Y36: =SUM(Y33:Y35) -> 53996.687 | Z36: =SUM(Z33:Z35) -> 53996.687 | AA36: =SUM(AA33:AA35) -> 53996.687 | AB36: =SUM(AB33:AB35) -> 53996.687 | ... AF36: =SUM(AF33:AF35) -> 55616.588 | AG36: =SUM(U36:AF36) -> 652819.95 | AH36: =IFERROR(AG36/AG$16,"") | AJ36: =N36-AG36 -> -444245.62
A37: Total - 5000 - Robot Production and Deployment | B37: =B19+B22+B27+B28+B29+B30+B31+B36+B20+B21 -> 150062 | C37: =C19+C22+C27+C28+C29+C30+C31+C36+C20+C21 -> 177551.58 | D37: =D19+D22+D27+D28+D29+D30+D31+D36+D20+D21 -> 188086.69 | E37: =E19+E22+E27+E28+E29+E30+E31+E36+E20+E21 -> 219001.28 | F37: =F19+F22+F27+F28+F29+F30+F31+F36+F20+F21 -> 192199.72 | G37: =G19+G22+G27+G28+G29+G30+G31+G36+G20+G21 -> 191563.96 | H37: =H19+H22+H27+H28+H29+H30+H31+H36+H20+H21 -> 170597.45 | I37: =I19+I22+I27+I28+I29+I30+I31+I36+I20+I21 -> 190947.42 | ... M37: =M19+M22+M27+M28+M29+M30+M31+M36+M20+M21 -> 204518.72 | N37: =SUM(B37:M37) -> 2305146.9 | O37: =IFERROR(N37/N$16,"") -> 0.31050184 | U37: =U19+U22+U27+U28+U29+U30+U31+U36+U20+U21 -> 64413.354 | V37: =V19+V22+V27+V28+V29+V30+V31+V36+V20+V21 -> 59413.354 | W37: =W19+W22+W27+W28+W29+W30+W31+W36+W20+W21 -> 59413.354 | X37: =X19+X22+X27+X28+X29+X30+X31+X36+X20+X21 -> 59413.354 | Y37: =Y19+Y22+Y27+Y28+Y29+Y30+Y31+Y36+Y20+Y21 -> 64413.354 | Z37: =Z19+Z22+Z27+Z28+Z29+Z30+Z31+Z36+Z20+Z21 -> 59955.021 | AA37: =AA19+AA22+AA27+AA28+AA29+AA30+AA31+AA36+AA20+AA21 -> 60225.854 | AB37: =AB19+AB22+AB27+AB28+AB29+AB30+AB31+AB36+AB20+AB21 -> 60496.687 | ... AF37: =AF19+AF22+AF27+AF28+AF29+AF30+AF31+AF36+AF20+AF21 -> 63199.921 | AG37: =SUM(U37:AF37) -> 740674.12 | AH37: =IFERROR(AG37/AG$16,"") | AJ37: =N37-AG37 -> 1564472.8
A38: 5015 - Supplies and Materials | B38: =SUM(FO!B38,PO!B38,CO!B38,FE!B38,PE!B38) -> 0 | C38: =SUM(FO!C38,PO!C38,CO!C38,FE!C38,PE!C38) -> 0 | D38: =SUM(FO!D38,PO!D38,CO!D38,FE!D38,PE!D38) -> 2782.65 | E38: =SUM(FO!E38,PO!E38,CO!E38,FE!E38,PE!E38) -> 56.1 | F38: =SUM(FO!F38,PO!F38,CO!F38,FE!F38,PE!F38) -> 0 | G38: =SUM(FO!G38,PO!G38,CO!G38,FE!G38,PE!G38) -> -352.47 | H38: =SUM(FO!H38,PO!H38,CO!H38,FE!H38,PE!H38) -> 0 | I38: =SUM(FO!I38,PO!I38,CO!I38,FE!I38,PE!I38) -> 0 | ... M38: =SUM(FO!M38,PO!M38,CO!M38,FE!M38,PE!M38) -> 0 | N38: =SUM(B38:M38) -> 2486.28 | O38: =IFERROR(N38/N$16,"") -> 0.00033490036 | U38: =SUM(FO!U38,PO!U38,CO!U38,FE!U38,PE!U38) -> 21250 | V38: =SUM(FO!V38,PO!V38,CO!V38,FE!V38,PE!V38) -> 6250 | W38: =SUM(FO!W38,PO!W38,CO!W38,FE!W38,PE!W38) -> 6250 | X38: =SUM(FO!X38,PO!X38,CO!X38,FE!X38,PE!X38) -> 6250 | Y38: =SUM(FO!Y38,PO!Y38,CO!Y38,FE!Y38,PE!Y38) -> 6562.5 | Z38: =SUM(FO!Z38,PO!Z38,CO!Z38,FE!Z38,PE!Z38) -> 6875 | AA38: =SUM(FO!AA38,PO!AA38,CO!AA38,FE!AA38,PE!AA38) -> 7187.5 | AB38: =SUM(FO!AB38,PO!AB38,CO!AB38,FE!AB38,PE!AB38) -> 7500 | ... AF38: =SUM(FO!AF38,PO!AF38,CO!AF38,FE!AF38,PE!AF38) -> 8750 | AG38: =SUM(U38:AF38) -> 101250 | AH38: =IFERROR(AG38/AG$16,"") | AJ38: =N38-AG38 -> -98763.72
A39: 5028 - Duties & Tariffs - Production | B39: =SUM(FO!B39,PO!B39,CO!B39,FE!B39,PE!B39) -> 0 | C39: =SUM(FO!C39,PO!C39,CO!C39,FE!C39,PE!C39) -> 0 | D39: =SUM(FO!D39,PO!D39,CO!D39,FE!D39,PE!D39) -> 0 | E39: =SUM(FO!E39,PO!E39,CO!E39,FE!E39,PE!E39) -> 0 | F39: =SUM(FO!F39,PO!F39,CO!F39,FE!F39,PE!F39) -> 6857.32 | G39: =SUM(FO!G39,PO!G39,CO!G39,FE!G39,PE!G39) -> 0 | H39: =SUM(FO!H39,PO!H39,CO!H39,FE!H39,PE!H39) -> 10645.5 | I39: =SUM(FO!I39,PO!I39,CO!I39,FE!I39,PE!I39) -> 6414.69 | ... M39: =SUM(FO!M39,PO!M39,CO!M39,FE!M39,PE!M39) -> 1000 | N39: =SUM(B39:M39) -> 29917.51 | O39: =IFERROR(N39/N$16,"") -> 0.0040298698 | U39: =SUM(FO!U39,PO!U39,CO!U39,FE!U39,PE!U39) -> 2207.0939 | V39: =SUM(FO!V39,PO!V39,CO!V39,FE!V39,PE!V39) -> 2207.0939 | W39: =SUM(FO!W39,PO!W39,CO!W39,FE!W39,PE!W39) -> 2207.0939 | X39: =SUM(FO!X39,PO!X39,CO!X39,FE!X39,PE!X39) -> 2207.0939 | Y39: =SUM(FO!Y39,PO!Y39,CO!Y39,FE!Y39,PE!Y39) -> 2207.0939 | Z39: =SUM(FO!Z39,PO!Z39,CO!Z39,FE!Z39,PE!Z39) -> 2207.0939 | AA39: =SUM(FO!AA39,PO!AA39,CO!AA39,FE!AA39,PE!AA39) -> 2207.0939 | AB39: =SUM(FO!AB39,PO!AB39,CO!AB39,FE!AB39,PE!AB39) -> 2207.0939 | ... AF39: =SUM(FO!AF39,PO!AF39,CO!AF39,FE!AF39,PE!AF39) -> 2207.0939 | AG39: =SUM(U39:AF39) -> 26485.126 | AH39: =IFERROR(AG39/AG$16,"") | AJ39: =N39-AG39 -> 3432.3835
A40: 5029 - Processing Fee - Production | B40: =SUM(FO!B40,PO!B40,CO!B40,FE!B40,PE!B40) -> 0 | C40: =SUM(FO!C40,PO!C40,CO!C40,FE!C40,PE!C40) -> 0 | D40: =SUM(FO!D40,PO!D40,CO!D40,FE!D40,PE!D40) -> 0 | E40: =SUM(FO!E40,PO!E40,CO!E40,FE!E40,PE!E40) -> 0 | F40: =SUM(FO!F40,PO!F40,CO!F40,FE!F40,PE!F40) -> 125 | G40: =SUM(FO!G40,PO!G40,CO!G40,FE!G40,PE!G40) -> -362.34 | H40: =SUM(FO!H40,PO!H40,CO!H40,FE!H40,PE!H40) -> 0 | I40: =SUM(FO!I40,PO!I40,CO!I40,FE!I40,PE!I40) -> 4095.3 | ... M40: =SUM(FO!M40,PO!M40,CO!M40,FE!M40,PE!M40) -> 125 | N40: =SUM(B40:M40) -> 4357.96 | O40: =IFERROR(N40/N$16,"") -> 0.00058701448 | U40: =SUM(FO!U40,PO!U40,CO!U40,FE!U40,PE!U40) -> 381.3215 | V40: =SUM(FO!V40,PO!V40,CO!V40,FE!V40,PE!V40) -> 381.3215 | W40: =SUM(FO!W40,PO!W40,CO!W40,FE!W40,PE!W40) -> 381.3215 | X40: =SUM(FO!X40,PO!X40,CO!X40,FE!X40,PE!X40) -> 381.3215 | Y40: =SUM(FO!Y40,PO!Y40,CO!Y40,FE!Y40,PE!Y40) -> 381.3215 | Z40: =SUM(FO!Z40,PO!Z40,CO!Z40,FE!Z40,PE!Z40) -> 381.3215 | AA40: =SUM(FO!AA40,PO!AA40,CO!AA40,FE!AA40,PE!AA40) -> 381.3215 | AB40: =SUM(FO!AB40,PO!AB40,CO!AB40,FE!AB40,PE!AB40) -> 381.3215 | ... AF40: =SUM(FO!AF40,PO!AF40,CO!AF40,FE!AF40,PE!AF40) -> 381.3215 | AG40: =SUM(U40:AF40) -> 4575.858 | AH40: =IFERROR(AG40/AG$16,"") | AJ40: =N40-AG40 -> -217.898
A41: 5070 - Scrap | B41: =SUM(FO!B41,PO!B41,CO!B41,FE!B41,PE!B41) -> 0 | C41: =SUM(FO!C41,PO!C41,CO!C41,FE!C41,PE!C41) -> 0 | D41: =SUM(FO!D41,PO!D41,CO!D41,FE!D41,PE!D41) -> 0 | E41: =SUM(FO!E41,PO!E41,CO!E41,FE!E41,PE!E41) -> 0 | F41: =SUM(FO!F41,PO!F41,CO!F41,FE!F41,PE!F41) -> 0 | G41: =SUM(FO!G41,PO!G41,CO!G41,FE!G41,PE!G41) -> 1662.88 | H41: =SUM(FO!H41,PO!H41,CO!H41,FE!H41,PE!H41) -> 818.38 | I41: =SUM(FO!I41,PO!I41,CO!I41,FE!I41,PE!I41) -> 111429.29 | ... M41: =SUM(FO!M41,PO!M41,CO!M41,FE!M41,PE!M41) -> 0 | N41: =SUM(B41:M41) -> 113910.55 | O41: =IFERROR(N41/N$16,"") -> 0.01534368 | U41: =SUM(FO!U41,PO!U41,CO!U41,FE!U41,PE!U41) -> 9492.5458 | V41: =SUM(FO!V41,PO!V41,CO!V41,FE!V41,PE!V41) -> 9492.5458 | W41: =SUM(FO!W41,PO!W41,CO!W41,FE!W41,PE!W41) -> 9492.5458 | X41: =SUM(FO!X41,PO!X41,CO!X41,FE!X41,PE!X41) -> 9492.5458 | Y41: =SUM(FO!Y41,PO!Y41,CO!Y41,FE!Y41,PE!Y41) -> 9492.5458 | Z41: =SUM(FO!Z41,PO!Z41,CO!Z41,FE!Z41,PE!Z41) -> 9492.5458 | AA41: =SUM(FO!AA41,PO!AA41,CO!AA41,FE!AA41,PE!AA41) -> 9492.5458 | AB41: =SUM(FO!AB41,PO!AB41,CO!AB41,FE!AB41,PE!AB41) -> 9492.5458 | ... AF41: =SUM(FO!AF41,PO!AF41,CO!AF41,FE!AF41,PE!AF41) -> 9492.5458 | AG41: =SUM(U41:AF41) -> 113910.55 | AH41: =IFERROR(AG41/AG$16,"") | AJ41: =N41-AG41 -> 0
A42: 5201 - Inventory Adjustments | B42: =SUM(FO!B42,PO!B42,CO!B42,FE!B42,PE!B42) -> 0 | C42: =SUM(FO!C42,PO!C42,CO!C42,FE!C42,PE!C42) -> 0 | D42: =SUM(FO!D42,PO!D42,CO!D42,FE!D42,PE!D42) -> 0 | E42: =SUM(FO!E42,PO!E42,CO!E42,FE!E42,PE!E42) -> 0 | F42: =SUM(FO!F42,PO!F42,CO!F42,FE!F42,PE!F42) -> 0 | G42: =SUM(FO!G42,PO!G42,CO!G42,FE!G42,PE!G42) -> 0 | H42: =SUM(FO!H42,PO!H42,CO!H42,FE!H42,PE!H42) -> 0 | I42: =SUM(FO!I42,PO!I42,CO!I42,FE!I42,PE!I42) -> 0 | ... M42: =SUM(FO!M42,PO!M42,CO!M42,FE!M42,PE!M42) -> 4000 | N42: =SUM(B42:M42) -> 22000 | O42: =IFERROR(N42/N$16,"") -> 0.0029633862 | U42: =SUM(FO!U42,PO!U42,CO!U42,FE!U42,PE!U42) -> 20000 | V42: =SUM(FO!V42,PO!V42,CO!V42,FE!V42,PE!V42) -> 5000 | W42: =SUM(FO!W42,PO!W42,CO!W42,FE!W42,PE!W42) -> 5000 | X42: =SUM(FO!X42,PO!X42,CO!X42,FE!X42,PE!X42) -> 5000 | Y42: =SUM(FO!Y42,PO!Y42,CO!Y42,FE!Y42,PE!Y42) -> 5000 | Z42: =SUM(FO!Z42,PO!Z42,CO!Z42,FE!Z42,PE!Z42) -> 5000 | AA42: =SUM(FO!AA42,PO!AA42,CO!AA42,FE!AA42,PE!AA42) -> 5000 | AB42: =SUM(FO!AB42,PO!AB42,CO!AB42,FE!AB42,PE!AB42) -> 5000 | ... AF42: =SUM(FO!AF42,PO!AF42,CO!AF42,FE!AF42,PE!AF42) -> 5000 | AG42: =SUM(U42:AF42) -> 75000 | AH42: =IFERROR(AG42/AG$16,"") | AJ42: =N42-AG42 -> -53000
A43: 5300 - Maintenance
A44: 5310 - Contractors - Field | B44: =SUM(FO!B44,PO!B44,CO!B44,FE!B44,PE!B44) -> 0 | C44: =SUM(FO!C44,PO!C44,CO!C44,FE!C44,PE!C44) -> 0 | D44: =SUM(FO!D44,PO!D44,CO!D44,FE!D44,PE!D44) -> 0 | E44: =SUM(FO!E44,PO!E44,CO!E44,FE!E44,PE!E44) -> 0 | F44: =SUM(FO!F44,PO!F44,CO!F44,FE!F44,PE!F44) -> 19808 | G44: =SUM(FO!G44,PO!G44,CO!G44,FE!G44,PE!G44) -> 10009 | H44: =SUM(FO!H44,PO!H44,CO!H44,FE!H44,PE!H44) -> 10968.52 | I44: =SUM(FO!I44,PO!I44,CO!I44,FE!I44,PE!I44) -> 6116.47 | ... M44: =SUM(FO!M44,PO!M44,CO!M44,FE!M44,PE!M44) -> 52110 | N44: =SUM(B44:M44) -> 231821.99 | O44: =IFERROR(N44/N$16,"") -> 0.031226277 | U44: =SUM(FO!U44,PO!U44,CO!U44,FE!U44,PE!U44) -> 0 | V44: =SUM(FO!V44,PO!V44,CO!V44,FE!V44,PE!V44) -> 0 | W44: =SUM(FO!W44,PO!W44,CO!W44,FE!W44,PE!W44) -> 0 | X44: =SUM(FO!X44,PO!X44,CO!X44,FE!X44,PE!X44) -> 0 | Y44: =SUM(FO!Y44,PO!Y44,CO!Y44,FE!Y44,PE!Y44) -> 0 | Z44: =SUM(FO!Z44,PO!Z44,CO!Z44,FE!Z44,PE!Z44) -> 0 | AA44: =SUM(FO!AA44,PO!AA44,CO!AA44,FE!AA44,PE!AA44) -> 0 | AB44: =SUM(FO!AB44,PO!AB44,CO!AB44,FE!AB44,PE!AB44) -> 0 | ... AF44: =SUM(FO!AF44,PO!AF44,CO!AF44,FE!AF44,PE!AF44) -> 0 | AG44: =SUM(U44:AF44) -> 0 | AH44: =IFERROR(AG44/AG$16,"") | AJ44: =N44-AG44 -> 231821.99
...

Sheet FO
A1: Field Operations
A2: 2026 Actuals/Forecast & 2027 Budget
B7: Actual | C7: Actual | D7: Actual | E7: Actual | F7: Actual | G7: Actual | H7: Actual | I7: Actual | J7: Forecast | K7: Forecast | L7: Forecast | M7: Forecast | N7: Forecast | O7: Forecast | S7: Annual Input | T7: YOY | U7: Budget | V7: Budget | W7: Budget | X7: Budget | Y7: Budget | Z7: Budget | AA7: Budget | AB7: Budget | AC7: Budget | AD7: Budget | AE7: Budget | AF7: Budget | AG7: Budget | AH7: Budget | AJ7: YOY
B8: Jan | C8: Feb | D8: Mar | E8: Apr | F8: May | G8: Jun | H8: Jul | I8: Aug | J8: Sep | K8: Oct | L8: Nov | M8: Dec | N8: 2026 | O8: % Total Rev | R8: Input Method | S8: "Even" spread | T8: Growth % | U8: Jan | V8: Feb | W8: Mar | X8: Apr | Y8: May | Z8: Jun | AA8: Jul | AB8: Aug | AC8: Sep | AD8: Oct | AE8: Nov | AF8: Dec | AG8: 2027 | AH8: % Total Rev | AJ8: Fav / (Unfav)
A9: Ordinary Income/Expense
A10: Income
A11: 4000 - Sales
A12: 4100 - Subscription/Platform Fees | B12: 0 | C12: 0 | D12: 0 | E12: 0 | F12: 0 | G12: 0 | H12: 0 | I12: 0 | N12: =SUM(B12:M12) -> 0 | O12: =IFERROR(N12/N$16,"") | R12: Even | T12: 0.05 | U12: =IF($R12="Manual","",IFERROR(IF($R12="YOY Growth",$N12*(1+$T12)/12,$S12/12),"")) -> 0 | V12: =IF($R12="Manual","",IFERROR(IF($R12="YOY Growth",$N12*(1+$T12)/12,$S12/12),"")) -> 0 | W12: =IF($R12="Manual","",IFERROR(IF($R12="YOY Growth",$N12*(1+$T12)/12,$S12/12),"")) -> 0 | X12: =IF($R12="Manual","",IFERROR(IF($R12="YOY Growth",$N12*(1+$T12)/12,$S12/12),"")) -> 0 | Y12: =IF($R12="Manual","",IFERROR(IF($R12="YOY Growth",$N12*(1+$T12)/12,$S12/12),"")) -> 0 | Z12: =IF($R12="Manual","",IFERROR(IF($R12="YOY Growth",$N12*(1+$T12)/12,$S12/12),"")) -> 0 | AA12: =IF($R12="Manual","",IFERROR(IF($R12="YOY Growth",$N12*(1+$T12)/12,$S12/12),"")) -> 0 | AB12: =IF($R12="Manual","",IFERROR(IF($R12="YOY Growth",$N12*(1+$T12)/12,$S12/12),"")) -> 0 | ... AF12: =IF($R12="Manual","",IFERROR(IF($R12="YOY Growth",$N12*(1+$T12)/12,$S12/12),"")) -> 0 | AG12: =SUM(U12:AF12) -> 0 | AH12: =IFERROR(AG12/AG$16,"") | AJ12: =AG12-N12 -> 0
A13: 4500 - Implementation Fees | B13: 0 | C13: 0 | D13: 0 | E13: 0 | F13: 0 | G13: 0 | H13: 0 | I13: 0 | N13: =SUM(B13:M13) -> 0 | O13: =IFERROR(N13/N$16,"") | R13: Even | S13: 0 | T13: 0.05 | U13: =IF($R13="Manual","",IFERROR(IF($R13="YOY Growth",$N13*(1+$T13)/12,$S13/12),"")) -> 0 | V13: =IF($R13="Manual","",IFERROR(IF($R13="YOY Growth",$N13*(1+$T13)/12,$S13/12),"")) -> 0 | W13: =IF($R13="Manual","",IFERROR(IF($R13="YOY Growth",$N13*(1+$T13)/12,$S13/12),"")) -> 0 | X13: =IF($R13="Manual","",IFERROR(IF($R13="YOY Growth",$N13*(1+$T13)/12,$S13/12),"")) -> 0 | Y13: =IF($R13="Manual","",IFERROR(IF($R13="YOY Growth",$N13*(1+$T13)/12,$S13/12),"")) -> 0 | Z13: =IF($R13="Manual","",IFERROR(IF($R13="YOY Growth",$N13*(1+$T13)/12,$S13/12),"")) -> 0 | AA13: =IF($R13="Manual","",IFERROR(IF($R13="YOY Growth",$N13*(1+$T13)/12,$S13/12),"")) -> 0 | AB13: =IF($R13="Manual","",IFERROR(IF($R13="YOY Growth",$N13*(1+$T13)/12,$S13/12),"")) -> 0 | ... AF13: =IF($R13="Manual","",IFERROR(IF($R13="YOY Growth",$N13*(1+$T13)/12,$S13/12),"")) -> 0 | AG13: =SUM(U13:AF13) -> 0 | AH13: =IFERROR(AG13/AG$16,"") | AJ13: =AG13-N13 -> 0
A14: Total - 4000 - Sales | B14: =SUM(B12:B13) -> 0 | C14: =SUM(C12:C13) -> 0 | D14: =SUM(D12:D13) -> 0 | E14: =SUM(E12:E13) -> 0 | F14: =SUM(F12:F13) -> 0 | G14: =SUM(G12:G13) -> 0 | H14: =SUM(H12:H13) -> 0 | I14: =SUM(I12:I13) -> 0 | ... M14: =SUM(M12:M13) -> 0 | N14: =SUM(B14:M14) -> 0 | O14: =SUM(O12:O13) -> 0 | U14: =SUM(U12:U13) -> 0 | V14: =SUM(V12:V13) -> 0 | W14: =SUM(W12:W13) -> 0 | X14: =SUM(X12:X13) -> 0 | Y14: =SUM(Y12:Y13) -> 0 | Z14: =SUM(Z12:Z13) -> 0 | AA14: =SUM(AA12:AA13) -> 0 | AB14: =SUM(AB12:AB13) -> 0 | ... AF14: =SUM(AF12:AF13) -> 0 | AG14: =SUM(U14:AF14) -> 0 | AH14: =SUM(AH12:AH13) -> 0 | AJ14: =AG14-N14 -> 0
A15: 4900 - One-Time Revenue | B15: 0 | C15: 0 | D15: 0 | E15: 0 | F15: 0 | G15: 0 | H15: 0 | I15: 0 | N15: =SUM(B15:M15) -> 0 | O15: =IFERROR(N15/N$16,"") | R15: Even | S15: 0 | T15: 0.05 | U15: =IF($R15="Manual","",IFERROR(IF($R15="YOY Growth",$N15*(1+$T15)/12,$S15/12),"")) -> 0 | V15: =IF($R15="Manual","",IFERROR(IF($R15="YOY Growth",$N15*(1+$T15)/12,$S15/12),"")) -> 0 | W15: =IF($R15="Manual","",IFERROR(IF($R15="YOY Growth",$N15*(1+$T15)/12,$S15/12),"")) -> 0 | X15: =IF($R15="Manual","",IFERROR(IF($R15="YOY Growth",$N15*(1+$T15)/12,$S15/12),"")) -> 0 | Y15: =IF($R15="Manual","",IFERROR(IF($R15="YOY Growth",$N15*(1+$T15)/12,$S15/12),"")) -> 0 | Z15: =IF($R15="Manual","",IFERROR(IF($R15="YOY Growth",$N15*(1+$T15)/12,$S15/12),"")) -> 0 | AA15: =IF($R15="Manual","",IFERROR(IF($R15="YOY Growth",$N15*(1+$T15)/12,$S15/12),"")) -> 0 | AB15: =IF($R15="Manual","",IFERROR(IF($R15="YOY Growth",$N15*(1+$T15)/12,$S15/12),"")) -> 0 | ... AF15: =IF($R15="Manual","",IFERROR(IF($R15="YOY Growth",$N15*(1+$T15)/12,$S15/12),"")) -> 0 | AG15: =SUM(U15:AF15) -> 0 | AH15: =IFERROR(AG15/AG$16,"") | AJ15: =AG15-N15 -> 0
A16: Total - Income | B16: =B14+B15 -> 0 | C16: =C14+C15 -> 0 | D16: =D14+D15 -> 0 | E16: =E14+E15 -> 0 | F16: =F14+F15 -> 0 | G16: =G14+G15 -> 0 | H16: =H14+H15 -> 0 | I16: =I14+I15 -> 0 | ... M16: =M14+M15 -> 0 | N16: =SUM(B16:M16) -> 0 | O16: =SUM(O14:O15) -> 0 | U16: =U14+U15 -> 0 | V16: =V14+V15 -> 0 | W16: =W14+W15 -> 0 | X16: =X14+X15 -> 0 | Y16: =Y14+Y15 -> 0 | Z16: =Z14+Z15 -> 0 | AA16: =AA14+AA15 -> 0 | AB16: =AB14+AB15 -> 0 | ... AF16: =AF14+AF15 -> 0 | AG16: =SUM(U16:AF16) -> 0 | AH16: =SUM(AH14:AH15) -> 0 | AJ16: =AG16-N16 -> 0
A17: Cost Of Sales
A18: 5000 - Robot Production and Deployment
A19: 5010 - SlipBot Depreciation | B19: 0 | C19: 0 | D19: 0 | E19: 0 | F19: 0 | G19: 0 | H19: 0 | I19: 0 | N19: =SUM(B19:M19) -> 0 | O19: =IFERROR(N19/N$16,"") | R19: Even | S19: 0 | T19: 0.05 | U19: =IF($R19="Manual","",IFERROR(IF($R19="YOY Growth",$N19*(1+$T19)/12,$S19/12),"")) -> 0 | V19: =IF($R19="Manual","",IFERROR(IF($R19="YOY Growth",$N19*(1+$T19)/12,$S19/12),"")) -> 0 | W19: =IF($R19="Manual","",IFERROR(IF($R19="YOY Growth",$N19*(1+$T19)/12,$S19/12),"")) -> 0 | X19: =IF($R19="Manual","",IFERROR(IF($R19="YOY Growth",$N19*(1+$T19)/12,$S19/12),"")) -> 0 | Y19: =IF($R19="Manual","",IFERROR(IF($R19="YOY Growth",$N19*(1+$T19)/12,$S19/12),"")) -> 0 | Z19: =IF($R19="Manual","",IFERROR(IF($R19="YOY Growth",$N19*(1+$T19)/12,$S19/12),"")) -> 0 | AA19: =IF($R19="Manual","",IFERROR(IF($R19="YOY Growth",$N19*(1+$T19)/12,$S19/12),"")) -> 0 | AB19: =IF($R19="Manual","",IFERROR(IF($R19="YOY Growth",$N19*(1+$T19)/12,$S19/12),"")) -> 0 | ... AF19: =IF($R19="Manual","",IFERROR(IF($R19="YOY Growth",$N19*(1+$T19)/12,$S19/12),"")) -> 0 | AG19: =SUM(U19:AF19) -> 0 | AH19: =IFERROR(AG19/AG$16,"") | AJ19: =N19-AG19 -> 0
A20: 5011 - SlipLift Depreciation | B20: 0 | C20: 0 | D20: 0 | E20: 0 | F20: 0 | G20: 0 | H20: 0 | I20: 0 | N20: =SUM(B20:M20) -> 0 | O20: =IFERROR(N20/N$16,"") | R20: Even | S20: 0 | T20: 0.05 | U20: =IF($R20="Manual","",IFERROR(IF($R20="YOY Growth",$N20*(1+$T20)/12,$S20/12),"")) -> 0 | V20: =IF($R20="Manual","",IFERROR(IF($R20="YOY Growth",$N20*(1+$T20)/12,$S20/12),"")) -> 0 | W20: =IF($R20="Manual","",IFERROR(IF($R20="YOY Growth",$N20*(1+$T20)/12,$S20/12),"")) -> 0 | X20: =IF($R20="Manual","",IFERROR(IF($R20="YOY Growth",$N20*(1+$T20)/12,$S20/12),"")) -> 0 | Y20: =IF($R20="Manual","",IFERROR(IF($R20="YOY Growth",$N20*(1+$T20)/12,$S20/12),"")) -> 0 | Z20: =IF($R20="Manual","",IFERROR(IF($R20="YOY Growth",$N20*(1+$T20)/12,$S20/12),"")) -> 0 | AA20: =IF($R20="Manual","",IFERROR(IF($R20="YOY Growth",$N20*(1+$T20)/12,$S20/12),"")) -> 0 | AB20: =IF($R20="Manual","",IFERROR(IF($R20="YOY Growth",$N20*(1+$T20)/12,$S20/12),"")) -> 0 | ... AF20: =IF($R20="Manual","",IFERROR(IF($R20="YOY Growth",$N20*(1+$T20)/12,$S20/12),"")) -> 0 | AG20: =SUM(U20:AF20) -> 0 | AH20: =IFERROR(AG20/AG$16,"") | AJ20: =N20-AG20 -> 0
A21: 5012 - SlipCarrier Depreciation | B21: 0 | C21: 0 | D21: 0 | E21: 0 | F21: 0 | G21: 0 | H21: 0 | I21: 0 | N21: =SUM(B21:M21) -> 0 | O21: =IFERROR(N21/N$16,"") | R21: Even | S21: 0 | T21: 0.05 | U21: =IF($R21="Manual","",IFERROR(IF($R21="YOY Growth",$N21*(1+$T21)/12,$S21/12),"")) -> 0 | V21: =IF($R21="Manual","",IFERROR(IF($R21="YOY Growth",$N21*(1+$T21)/12,$S21/12),"")) -> 0 | W21: =IF($R21="Manual","",IFERROR(IF($R21="YOY Growth",$N21*(1+$T21)/12,$S21/12),"")) -> 0 | X21: =IF($R21="Manual","",IFERROR(IF($R21="YOY Growth",$N21*(1+$T21)/12,$S21/12),"")) -> 0 | Y21: =IF($R21="Manual","",IFERROR(IF($R21="YOY Growth",$N21*(1+$T21)/12,$S21/12),"")) -> 0 | Z21: =IF($R21="Manual","",IFERROR(IF($R21="YOY Growth",$N21*(1+$T21)/12,$S21/12),"")) -> 0 | AA21: =IF($R21="Manual","",IFERROR(IF($R21="YOY Growth",$N21*(1+$T21)/12,$S21/12),"")) -> 0 | AB21: =IF($R21="Manual","",IFERROR(IF($R21="YOY Growth",$N21*(1+$T21)/12,$S21/12),"")) -> 0 | ... AF21: =IF($R21="Manual","",IFERROR(IF($R21="YOY Growth",$N21*(1+$T21)/12,$S21/12),"")) -> 0 | AG21: =SUM(U21:AF21) -> 0 | AH21: =IFERROR(AG21/AG$16,"") | AJ21: =N21-AG21 -> 0
A22: 5020 - Robot Peripherals Depreciation | B22: 0 | C22: 0 | D22: 0 | E22: 0 | F22: 0 | G22: 0 | H22: 0 | I22: 0 | N22: =SUM(B22:M22) -> 0 | O22: =IFERROR(N22/N$16,"") | R22: Even | S22: 0 | T22: 0.05 | U22: =IF($R22="Manual","",IFERROR(IF($R22="YOY Growth",$N22*(1+$T22)/12,$S22/12),"")) -> 0 | V22: =IF($R22="Manual","",IFERROR(IF($R22="YOY Growth",$N22*(1+$T22)/12,$S22/12),"")) -> 0 | W22: =IF($R22="Manual","",IFERROR(IF($R22="YOY Growth",$N22*(1+$T22)/12,$S22/12),"")) -> 0 | X22: =IF($R22="Manual","",IFERROR(IF($R22="YOY Growth",$N22*(1+$T22)/12,$S22/12),"")) -> 0 | Y22: =IF($R22="Manual","",IFERROR(IF($R22="YOY Growth",$N22*(1+$T22)/12,$S22/12),"")) -> 0 | Z22: =IF($R22="Manual","",IFERROR(IF($R22="YOY Growth",$N22*(1+$T22)/12,$S22/12),"")) -> 0 | AA22: =IF($R22="Manual","",IFERROR(IF($R22="YOY Growth",$N22*(1+$T22)/12,$S22/12),"")) -> 0 | AB22: =IF($R22="Manual","",IFERROR(IF($R22="YOY Growth",$N22*(1+$T22)/12,$S22/12),"")) -> 0 | ... AF22: =IF($R22="Manual","",IFERROR(IF($R22="YOY Growth",$N22*(1+$T22)/12,$S22/12),"")) -> 0 | AG22: =SUM(U22:AF22) -> 0 | AH22: =IFERROR(AG22/AG$16,"") | AJ22: =N22-AG22 -> 0
A23: 5025 - Freight and Delivery - Production (Summary)
A24: 5025 - Freight and Delivery - Production (Summary) | B24: 376 | C24: 850.7 | D24: 783.62 | E24: 1861.07 | F24: 0 | G24: 0 | H24: 0 | I24: 0 | J24: 0 | K24: 0 | L24: 0 | M24: 0 | N24: =SUM(B24:M24) -> 3871.39 | O24: =IFERROR(N24/N$16,"") | R24: Even | S24: 0 | T24: 0.05 | U24: =IF($R24="Manual","",IFERROR(IF($R24="YOY Growth",$N24*(1+$T24)/12,$S24/12),"")) -> 0 | V24: =IF($R24="Manual","",IFERROR(IF($R24="YOY Growth",$N24*(1+$T24)/12,$S24/12),"")) -> 0 | W24: =IF($R24="Manual","",IFERROR(IF($R24="YOY Growth",$N24*(1+$T24)/12,$S24/12),"")) -> 0 | X24: =IF($R24="Manual","",IFERROR(IF($R24="YOY Growth",$N24*(1+$T24)/12,$S24/12),"")) -> 0 | Y24: =IF($R24="Manual","",IFERROR(IF($R24="YOY Growth",$N24*(1+$T24)/12,$S24/12),"")) -> 0 | Z24: =IF($R24="Manual","",IFERROR(IF($R24="YOY Growth",$N24*(1+$T24)/12,$S24/12),"")) -> 0 | AA24: =IF($R24="Manual","",IFERROR(IF($R24="YOY Growth",$N24*(1+$T24)/12,$S24/12),"")) -> 0 | AB24: =IF($R24="Manual","",IFERROR(IF($R24="YOY Growth",$N24*(1+$T24)/12,$S24/12),"")) -> 0 | ... AF24: =IF($R24="Manual","",IFERROR(IF($R24="YOY Growth",$N24*(1+$T24)/12,$S24/12),"")) -> 0 | AG24: =SUM(U24:AF24) -> 0 | AH24: =IFERROR(AG24/AG$16,"") | AJ24: =N24-AG24 -> 3871.39
A25: 5026 - Freight and Delivery - Production - Expedited | B25: 0 | C25: 0 | D25: 0 | E25: 261.8 | F25: 0 | G25: 0 | H25: 0 | I25: 0 | J25: 0 | K25: 0 | L25: 0 | M25: 0 | N25: =SUM(B25:M25) -> 261.8 | O25: =IFERROR(N25/N$16,"") | R25: Even | S25: 0 | T25: 0.05 | U25: =IF($R25="Manual","",IFERROR(IF($R25="YOY Growth",$N25*(1+$T25)/12,$S25/12),"")) -> 0 | V25: =IF($R25="Manual","",IFERROR(IF($R25="YOY Growth",$N25*(1+$T25)/12,$S25/12),"")) -> 0 | W25: =IF($R25="Manual","",IFERROR(IF($R25="YOY Growth",$N25*(1+$T25)/12,$S25/12),"")) -> 0 | X25: =IF($R25="Manual","",IFERROR(IF($R25="YOY Growth",$N25*(1+$T25)/12,$S25/12),"")) -> 0 | Y25: =IF($R25="Manual","",IFERROR(IF($R25="YOY Growth",$N25*(1+$T25)/12,$S25/12),"")) -> 0 | Z25: =IF($R25="Manual","",IFERROR(IF($R25="YOY Growth",$N25*(1+$T25)/12,$S25/12),"")) -> 0 | AA25: =IF($R25="Manual","",IFERROR(IF($R25="YOY Growth",$N25*(1+$T25)/12,$S25/12),"")) -> 0 | AB25: =IF($R25="Manual","",IFERROR(IF($R25="YOY Growth",$N25*(1+$T25)/12,$S25/12),"")) -> 0 | ... AF25: =IF($R25="Manual","",IFERROR(IF($R25="YOY Growth",$N25*(1+$T25)/12,$S25/12),"")) -> 0 | AG25: =SUM(U25:AF25) -> 0 | AH25: =IFERROR(AG25/AG$16,"") | AJ25: =N25-AG25 -> 261.8
A26: 5027 - Freight and Delivery - Production - Standard | B26: 0 | C26: 0 | D26: 0 | E26: 348.38 | F26: 79.47 | G26: 0 | H26: 0 | I26: 250 | J26: 0 | K26: 0 | L26: 0 | M26: 0 | N26: =SUM(B26:M26) -> 677.85 | O26: =IFERROR(N26/N$16,"") | R26: Even | S26: 0 | T26: 0.05 | U26: =IF($R26="Manual","",IFERROR(IF($R26="YOY Growth",$N26*(1+$T26)/12,$S26/12),"")) -> 0 | V26: =IF($R26="Manual","",IFERROR(IF($R26="YOY Growth",$N26*(1+$T26)/12,$S26/12),"")) -> 0 | W26: =IF($R26="Manual","",IFERROR(IF($R26="YOY Growth",$N26*(1+$T26)/12,$S26/12),"")) -> 0 | X26: =IF($R26="Manual","",IFERROR(IF($R26="YOY Growth",$N26*(1+$T26)/12,$S26/12),"")) -> 0 | Y26: =IF($R26="Manual","",IFERROR(IF($R26="YOY Growth",$N26*(1+$T26)/12,$S26/12),"")) -> 0 | Z26: =IF($R26="Manual","",IFERROR(IF($R26="YOY Growth",$N26*(1+$T26)/12,$S26/12),"")) -> 0 | AA26: =IF($R26="Manual","",IFERROR(IF($R26="YOY Growth",$N26*(1+$T26)/12,$S26/12),"")) -> 0 | AB26: =IF($R26="Manual","",IFERROR(IF($R26="YOY Growth",$N26*(1+$T26)/12,$S26/12),"")) -> 0 | ... AF26: =IF($R26="Manual","",IFERROR(IF($R26="YOY Growth",$N26*(1+$T26)/12,$S26/12),"")) -> 0 | AG26: =SUM(U26:AF26) -> 0 | AH26: =IFERROR(AG26/AG$16,"") | AJ26: =N26-AG26 -> 677.85
A27: Total - 5025 - Freight and Delivery - Production (Summary) | B27: =SUM(B24:B26) -> 376 | C27: =SUM(C24:C26) -> 850.7 | D27: =SUM(D24:D26) -> 783.62 | E27: =SUM(E24:E26) -> 2471.25 | F27: =SUM(F24:F26) -> 79.47 | G27: =SUM(G24:G26) -> 0 | H27: =SUM(H24:H26) -> 0 | I27: =SUM(I24:I26) -> 250 | ... M27: =SUM(M24:M26) -> 0 | N27: =SUM(B27:M27) -> 4811.04 | O27: =IFERROR(N27/N$16,"") | U27: =SUM(U24:U26) -> 0 | V27: =SUM(V24:V26) -> 0 | W27: =SUM(W24:W26) -> 0 | X27: =SUM(X24:X26) -> 0 | Y27: =SUM(Y24:Y26) -> 0 | Z27: =SUM(Z24:Z26) -> 0 | AA27: =SUM(AA24:AA26) -> 0 | AB27: =SUM(AB24:AB26) -> 0 | ... AF27: =SUM(AF24:AF26) -> 0 | AG27: =SUM(U27:AF27) -> 0 | AH27: =IFERROR(AG27/AG$16,"") | AJ27: =N27-AG27 -> 4811.04
A28: 5030 - Production Tools and Supplies | B28: 0 | C28: 0 | D28: 0 | E28: 2186.18 | F28: 0 | G28: 0 | H28: 117.53 | I28: 0 | J28: 0 | K28: 0 | L28: 0 | M28: 0 | N28: =SUM(B28:M28) -> 2303.71 | O28: =IFERROR(N28/N$16,"") | R28: Even | S28: 0 | T28: 0.05 | U28: =IF($R28="Manual","",IFERROR(IF($R28="YOY Growth",$N28*(1+$T28)/12,$S28/12),"")) -> 0 | V28: =IF($R28="Manual","",IFERROR(IF($R28="YOY Growth",$N28*(1+$T28)/12,$S28/12),"")) -> 0 | W28: =IF($R28="Manual","",IFERROR(IF($R28="YOY Growth",$N28*(1+$T28)/12,$S28/12),"")) -> 0 | X28: =IF($R28="Manual","",IFERROR(IF($R28="YOY Growth",$N28*(1+$T28)/12,$S28/12),"")) -> 0 | Y28: =IF($R28="Manual","",IFERROR(IF($R28="YOY Growth",$N28*(1+$T28)/12,$S28/12),"")) -> 0 | Z28: =IF($R28="Manual","",IFERROR(IF($R28="YOY Growth",$N28*(1+$T28)/12,$S28/12),"")) -> 0 | AA28: =IF($R28="Manual","",IFERROR(IF($R28="YOY Growth",$N28*(1+$T28)/12,$S28/12),"")) -> 0 | AB28: =IF($R28="Manual","",IFERROR(IF($R28="YOY Growth",$N28*(1+$T28)/12,$S28/12),"")) -> 0 | ... AF28: =IF($R28="Manual","",IFERROR(IF($R28="YOY Growth",$N28*(1+$T28)/12,$S28/12),"")) -> 0 | AG28: =SUM(U28:AF28) -> 0 | AH28: =IFERROR(AG28/AG$16,"") | AJ28: =N28-AG28 -> 2303.71
A29: 5040 - Freight & Delivery - Deployment | B29: 7000 | C29: 5000.95 | D29: 3522.7 | E29: 3294.47 | F29: 0 | G29: 122.59 | H29: 0 | I29: 3240.99 | J29: 15000 | K29: 10000 | L29: 5000 | M29: 5000 | N29: =SUM(B29:M29) -> 57181.7 | O29: =IFERROR(N29/N$16,"") | R29: Even | S29: 0 | T29: 0.05 | U29: =IF($R29="Manual","",IFERROR(IF($R29="YOY Growth",$N29*(1+$T29)/12,$S29/12),"")) -> 0 | V29: =IF($R29="Manual","",IFERROR(IF($R29="YOY Growth",$N29*(1+$T29)/12,$S29/12),"")) -> 0 | W29: =IF($R29="Manual","",IFERROR(IF($R29="YOY Growth",$N29*(1+$T29)/12,$S29/12),"")) -> 0 | X29: =IF($R29="Manual","",IFERROR(IF($R29="YOY Growth",$N29*(1+$T29)/12,$S29/12),"")) -> 0 | Y29: =IF($R29="Manual","",IFERROR(IF($R29="YOY Growth",$N29*(1+$T29)/12,$S29/12),"")) -> 0 | Z29: =IF($R29="Manual","",IFERROR(IF($R29="YOY Growth",$N29*(1+$T29)/12,$S29/12),"")) -> 0 | AA29: =IF($R29="Manual","",IFERROR(IF($R29="YOY Growth",$N29*(1+$T29)/12,$S29/12),"")) -> 0 | AB29: =IF($R29="Manual","",IFERROR(IF($R29="YOY Growth",$N29*(1+$T29)/12,$S29/12),"")) -> 0 | ... AF29: =IF($R29="Manual","",IFERROR(IF($R29="YOY Growth",$N29*(1+$T29)/12,$S29/12),"")) -> 0 | AG29: =SUM(U29:AF29) -> 0 | AH29: =IFERROR(AG29/AG$16,"") | AJ29: =N29-AG29 -> 57181.7
A30: 5050 - Travel - Deployment | B30: 0 | C30: 0 | D30: 0 | E30: 0 | F30: 0 | G30: 0 | H30: 911.81 | I30: 1772.23 | J30: 0 | K30: 0 | L30: 0 | M30: 0 | N30: =SUM(B30:M30) -> 2684.04 | O30: =IFERROR(N30/N$16,"") | R30: Even | S30: 0 | T30: 0.05 | U30: =IF($R30="Manual","",IFERROR(IF($R30="YOY Growth",$N30*(1+$T30)/12,$S30/12),"")) -> 0 | V30: =IF($R30="Manual","",IFERROR(IF($R30="YOY Growth",$N30*(1+$T30)/12,$S30/12),"")) -> 0 | W30: =IF($R30="Manual","",IFERROR(IF($R30="YOY Growth",$N30*(1+$T30)/12,$S30/12),"")) -> 0 | X30: =IF($R30="Manual","",IFERROR(IF($R30="YOY Growth",$N30*(1+$T30)/12,$S30/12),"")) -> 0 | Y30: =IF($R30="Manual","",IFERROR(IF($R30="YOY Growth",$N30*(1+$T30)/12,$S30/12),"")) -> 0 | Z30: =IF($R30="Manual","",IFERROR(IF($R30="YOY Growth",$N30*(1+$T30)/12,$S30/12),"")) -> 0 | AA30: =IF($R30="Manual","",IFERROR(IF($R30="YOY Growth",$N30*(1+$T30)/12,$S30/12),"")) -> 0 | AB30: =IF($R30="Manual","",IFERROR(IF($R30="YOY Growth",$N30*(1+$T30)/12,$S30/12),"")) -> 0 | ... AF30: =IF($R30="Manual","",IFERROR(IF($R30="YOY Growth",$N30*(1+$T30)/12,$S30/12),"")) -> 0 | AG30: =SUM(U30:AF30) -> 0 | AH30: =IFERROR(AG30/AG$16,"") | AJ30: =N30-AG30 -> 2684.04
A31: 5060 - Meals - Deployment | B31: 0 | C31: 0 | D31: 0 | E31: 0 | F31: 0 | G31: 20.14 | H31: 0 | I31: 528.6 | J31: 0 | K31: 0 | L31: 0 | M31: 0 | N31: =SUM(B31:M31) -> 548.74 | O31: =IFERROR(N31/N$16,"") | R31: Even | S31: 0 | T31: 0.05 | U31: =IF($R31="Manual","",IFERROR(IF($R31="YOY Growth",$N31*(1+$T31)/12,$S31/12),"")) -> 0 | V31: =IF($R31="Manual","",IFERROR(IF($R31="YOY Growth",$N31*(1+$T31)/12,$S31/12),"")) -> 0 | W31: =IF($R31="Manual","",IFERROR(IF($R31="YOY Growth",$N31*(1+$T31)/12,$S31/12),"")) -> 0 | X31: =IF($R31="Manual","",IFERROR(IF($R31="YOY Growth",$N31*(1+$T31)/12,$S31/12),"")) -> 0 | Y31: =IF($R31="Manual","",IFERROR(IF($R31="YOY Growth",$N31*(1+$T31)/12,$S31/12),"")) -> 0 | Z31: =IF($R31="Manual","",IFERROR(IF($R31="YOY Growth",$N31*(1+$T31)/12,$S31/12),"")) -> 0 | AA31: =IF($R31="Manual","",IFERROR(IF($R31="YOY Growth",$N31*(1+$T31)/12,$S31/12),"")) -> 0 | AB31: =IF($R31="Manual","",IFERROR(IF($R31="YOY Growth",$N31*(1+$T31)/12,$S31/12),"")) -> 0 | ... AF31: =IF($R31="Manual","",IFERROR(IF($R31="YOY Growth",$N31*(1+$T31)/12,$S31/12),"")) -> 0 | AG31: =SUM(U31:AF31) -> 0 | AH31: =IFERROR(AG31/AG$16,"") | AJ31: =N31-AG31 -> 548.74
A32: 5100 - Labor Expense - Production
A33: 5110 - Salaries and Wages - Production | B33: 0 | C33: 0 | D33: 0 | E33: 0 | F33: 0 | G33: 0 | H33: 0 | I33: 0 | J33: 0 | K33: 0 | L33: 0 | M33: 0 | N33: =SUM(B33:M33) -> 0 | O33: =IFERROR(N33/N$16,"") | AG33: =SUM(U33:AF33) -> 0 | AH33: =IFERROR(AG33/AG$16,"") | AJ33: =N33-AG33 -> 0
A34: 5130 - Payroll Taxes - Production | B34: 0 | C34: 0 | D34: 0 | E34: 0 | F34: 0 | G34: 0 | H34: 0 | I34: 0 | J34: 0 | K34: 0 | L34: 0 | M34: 0 | N34: =SUM(B34:M34) -> 0 | O34: =IFERROR(N34/N$16,"") | AG34: =SUM(U34:AF34) -> 0 | AH34: =IFERROR(AG34/AG$16,"") | AJ34: =N34-AG34 -> 0
A35: 5140 - Benefits - Production | B35: 0 | C35: 0 | D35: 0 | E35: 0 | F35: 0 | G35: 0 | H35: 0 | I35: 0 | J35: 0 | K35: 0 | L35: 0 | M35: 0 | N35: =SUM(B35:M35) -> 0 | O35: =IFERROR(N35/N$16,"") | AG35: =SUM(U35:AF35) -> 0 | AH35: =IFERROR(AG35/AG$16,"") | AJ35: =N35-AG35 -> 0
A36: Total - 5100 - Labor Expense - Production | B36: =SUM(B33:B35) -> 0 | C36: =SUM(C33:C35) -> 0 | D36: =SUM(D33:D35) -> 0 | E36: =SUM(E33:E35) -> 0 | F36: =SUM(F33:F35) -> 0 | G36: =SUM(G33:G35) -> 0 | H36: =SUM(H33:H35) -> 0 | I36: =SUM(I33:I35) -> 0 | ... M36: =SUM(M33:M35) -> 0 | N36: =SUM(B36:M36) -> 0 | O36: =IFERROR(N36/N$16,"") | U36: =SUM(U33:U35) -> 0 | V36: =SUM(V33:V35) -> 0 | W36: =SUM(W33:W35) -> 0 | X36: =SUM(X33:X35) -> 0 | Y36: =SUM(Y33:Y35) -> 0 | Z36: =SUM(Z33:Z35) -> 0 | AA36: =SUM(AA33:AA35) -> 0 | AB36: =SUM(AB33:AB35) -> 0 | ... AF36: =SUM(AF33:AF35) -> 0 | AG36: =SUM(U36:AF36) -> 0 | AH36: =IFERROR(AG36/AG$16,"") | AJ36: =N36-AG36 -> 0
