Workbook
Name _EPS01: #REF!
Name _EPS02: #REF!
Name _EPS1: #REF!
Name _EPS2: #REF!
Name _EPS3: #REF!
Name _EPS99: #REF!
Name _exp2: #REF!
Name _lev2: #REF!
Name _Low1: #REF!
Name _Low2: #REF!
Name _Low3: #REF!
Name _Low4: #REF!
Name _Low5: #REF!
Name _Low6: #REF!
Name _Low7: #REF!
Name _Low8: #REF!
Name _Low9: #REF!
Name _mu2: #REF!
Name _PE1: #REF!
Name _PE2: #REF!
Name _PE3: #REF!
Name _PFY1: #REF!
Name _PFY2: #REF!
Name _PFY3: #REF!
Name _PFY4: #REF!
Name _pr2: #REF!
Name _TAB1: #REF!
Name _Yr1: #REF!
Name _Yr2: #REF!
Name aaaafff: #REF!
Name AccPay: #REF!
Name AccRec: #REF!
Name ACCRETE: #REF!
Name Acq: #REF!
Name AcqNum: #REF!
Name AcqTrig: #REF!
Name Acquirors: #REF!
Name AdjTaxes: #REF!
Name ADLTM: #REF!
Name ADYear1: #REF!
Name ADYear2: #REF!
Name AfterTaxItems: #REF!
Name allokay: #REF!
Name allsicempty: #REF!
Name AmortLTM: #REF!
Name AmortPeriod: #REF!
Name AmortYear1: #REF!
Name AmortYear2: #REF!
Name amt: #REF!
Name Assets: #REF!
Name AssetsA: #REF!
Name AssetsT: #REF!
Name AssetWriteup: #REF!
Name AttritionMonthly: #REF!
Name AVG_CPM: #REF!
Name AvgShares: #REF!
Name BaseTick: #REF!
Name Beg_Bal: #REF!
Name BenefitsLoad: #REF!
Name Beta: #REF!

Sheet Claude Log
A1: Turn # | B1: Date | C1: User Request | D1: Action Taken | E1: Details | F1: Outcome
A2: 1 | B2: 46281 | C2: Make the COO P&L tab the sum of FO, PO, CO, FE and PE; also asked that all sheets be formatted the same. | D2: Rewrote all single-sheet pull formulas on COO; compared formatting across the six P&L tabs. | E2: 2,142 cells in COO!A9:AJ145 changed from =SUM(PO!x) to =SUM(FO!x,PO!x,CO!x,FE!x,PE!x). Formatting: user chose fonts/number formats/column widths only (no fill changes). Set uniform column widths on all six P&L tabs (A=301.5; month cols 62.5; N=78; O=70; P/Q=41.5; R=82.5; S=75; T=70.5; AG=78), body font Calibri 10 in A9:AJ145, and copied COO's line-item number formats to B9:Q142 and U9:AJ142 on FO/PO/CO/FE/PE. Excluded dept-only budget driver columns R:T and header rows 1:8; left all cell fills and font colors (blue = input convention) untouched. | F2: Verified: no error values on any of the six tabs; COO tie-out check row 133 nets to ~0 in every column; number formats in the shared body now identical across all six tabs; % rows (e.g. row 65 margins) now render as percentages on the dept tabs. Fill/highlight differences intentionally left as-is.
A3: 2 | B3: 46283 | C3: Add a headcount (#) summary to the COO HC total tab. | D3: Built a monthly active-headcount roll-up by department plus a COGS/SG&A split on COO HC rows 64-76. | E3: Rows 65-69 use =COUNTIF('<Dept> HC'!I$14:I$57,">0") per month (counts any employee/new hire/transfer-in row carrying salary in that month; transfer-out memo rows carry no cost so they aren't double-counted). Row 70 totals; rows 73-74 split via SUMIF on the D65:D69 P&L classification; row 75 total and row 76 tie-out check. Column Z shows Dec-27 ending headcount (point in time) rather than a sum of months, labeled in Z64. | F3: COO HC!B64:Z76. Sep-26 total 35 (PO 9, FO 16, FE 6, PE 0, CO 4); Dec-27 ending 36. Tie-out row 76 = 0 in every month. Verified I65:X76 and Z65:Z75 read back with no errors.
A4: 3 | B4: 46283 | C4: Excel agent (CRO HC and PL workfile) asked for the COO HC headcount summary so it could replicate the block on its CRO HC tab. | D4: Read the block with styles plus surrounding context and shared it as a file with the other Excel file; no changes made to this workbook. | E4: Shared coo-hc-headcount-summary.json containing values, formulas, displayed text, number formats, styling and layout notes for COO HC!B62:Z78 and the row 8-12 header context. Documented the COUNTIF('<Dept> HC'!I$14:I$57,">0") pattern, the SUMIF P&L split off D65:D69, and that column Z is Dec-27 ending headcount rather than a sum. | F4: File shared and message sent to the CRO workbook agent. Note: PE HC now has 9 staffed rows (added outside this chat), so COO totals now read 44 in Sep-26 and 45 from Oct-26 on; tie-out row 76 still 0 in every month.
A5: 4 | B5: 46283 | C5: Status update from the CRO workbook agent confirming it replicated the headcount summary; no action requested. | D5: Absorbed the update; no changes to this workbook beyond this log entry. | E5: CRO built the block at CRO HC!B54:Z64 (offset because CRO's grid ends at row 52): row 54 header, 55-57 AM/MK/SL, 58 total, 60 header, 61 COGS, 62 SG&A, 63 total, 64 check. It used =COUNTIF('<Dept> HC'!I$14:I$52,">0") since CRO dept tabs are cost-bearing through row 52 (transfers-in 47:52, transfer-out memo 54:59) versus 14:57 here. Same SUMIF split, Z as point-in-time, same formats. | F5: Noted: the row-range difference is a correct adaptation to CRO's tab layout, not an inconsistency. CRO reports no errors and a zero check row across all 16 months.
A6: 5 | B6: 46283 | C6: A Total Company roll-up workbook (Book1) asked for a structure map of this file so it can point external-link formulas at the right cells; explicitly no changes to this workbook. | D6: Read the layout of all five department HC tabs to confirm they are identical, then shared coo-map.json. No cells in this workbook were modified. | E6: Map covers: month grid (dates row 10, index row 11, columns I=Sep-26 through X=Dec-27, Y spacer), roster blocks (current employees 14-33, open positions 35-39, new hires 41-50, transfers-in 52-57 cost-bearing, transfers-out 59-64 memo-only, effective month in column E and end month in F), totals rows 67 S&W / 68 taxes / 69 benefits / 70 total payroll, per-dept names, codes, P&L class (PO+FO = COGS; FE, PE, CO = SG&A) and GL accounts, plus the COO HC roll-up row map. | F6: File shared and message sent to the Book1 agent, recommending it link to the COO HC roll-up rather than re-summing the department tabs. Verified all five dept tabs use the same row layout and =SUM(I14:I57) for Total Salaries & Wages.
A7: 7 | B7: 46286 | C7: CEO workbook agent asked for a hc-transfers.csv listing every transfer-in/out row and any current employee flagged "Transfer out" in column A, for a cross-file transfer reconciliation. | D7: Scanned column A and the transfers sections of all five department HC tabs (FO, PO, CO, FE, PE) plus the COO HC roll-up; shared hc-transfers.csv (header row only). No changes to workbook data. | E7: Transfers-In block sits at rows 52-57 and Transfers-Out memo block at rows 59-64 on each dept tab; all of these rows are blank (name, title, salary, start/end all empty). No current-employee row on any tab carries a "Transfer out" flag in column A - column A holds only the "From Dept"/"To Dept" section labels. COO HC is a formula roll-up with no employee rows. | F7: hc-transfers.csv shared with headers block,dept_code,counterparty_dept,employee,title,annual_salary,start_month,end_month and zero data rows: the COO workbook currently has no inter-department transfer activity.
A8: 8 | B8: 46289 | C8: CEO workbook agent asked (read-only) for hc-transfers.csv in a new column layout: sheet, row, block (IN/OUT/ROSTER), own_dept, counterparty_dept, employee, title, annual_salary, start_month, end_month. | D8: Re-scanned FO/PO/CO/FE/PE HC tabs and shared hc-transfers.csv (header row only). No workbook data changed. | E8: Blocks located by their headers on each tab: Transfers In rows 52-57 (header row 51), Transfers Out rows 59-66 (header row 58), totals from row 67. Rows counted as populated if cols A-E had any content (F:H hold template defaults for end month / increase % / increase month). Column A of roster rows checked for any 'Transfer' flag - none found. | F8: Zero transfer rows across all five tabs; confirmed to CEO agent. Correction to turn 5 map: Transfers Out memo block runs rows 59-66, not 59-64.
A9: 9 | B9: 46289 | C9: CEO workbook agent asked (read-only) to re-share hc-transfers.csv from FO/PO/CO/FE/PE HC in the same columns and say whether anything changed since the last extract. | D9: Re-scanned the five dept HC tabs and re-shared hc-transfers.csv (header row only). No workbook data changed. | E9: Same logic as turn 8: blocks located by header (Transfers In header row 51 / rows 52-57; Transfers Out header row 58 / rows 59-66; totals row 67 on every tab). Checked cols A-E for content, Transfers In F:H for any non-default values, and roster column A for any 'Transfer' flag. | F9: No change since turn 8: zero transfer rows, no transfer-out flags, block positions unchanged, F:H still template defaults. Reported to CEO agent.
A10: 10 | B10: 46289 | C10: CEO workfile (Excel peer) requested read-only export of all Transfers In/Out rows and 'Transfer out'-flagged current employees on each HC tab as hc-transfers.csv. | D10: Scanned HC tabs and shared hc-transfers.csv (header only). | E10: Checked FO/PO/CO/FE/PE HC Transfers In (rows 52-57) and Transfers Out (rows 59-66) for any entries in cols A-D; searched all cells for 'transfer' flags on current employees. COO HC is a formula roll-up with no transfer rows. No workbook data edited. | F10: No transfer activity found; header-only CSV shared and CEO agent notified.
A11: 11 | B11: 46290 | C11: Peer (TC PL Rollup Excel) requested read-only layout export of the 2027 Budget P&L tabs for linking. | D11: Wrote shared file layout-COO.json; no workbook data changed | E11: Tabs: COO P&L, FO, PO, CO, FE, PE. Budget Jan-Dec = U:AF, FY2027 = AG, Net Income row 132. Budget cells almost all formulas (COO P&L has 12 hardcoded zeros in U124:AF124). | F11: File shared with rollup agent; reply sent
A12: 12 | B12: 46290 | C12: Rollup Excel agent (read-only request): report HC tabs A1:H10, D5/D6 labels & references, external links, sheet names; write hc_info_COO.json | D12: Read-only scan; wrote shared file hc_info_COO.json; replied to Rollup agent | E12: HC tabs: COO HC (summary, D5/D6 blank), FO/PO/CO/FE/PE HC. D5 blank (B5 'ASSUMPTIONS'); D6=0.04 payroll tax rate, referenced 16x per tab in row 68 (=I67*$D$6). External links: ~2,160 formulas per P&L tab to [2027B Expense TC Prep w Aug Act.xlsx]; none to 2027B TC PL Rollup. | F12: No workbook data changed (only this log row added)
A13: 13 | B13: 46290 | C13: Rollup Excel agent asked to apply hc_rate_links.json: link D6 (payroll tax) and D7 (benefits) on CO/FE/FO/PE/PO HC to the rollup's T&B rates, green font, 0.0% | D13: Replaced hardcoded 4%/9% in D6:D7 on 5 HC tabs with external INDEX/MATCH links | E13: Formula: =INDEX('G:\My Drive\SLIP Folders\Budget\2027\[2027B TC PL Rollup.xlsx]T&B'!$S$104:$S$120 (D6) / $T (D7), MATCH(dept code, $R$104:$R$120,0)). Prior values 0.04/0.09 on all 5 tabs. COO HC untouched. | F13: CO 5.2%/11.9%, FE 4.1%/7.2%, FO 6.8%/16.4%, PE 3.6%/8.8%, PO 3.6%/6.2%; all match expected, no errors
A14: 14 | B14: 46290 | C14: Rollup agent asked to read back (no edits) D6/D7 T&B formulas on CO/FE/FO/PE/PO HC after rollup summary moved to R11:T27, confirm refs and values, then save. | D14: Read-only verification of D6:D7 on 5 HC sheets; saved workbook | E14: Formulas use INDEX/MATCH on '[2027B TC PL Rollup.xlsx]T&B' with ranges $R$11:$R$120 / $S$11:$S$120 / $T$11:$T$120 (not $11:$27 as expected). No errors. Values: CO 5.2%/11.9%, FE 4.1%/7.2%, FO 6.8%/16.4%, PE 3.6%/8.8%, PO 3.6%/20.6%. | F14: All values match expected; range end-row discrepancy ($120 vs $27) reported to rollup agent, not edited

Sheet Headcount -->

Sheet COO HC
A1: Slip Robotics, Inc.
A2: COO — ORGANIZATION ROLL-UP | Sep-2026 → Dec-2027 | 2027 Budget Planning
A3: Rolls up the department tabs in this workbook. All figures are formulas — edit the department tabs, not this one. Transfers between departments net to zero only at the total-company level (Org Total tab).
B10: Dept | C10: Department Name | D10: P&L | I10: ='PO HC'!I10 -> 46266 | J10: ='PO HC'!J10 -> 46296 | K10: ='PO HC'!K10 -> 46327 | L10: ='PO HC'!L10 -> 46357 | M10: ='PO HC'!M10 -> 46388 | N10: ='PO HC'!N10 -> 46419 | O10: ='PO HC'!O10 -> 46447 | P10: ='PO HC'!P10 -> 46478 | ... X10: ='PO HC'!X10 -> 46722 | Z10: 2027 Total
I11: ='PO HC'!I11 -> 1 | J11: ='PO HC'!J11 -> 2 | K11: ='PO HC'!K11 -> 3 | L11: ='PO HC'!L11 -> 4 | M11: ='PO HC'!M11 -> 5 | N11: ='PO HC'!N11 -> 6 | O11: ='PO HC'!O11 -> 7 | P11: ='PO HC'!P11 -> 8 | ... X11: ='PO HC'!X11 -> 16
B13: Total Salaries & Wages
B14: PO | C14: Production Operations | D14: COGS | I14: ='PO HC'!I67 -> 43450 | J14: ='PO HC'!J67 -> 43450 | K14: ='PO HC'!K67 -> 43450 | L14: ='PO HC'!L67 -> 43450 | M14: ='PO HC'!M67 -> 43450 | N14: ='PO HC'!N67 -> 43450 | O14: ='PO HC'!O67 -> 43450 | P14: ='PO HC'!P67 -> 43450 | ... X14: ='PO HC'!X67 -> 44753.5 | Z14: =SUM(M14:X14) -> 525310.5
B15: FO | C15: Field Operations | D15: COGS | I15: ='FO HC'!I67 -> 90012.583 | J15: ='FO HC'!J67 -> 90012.583 | K15: ='FO HC'!K67 -> 90012.583 | L15: ='FO HC'!L67 -> 90012.583 | M15: ='FO HC'!M67 -> 90012.583 | N15: ='FO HC'!N67 -> 90012.583 | O15: ='FO HC'!O67 -> 90012.583 | P15: ='FO HC'!P67 -> 90012.583 | ... X15: ='FO HC'!X67 -> 92712.961 | Z15: =SUM(M15:X15) -> 1088252.1
B16: FE | C16: Field Engineering | D16: SG&A | I16: ='FE HC'!I67 -> 55889.25 | J16: ='FE HC'!J67 -> 55889.25 | K16: ='FE HC'!K67 -> 55889.25 | L16: ='FE HC'!L67 -> 67555.917 | M16: ='FE HC'!M67 -> 67555.917 | N16: ='FE HC'!N67 -> 67555.917 | O16: ='FE HC'!O67 -> 67555.917 | P16: ='FE HC'!P67 -> 67555.917 | ... X16: ='FE HC'!X67 -> 69582.594 | Z16: =SUM(M16:X16) -> 816751.03
B17: PE | C17: Production Engineering | D17: SG&A | I17: ='PE HC'!I67 -> 89166.25 | J17: ='PE HC'!J67 -> 89166.25 | K17: ='PE HC'!K67 -> 89166.25 | L17: ='PE HC'!L67 -> 89166.25 | M17: ='PE HC'!M67 -> 89166.25 | N17: ='PE HC'!N67 -> 89166.25 | O17: ='PE HC'!O67 -> 89166.25 | P17: ='PE HC'!P67 -> 89166.25 | ... X17: ='PE HC'!X67 -> 91841.238 | Z17: =SUM(M17:X17) -> 1078020
B18: CO | C18: Central Operations | D18: SG&A | I18: ='CO HC'!I67 -> 36209.833 | J18: ='CO HC'!J67 -> 43709.833 | K18: ='CO HC'!K67 -> 43709.833 | L18: ='CO HC'!L67 -> 43709.833 | M18: ='CO HC'!M67 -> 43709.833 | N18: ='CO HC'!N67 -> 43709.833 | O18: ='CO HC'!O67 -> 43709.833 | P18: ='CO HC'!P67 -> 43709.833 | ... X18: ='CO HC'!X67 -> 45021.128 | Z18: =SUM(M18:X18) -> 528451.88
B19: Total Salaries & Wages — COO Total | I19: =SUM(I14:I18) -> 314727.92 | J19: =SUM(J14:J18) -> 322227.92 | K19: =SUM(K14:K18) -> 322227.92 | L19: =SUM(L14:L18) -> 333894.58 | M19: =SUM(M14:M18) -> 333894.58 | N19: =SUM(N14:N18) -> 333894.58 | O19: =SUM(O14:O18) -> 333894.58 | P19: =SUM(P14:P18) -> 333894.58 | ... X19: =SUM(X14:X18) -> 343911.42 | Z19: =SUM(M19:X19) -> 4036785.5
B21: Payroll Taxes
B22: PO | C22: Production Operations | D22: COGS | I22: ='PO HC'!I68 -> 1580.2286 | J22: ='PO HC'!J68 -> 1580.2286 | K22: ='PO HC'!K68 -> 1580.2286 | L22: ='PO HC'!L68 -> 1580.2286 | M22: ='PO HC'!M68 -> 1580.2286 | N22: ='PO HC'!N68 -> 1580.2286 | O22: ='PO HC'!O68 -> 1580.2286 | P22: ='PO HC'!P68 -> 1580.2286 | ... X22: ='PO HC'!X68 -> 1627.6354 | Z22: =SUM(M22:X22) -> 19104.963
B23: FO | C23: Field Operations | D23: COGS | I23: ='FO HC'!I68 -> 6163.2434 | J23: ='FO HC'!J68 -> 6163.2434 | K23: ='FO HC'!K68 -> 6163.2434 | L23: ='FO HC'!L68 -> 6163.2434 | M23: ='FO HC'!M68 -> 6163.2434 | N23: ='FO HC'!N68 -> 6163.2434 | O23: ='FO HC'!O68 -> 6163.2434 | P23: ='FO HC'!P68 -> 6163.2434 | ... X23: ='FO HC'!X68 -> 6348.1407 | Z23: =SUM(M23:X23) -> 74513.612
B24: FE | C24: Field Engineering | D24: SG&A | I24: ='FE HC'!I68 -> 2274.2492 | J24: ='FE HC'!J68 -> 2274.2492 | K24: ='FE HC'!K68 -> 2274.2492 | L24: ='FE HC'!L68 -> 2748.99 | M24: ='FE HC'!M68 -> 2748.99 | N24: ='FE HC'!N68 -> 2748.99 | O24: ='FE HC'!O68 -> 2748.99 | P24: ='FE HC'!P68 -> 2748.99 | ... X24: ='FE HC'!X68 -> 2831.4597 | Z24: =SUM(M24:X24) -> 33235.29
B25: PE | C25: Production Engineering | D25: SG&A | I25: ='PE HC'!I68 -> 3184.5425 | J25: ='PE HC'!J68 -> 3184.5425 | K25: ='PE HC'!K68 -> 3184.5425 | L25: ='PE HC'!L68 -> 3184.5425 | M25: ='PE HC'!M68 -> 3184.5425 | N25: ='PE HC'!N68 -> 3184.5425 | O25: ='PE HC'!O68 -> 3184.5425 | P25: ='PE HC'!P68 -> 3184.5425 | ... X25: ='PE HC'!X68 -> 3280.0788 | Z25: =SUM(M25:X25) -> 38501.119
B26: CO | C26: Central Operations | D26: SG&A | I26: ='CO HC'!I68 -> 1890.6805 | J26: ='CO HC'!J68 -> 2282.2898 | K26: ='CO HC'!K68 -> 2282.2898 | L26: ='CO HC'!L68 -> 2282.2898 | M26: ='CO HC'!M68 -> 2282.2898 | N26: ='CO HC'!N68 -> 2282.2898 | O26: ='CO HC'!O68 -> 2282.2898 | P26: ='CO HC'!P68 -> 2282.2898 | ... X26: ='CO HC'!X68 -> 2350.7584 | Z26: =SUM(M26:X26) -> 27592.883
B27: Payroll Taxes — COO Total | I27: =SUM(I22:I26) -> 15092.944 | J27: =SUM(J22:J26) -> 15484.553 | K27: =SUM(K22:K26) -> 15484.553 | L27: =SUM(L22:L26) -> 15959.294 | M27: =SUM(M22:M26) -> 15959.294 | N27: =SUM(N22:N26) -> 15959.294 | O27: =SUM(O22:O26) -> 15959.294 | P27: =SUM(P22:P26) -> 15959.294 | ... X27: =SUM(X22:X26) -> 16438.073 | Z27: =SUM(M27:X27) -> 192947.87
B29: Benefits
B30: PO | C30: Production Operations | D30: COGS | I30: ='PO HC'!I69 -> 8966.4588 | J30: ='PO HC'!J69 -> 8966.4588 | K30: ='PO HC'!K69 -> 8966.4588 | L30: ='PO HC'!L69 -> 8966.4588 | M30: ='PO HC'!M69 -> 8966.4588 | N30: ='PO HC'!N69 -> 8966.4588 | O30: ='PO HC'!O69 -> 8966.4588 | P30: ='PO HC'!P69 -> 8966.4588 | ... X30: ='PO HC'!X69 -> 9235.4525 | Z30: =SUM(M30:X30) -> 108404.49
B31: FO | C31: Field Operations | D31: COGS | I31: ='FO HC'!I69 -> 14766.898 | J31: ='FO HC'!J69 -> 14766.898 | K31: ='FO HC'!K69 -> 14766.898 | L31: ='FO HC'!L69 -> 14766.898 | M31: ='FO HC'!M69 -> 14766.898 | N31: ='FO HC'!N69 -> 14766.898 | O31: ='FO HC'!O69 -> 14766.898 | P31: ='FO HC'!P69 -> 14766.898 | ... X31: ='FO HC'!X69 -> 15209.905 | Z31: =SUM(M31:X31) -> 178531.8
B32: FE | C32: Field Engineering | D32: SG&A | I32: ='FE HC'!I69 -> 4036.8294 | J32: ='FE HC'!J69 -> 4036.8294 | K32: ='FE HC'!K69 -> 4036.8294 | L32: ='FE HC'!L69 -> 4879.5021 | M32: ='FE HC'!M69 -> 4879.5021 | N32: ='FE HC'!N69 -> 4879.5021 | O32: ='FE HC'!O69 -> 4879.5021 | P32: ='FE HC'!P69 -> 4879.5021 | ... X32: ='FE HC'!X69 -> 5025.8871 | Z32: =SUM(M32:X32) -> 58993.18
B33: PE | C33: Production Engineering | D33: SG&A | I33: ='PE HC'!I69 -> 7867.3457 | J33: ='PE HC'!J69 -> 7867.3457 | K33: ='PE HC'!K69 -> 7867.3457 | L33: ='PE HC'!L69 -> 7867.3457 | M33: ='PE HC'!M69 -> 7867.3457 | N33: ='PE HC'!N69 -> 7867.3457 | O33: ='PE HC'!O69 -> 7867.3457 | P33: ='PE HC'!P69 -> 7867.3457 | ... X33: ='PE HC'!X69 -> 8103.3661 | Z33: =SUM(M33:X33) -> 95116.21
B34: CO | C34: Central Operations | D34: SG&A | I34: ='CO HC'!I69 -> 4311.0723 | J34: ='CO HC'!J69 -> 5204.0077 | K34: ='CO HC'!K69 -> 5204.0077 | L34: ='CO HC'!L69 -> 5204.0077 | M34: ='CO HC'!M69 -> 5204.0077 | N34: ='CO HC'!N69 -> 5204.0077 | O34: ='CO HC'!O69 -> 5204.0077 | P34: ='CO HC'!P69 -> 5204.0077 | ... X34: ='CO HC'!X69 -> 5360.1279 | Z34: =SUM(M34:X34) -> 62916.453
B35: Benefits — COO Total | I35: =SUM(I30:I34) -> 39948.604 | J35: =SUM(J30:J34) -> 40841.54 | K35: =SUM(K30:K34) -> 40841.54 | L35: =SUM(L30:L34) -> 41684.212 | M35: =SUM(M30:M34) -> 41684.212 | N35: =SUM(N30:N34) -> 41684.212 | O35: =SUM(O30:O34) -> 41684.212 | P35: =SUM(P30:P34) -> 41684.212 | ... X35: =SUM(X30:X34) -> 42934.739 | Z35: =SUM(M35:X35) -> 503962.13
B37: Total Payroll
B38: PO | C38: Production Operations | D38: COGS | I38: ='PO HC'!I70 -> 53996.687 | J38: ='PO HC'!J70 -> 53996.687 | K38: ='PO HC'!K70 -> 53996.687 | L38: ='PO HC'!L70 -> 53996.687 | M38: ='PO HC'!M70 -> 53996.687 | N38: ='PO HC'!N70 -> 53996.687 | O38: ='PO HC'!O70 -> 53996.687 | P38: ='PO HC'!P70 -> 53996.687 | ... X38: ='PO HC'!X70 -> 55616.588 | Z38: =SUM(M38:X38) -> 652819.95
B39: FO | C39: Field Operations | D39: COGS | I39: ='FO HC'!I70 -> 110942.72 | J39: ='FO HC'!J70 -> 110942.72 | K39: ='FO HC'!K70 -> 110942.72 | L39: ='FO HC'!L70 -> 110942.72 | M39: ='FO HC'!M70 -> 110942.72 | N39: ='FO HC'!N70 -> 110942.72 | O39: ='FO HC'!O70 -> 110942.72 | P39: ='FO HC'!P70 -> 110942.72 | ... X39: ='FO HC'!X70 -> 114271.01 | Z39: =SUM(M39:X39) -> 1341297.5
B40: FE | C40: Field Engineering | D40: SG&A | I40: ='FE HC'!I70 -> 62200.329 | J40: ='FE HC'!J70 -> 62200.329 | K40: ='FE HC'!K70 -> 62200.329 | L40: ='FE HC'!L70 -> 75184.409 | M40: ='FE HC'!M70 -> 75184.409 | N40: ='FE HC'!N70 -> 75184.409 | O40: ='FE HC'!O70 -> 75184.409 | P40: ='FE HC'!P70 -> 75184.409 | ... X40: ='FE HC'!X70 -> 77439.941 | Z40: =SUM(M40:X40) -> 908979.5
B41: PE | C41: Production Engineering | D41: SG&A | I41: ='PE HC'!I70 -> 100218.14 | J41: ='PE HC'!J70 -> 100218.14 | K41: ='PE HC'!K70 -> 100218.14 | L41: ='PE HC'!L70 -> 100218.14 | M41: ='PE HC'!M70 -> 100218.14 | N41: ='PE HC'!N70 -> 100218.14 | O41: ='PE HC'!O70 -> 100218.14 | P41: ='PE HC'!P70 -> 100218.14 | ... X41: ='PE HC'!X70 -> 103224.68 | Z41: =SUM(M41:X41) -> 1211637.3
B42: CO | C42: Central Operations | D42: SG&A | I42: ='CO HC'!I70 -> 42411.586 | J42: ='CO HC'!J70 -> 51196.131 | K42: ='CO HC'!K70 -> 51196.131 | L42: ='CO HC'!L70 -> 51196.131 | M42: ='CO HC'!M70 -> 51196.131 | N42: ='CO HC'!N70 -> 51196.131 | O42: ='CO HC'!O70 -> 51196.131 | P42: ='CO HC'!P70 -> 51196.131 | ... X42: ='CO HC'!X70 -> 52732.015 | Z42: =SUM(M42:X42) -> 618961.22
B43: Total Payroll — COO Total | I43: =SUM(I38:I42) -> 369769.47 | J43: =SUM(J38:J42) -> 378554.01 | K43: =SUM(K38:K42) -> 378554.01 | L43: =SUM(L38:L42) -> 391538.09 | M43: =SUM(M38:M42) -> 391538.09 | N43: =SUM(N38:N42) -> 391538.09 | O43: =SUM(O38:O42) -> 391538.09 | P43: =SUM(P38:P42) -> 391538.09 | ... X43: =SUM(X38:X42) -> 403284.23 | Z43: =SUM(M43:X43) -> 4733695.5
B45: Total Payroll by P&L Classification
B46: COGS | I46: =SUMIF($D$38:$D$42,$B46,I$38:I$42) -> 164939.41 | J46: =SUMIF($D$38:$D$42,$B46,J$38:J$42) -> 164939.41 | K46: =SUMIF($D$38:$D$42,$B46,K$38:K$42) -> 164939.41 | L46: =SUMIF($D$38:$D$42,$B46,L$38:L$42) -> 164939.41 | M46: =SUMIF($D$38:$D$42,$B46,M$38:M$42) -> 164939.41 | N46: =SUMIF($D$38:$D$42,$B46,N$38:N$42) -> 164939.41 | O46: =SUMIF($D$38:$D$42,$B46,O$38:O$42) -> 164939.41 | P46: =SUMIF($D$38:$D$42,$B46,P$38:P$42) -> 164939.41 | ... X46: =SUMIF($D$38:$D$42,$B46,X$38:X$42) -> 169887.59 | Z46: =SUM(M46:X46) -> 1994117.5
B47: SG&A | I47: =SUMIF($D$38:$D$42,$B47,I$38:I$42) -> 204830.05 | J47: =SUMIF($D$38:$D$42,$B47,J$38:J$42) -> 213614.6 | K47: =SUMIF($D$38:$D$42,$B47,K$38:K$42) -> 213614.6 | L47: =SUMIF($D$38:$D$42,$B47,L$38:L$42) -> 226598.68 | M47: =SUMIF($D$38:$D$42,$B47,M$38:M$42) -> 226598.68 | N47: =SUMIF($D$38:$D$42,$B47,N$38:N$42) -> 226598.68 | O47: =SUMIF($D$38:$D$42,$B47,O$38:O$42) -> 226598.68 | P47: =SUMIF($D$38:$D$42,$B47,P$38:P$42) -> 226598.68 | ... X47: =SUMIF($D$38:$D$42,$B47,X$38:X$42) -> 233396.64 | Z47: =SUM(M47:X47) -> 2739578
B48: Total Payroll — COO | I48: =SUM(I46:I47) -> 369769.47 | J48: =SUM(J46:J47) -> 378554.01 | K48: =SUM(K46:K47) -> 378554.01 | L48: =SUM(L46:L47) -> 391538.09 | M48: =SUM(M46:M47) -> 391538.09 | N48: =SUM(N46:N47) -> 391538.09 | O48: =SUM(O46:O47) -> 391538.09 | P48: =SUM(P46:P47) -> 391538.09 | ... X48: =SUM(X46:X47) -> 403284.23 | Z48: =SUM(M48:X48) -> 4733695.5
B49: Check: ties to Total Payroll above (should be zero) | I49: =I48-I43 -> 0 | J49: =J48-J43 -> 0 | K49: =K48-K43 -> 0 | L49: =L48-L43 -> 0 | M49: =M48-M43 -> 0 | N49: =N48-N43 -> 0 | O49: =O48-O43 -> 0 | P49: =P48-P43 -> 0 | ... X49: =X48-X43 -> 0
B51: Transfers In — Cost Landing in This Organization ($)
B52: PO | C52: Production Operations | I52: =SUM('PO HC'!I52:I57) -> 0 | J52: =SUM('PO HC'!J52:J57) -> 0 | K52: =SUM('PO HC'!K52:K57) -> 0 | L52: =SUM('PO HC'!L52:L57) -> 0 | M52: =SUM('PO HC'!M52:M57) -> 0 | N52: =SUM('PO HC'!N52:N57) -> 0 | O52: =SUM('PO HC'!O52:O57) -> 0 | P52: =SUM('PO HC'!P52:P57) -> 0 | ... X52: =SUM('PO HC'!X52:X57) -> 0 | Z52: =SUM(M52:X52) -> 0
...

Sheet FO HC
A1: Slip Robotics, Inc.
A2: FIELD OPERATIONS (FO) — 16 Month Headcount & Labor Build (Sep-2026 → Dec-2027)
A3: Build labor by employee for 16 months: Sep-2026 through Dec-2027. Pick Start and End months from the dropdown (End defaults to Dec-27). Leave Start blank for unfilled positions. Salaries / Taxes / Benefits flow to the Budget file.
A4: Leader: COO | Dept Code: FO | P&L Classification: COGS | GL Accounts — Salaries 5510 · Taxes 5530 · Benefits 5540
B5: ASSUMPTIONS
B6: Employer payroll tax rate (% of wages) | D6: =INDEX('[1]T&B'!$S$13:$S$122,MATCH("FO",'[1]T&B'!$R$13:$R$122,0)) -> 0.068470908
B7: Benefits load (% of salary) | D7: =INDEX('[1]T&B'!$T$13:$T$122,MATCH("FO",'[1]T&B'!$R$13:$R$122,0)) -> 0.16405371
B8: Annual Increase Month in Budget year | D8: 46661 | V8: Annual
V9: Increase
B10: Employee | C10: Title | D10: Annual Salary | E10: Start Month | F10: End Month | G10: Annual Increase | H10: Increase Month | I10: =DATE(2026,9,1) -> 46266 | J10: =DATE(2026,10,1) -> 46296 | K10: =DATE(2026,11,1) -> 46327 | L10: =DATE(2026,12,1) -> 46357 | M10: =DATE(2027,1,1) -> 46388 | N10: =DATE(2027,2,1) -> 46419 | O10: =DATE(2027,3,1) -> 46447 | P10: =DATE(2027,4,1) -> 46478 | Q10: =DATE(2027,5,1) -> 46508 | R10: =DATE(2027,6,1) -> 46539 | S10: =DATE(2027,7,1) -> 46569 | T10: =DATE(2027,8,1) -> 46600 | U10: =DATE(2027,9,1) -> 46631 | V10: =DATE(2027,10,1) -> 46661 | W10: =DATE(2027,11,1) -> 46692 | X10: =DATE(2027,12,1) -> 46722 | Z10: 2027 Total | AB10: Input check
E11: (pick from list) | F11: (pick from list) | H11: Month index → | I11: 1 | J11: 2 | K11: 3 | L11: 4 | M11: 5 | N11: 6 | O11: 7 | P11: 8 | Q11: 9 | R11: 10 | S11: 11 | T11: 12 | U11: 13 | V11: 14 | W11: 15 | X11: 16
B13: Current Employees
B14: Gavin Grizzle | C14: Field Technician | D14: 60513 | E14: 46266 | F14: 46722 | G14: 0.03 | H14: =$D$8 -> 46661 | I14: =IF(OR($D14="",$E14="",NOT(ISNUMBER($D14))),"",IF(AND($E14<=I$10,IF($F14="",$X$10,$F14)>=I$10),$D14/12*(1+N($G14))^IF(AND(ISNUMBER($H14),I$10>=$H14),1+INT(DATEDIF($H14,I$10,"m")/12),0),0)) -> 5042.75 | J14: =IF(OR($D14="",$E14="",NOT(ISNUMBER($D14))),"",IF(AND($E14<=J$10,IF($F14="",$X$10,$F14)>=J$10),$D14/12*(1+N($G14))^IF(AND(ISNUMBER($H14),J$10>=$H14),1+INT(DATEDIF($H14,J$10,"m")/12),0),0)) -> 5042.75 | K14: =IF(OR($D14="",$E14="",NOT(ISNUMBER($D14))),"",IF(AND($E14<=K$10,IF($F14="",$X$10,$F14)>=K$10),$D14/12*(1+N($G14))^IF(AND(ISNUMBER($H14),K$10>=$H14),1+INT(DATEDIF($H14,K$10,"m")/12),0),0)) -> 5042.75 | L14: =IF(OR($D14="",$E14="",NOT(ISNUMBER($D14))),"",IF(AND($E14<=L$10,IF($F14="",$X$10,$F14)>=L$10),$D14/12*(1+N($G14))^IF(AND(ISNUMBER($H14),L$10>=$H14),1+INT(DATEDIF($H14,L$10,"m")/12),0),0)) -> 5042.75 | M14: =IF(OR($D14="",$E14="",NOT(ISNUMBER($D14))),"",IF(AND($E14<=M$10,IF($F14="",$X$10,$F14)>=M$10),$D14/12*(1+N($G14))^IF(AND(ISNUMBER($H14),M$10>=$H14),1+INT(DATEDIF($H14,M$10,"m")/12),0),0)) -> 5042.75 | N14: =IF(OR($D14="",$E14="",NOT(ISNUMBER($D14))),"",IF(AND($E14<=N$10,IF($F14="",$X$10,$F14)>=N$10),$D14/12*(1+N($G14))^IF(AND(ISNUMBER($H14),N$10>=$H14),1+INT(DATEDIF($H14,N$10,"m")/12),0),0)) -> 5042.75 | O14: =IF(OR($D14="",$E14="",NOT(ISNUMBER($D14))),"",IF(AND($E14<=O$10,IF($F14="",$X$10,$F14)>=O$10),$D14/12*(1+N($G14))^IF(AND(ISNUMBER($H14),O$10>=$H14),1+INT(DATEDIF($H14,O$10,"m")/12),0),0)) -> 5042.75 | P14: =IF(OR($D14="",$E14="",NOT(ISNUMBER($D14))),"",IF(AND($E14<=P$10,IF($F14="",$X$10,$F14)>=P$10),$D14/12*(1+N($G14))^IF(AND(ISNUMBER($H14),P$10>=$H14),1+INT(DATEDIF($H14,P$10,"m")/12),0),0)) -> 5042.75 | ... X14: =IF(OR($D14="",$E14="",NOT(ISNUMBER($D14))),"",IF(AND($E14<=X$10,IF($F14="",$X$10,$F14)>=X$10),$D14/12*(1+N($G14))^IF(AND(ISNUMBER($H14),X$10>=$H14),1+INT(DATEDIF($H14,X$10,"m")/12),0),0)) -> 5194.0325 | Z14: =SUM(M14:X14) -> 60966.848 | AB14: =IF($D14&$E14="","",IF(AND($D14<>"",NOT(ISNUMBER($D14))),"Salary must be a number",IF(AND($D14<>"",$E14=""),"Start month missing",IF(AND(ISNUMBER($E14),ISNUMBER($F14),$F14<$E14),"End is before Start",IF(AND($D14<>"",NOT(ISNUMBER($H14))),"Increase month missing","")))))
B15: James Murphy | C15: Field Technician | D15: 70021 | E15: 46266 | F15: 46722 | G15: 0.03 | H15: =$D$8 -> 46661 | I15: =IF(OR($D15="",$E15="",NOT(ISNUMBER($D15))),"",IF(AND($E15<=I$10,IF($F15="",$X$10,$F15)>=I$10),$D15/12*(1+N($G15))^IF(AND(ISNUMBER($H15),I$10>=$H15),1+INT(DATEDIF($H15,I$10,"m")/12),0),0)) -> 5835.0833 | J15: =IF(OR($D15="",$E15="",NOT(ISNUMBER($D15))),"",IF(AND($E15<=J$10,IF($F15="",$X$10,$F15)>=J$10),$D15/12*(1+N($G15))^IF(AND(ISNUMBER($H15),J$10>=$H15),1+INT(DATEDIF($H15,J$10,"m")/12),0),0)) -> 5835.0833 | K15: =IF(OR($D15="",$E15="",NOT(ISNUMBER($D15))),"",IF(AND($E15<=K$10,IF($F15="",$X$10,$F15)>=K$10),$D15/12*(1+N($G15))^IF(AND(ISNUMBER($H15),K$10>=$H15),1+INT(DATEDIF($H15,K$10,"m")/12),0),0)) -> 5835.0833 | L15: =IF(OR($D15="",$E15="",NOT(ISNUMBER($D15))),"",IF(AND($E15<=L$10,IF($F15="",$X$10,$F15)>=L$10),$D15/12*(1+N($G15))^IF(AND(ISNUMBER($H15),L$10>=$H15),1+INT(DATEDIF($H15,L$10,"m")/12),0),0)) -> 5835.0833 | M15: =IF(OR($D15="",$E15="",NOT(ISNUMBER($D15))),"",IF(AND($E15<=M$10,IF($F15="",$X$10,$F15)>=M$10),$D15/12*(1+N($G15))^IF(AND(ISNUMBER($H15),M$10>=$H15),1+INT(DATEDIF($H15,M$10,"m")/12),0),0)) -> 5835.0833 | N15: =IF(OR($D15="",$E15="",NOT(ISNUMBER($D15))),"",IF(AND($E15<=N$10,IF($F15="",$X$10,$F15)>=N$10),$D15/12*(1+N($G15))^IF(AND(ISNUMBER($H15),N$10>=$H15),1+INT(DATEDIF($H15,N$10,"m")/12),0),0)) -> 5835.0833 | O15: =IF(OR($D15="",$E15="",NOT(ISNUMBER($D15))),"",IF(AND($E15<=O$10,IF($F15="",$X$10,$F15)>=O$10),$D15/12*(1+N($G15))^IF(AND(ISNUMBER($H15),O$10>=$H15),1+INT(DATEDIF($H15,O$10,"m")/12),0),0)) -> 5835.0833 | P15: =IF(OR($D15="",$E15="",NOT(ISNUMBER($D15))),"",IF(AND($E15<=P$10,IF($F15="",$X$10,$F15)>=P$10),$D15/12*(1+N($G15))^IF(AND(ISNUMBER($H15),P$10>=$H15),1+INT(DATEDIF($H15,P$10,"m")/12),0),0)) -> 5835.0833 | ... X15: =IF(OR($D15="",$E15="",NOT(ISNUMBER($D15))),"",IF(AND($E15<=X$10,IF($F15="",$X$10,$F15)>=X$10),$D15/12*(1+N($G15))^IF(AND(ISNUMBER($H15),X$10>=$H15),1+INT(DATEDIF($H15,X$10,"m")/12),0),0)) -> 6010.1358 | Z15: =SUM(M15:X15) -> 70546.158 | AB15: =IF($D15&$E15="","",IF(AND($D15<>"",NOT(ISNUMBER($D15))),"Salary must be a number",IF(AND($D15<>"",$E15=""),"Start month missing",IF(AND(ISNUMBER($E15),ISNUMBER($F15),$F15<$E15),"End is before Start",IF(AND($D15<>"",NOT(ISNUMBER($H15))),"Increase month missing","")))))
B16: Adam Trostle | C16: Field Technician | D16: 69376 | E16: 46266 | F16: 46722 | G16: 0.03 | H16: =$D$8 -> 46661 | I16: =IF(OR($D16="",$E16="",NOT(ISNUMBER($D16))),"",IF(AND($E16<=I$10,IF($F16="",$X$10,$F16)>=I$10),$D16/12*(1+N($G16))^IF(AND(ISNUMBER($H16),I$10>=$H16),1+INT(DATEDIF($H16,I$10,"m")/12),0),0)) -> 5781.3333 | J16: =IF(OR($D16="",$E16="",NOT(ISNUMBER($D16))),"",IF(AND($E16<=J$10,IF($F16="",$X$10,$F16)>=J$10),$D16/12*(1+N($G16))^IF(AND(ISNUMBER($H16),J$10>=$H16),1+INT(DATEDIF($H16,J$10,"m")/12),0),0)) -> 5781.3333 | K16: =IF(OR($D16="",$E16="",NOT(ISNUMBER($D16))),"",IF(AND($E16<=K$10,IF($F16="",$X$10,$F16)>=K$10),$D16/12*(1+N($G16))^IF(AND(ISNUMBER($H16),K$10>=$H16),1+INT(DATEDIF($H16,K$10,"m")/12),0),0)) -> 5781.3333 | L16: =IF(OR($D16="",$E16="",NOT(ISNUMBER($D16))),"",IF(AND($E16<=L$10,IF($F16="",$X$10,$F16)>=L$10),$D16/12*(1+N($G16))^IF(AND(ISNUMBER($H16),L$10>=$H16),1+INT(DATEDIF($H16,L$10,"m")/12),0),0)) -> 5781.3333 | M16: =IF(OR($D16="",$E16="",NOT(ISNUMBER($D16))),"",IF(AND($E16<=M$10,IF($F16="",$X$10,$F16)>=M$10),$D16/12*(1+N($G16))^IF(AND(ISNUMBER($H16),M$10>=$H16),1+INT(DATEDIF($H16,M$10,"m")/12),0),0)) -> 5781.3333 | N16: =IF(OR($D16="",$E16="",NOT(ISNUMBER($D16))),"",IF(AND($E16<=N$10,IF($F16="",$X$10,$F16)>=N$10),$D16/12*(1+N($G16))^IF(AND(ISNUMBER($H16),N$10>=$H16),1+INT(DATEDIF($H16,N$10,"m")/12),0),0)) -> 5781.3333 | O16: =IF(OR($D16="",$E16="",NOT(ISNUMBER($D16))),"",IF(AND($E16<=O$10,IF($F16="",$X$10,$F16)>=O$10),$D16/12*(1+N($G16))^IF(AND(ISNUMBER($H16),O$10>=$H16),1+INT(DATEDIF($H16,O$10,"m")/12),0),0)) -> 5781.3333 | P16: =IF(OR($D16="",$E16="",NOT(ISNUMBER($D16))),"",IF(AND($E16<=P$10,IF($F16="",$X$10,$F16)>=P$10),$D16/12*(1+N($G16))^IF(AND(ISNUMBER($H16),P$10>=$H16),1+INT(DATEDIF($H16,P$10,"m")/12),0),0)) -> 5781.3333 | ... X16: =IF(OR($D16="",$E16="",NOT(ISNUMBER($D16))),"",IF(AND($E16<=X$10,IF($F16="",$X$10,$F16)>=X$10),$D16/12*(1+N($G16))^IF(AND(ISNUMBER($H16),X$10>=$H16),1+INT(DATEDIF($H16,X$10,"m")/12),0),0)) -> 5954.7733 | Z16: =SUM(M16:X16) -> 69896.32 | AB16: =IF($D16&$E16="","",IF(AND($D16<>"",NOT(ISNUMBER($D16))),"Salary must be a number",IF(AND($D16<>"",$E16=""),"Start month missing",IF(AND(ISNUMBER($E16),ISNUMBER($F16),$F16<$E16),"End is before Start",IF(AND($D16<>"",NOT(ISNUMBER($H16))),"Increase month missing","")))))
B17: Joe Byers | C17: Field Technician | D17: 61687 | E17: 46266 | F17: 46722 | G17: 0.03 | H17: =$D$8 -> 46661 | I17: =IF(OR($D17="",$E17="",NOT(ISNUMBER($D17))),"",IF(AND($E17<=I$10,IF($F17="",$X$10,$F17)>=I$10),$D17/12*(1+N($G17))^IF(AND(ISNUMBER($H17),I$10>=$H17),1+INT(DATEDIF($H17,I$10,"m")/12),0),0)) -> 5140.5833 | J17: =IF(OR($D17="",$E17="",NOT(ISNUMBER($D17))),"",IF(AND($E17<=J$10,IF($F17="",$X$10,$F17)>=J$10),$D17/12*(1+N($G17))^IF(AND(ISNUMBER($H17),J$10>=$H17),1+INT(DATEDIF($H17,J$10,"m")/12),0),0)) -> 5140.5833 | K17: =IF(OR($D17="",$E17="",NOT(ISNUMBER($D17))),"",IF(AND($E17<=K$10,IF($F17="",$X$10,$F17)>=K$10),$D17/12*(1+N($G17))^IF(AND(ISNUMBER($H17),K$10>=$H17),1+INT(DATEDIF($H17,K$10,"m")/12),0),0)) -> 5140.5833 | L17: =IF(OR($D17="",$E17="",NOT(ISNUMBER($D17))),"",IF(AND($E17<=L$10,IF($F17="",$X$10,$F17)>=L$10),$D17/12*(1+N($G17))^IF(AND(ISNUMBER($H17),L$10>=$H17),1+INT(DATEDIF($H17,L$10,"m")/12),0),0)) -> 5140.5833 | M17: =IF(OR($D17="",$E17="",NOT(ISNUMBER($D17))),"",IF(AND($E17<=M$10,IF($F17="",$X$10,$F17)>=M$10),$D17/12*(1+N($G17))^IF(AND(ISNUMBER($H17),M$10>=$H17),1+INT(DATEDIF($H17,M$10,"m")/12),0),0)) -> 5140.5833 | N17: =IF(OR($D17="",$E17="",NOT(ISNUMBER($D17))),"",IF(AND($E17<=N$10,IF($F17="",$X$10,$F17)>=N$10),$D17/12*(1+N($G17))^IF(AND(ISNUMBER($H17),N$10>=$H17),1+INT(DATEDIF($H17,N$10,"m")/12),0),0)) -> 5140.5833 | O17: =IF(OR($D17="",$E17="",NOT(ISNUMBER($D17))),"",IF(AND($E17<=O$10,IF($F17="",$X$10,$F17)>=O$10),$D17/12*(1+N($G17))^IF(AND(ISNUMBER($H17),O$10>=$H17),1+INT(DATEDIF($H17,O$10,"m")/12),0),0)) -> 5140.5833 | P17: =IF(OR($D17="",$E17="",NOT(ISNUMBER($D17))),"",IF(AND($E17<=P$10,IF($F17="",$X$10,$F17)>=P$10),$D17/12*(1+N($G17))^IF(AND(ISNUMBER($H17),P$10>=$H17),1+INT(DATEDIF($H17,P$10,"m")/12),0),0)) -> 5140.5833 | ... X17: =IF(OR($D17="",$E17="",NOT(ISNUMBER($D17))),"",IF(AND($E17<=X$10,IF($F17="",$X$10,$F17)>=X$10),$D17/12*(1+N($G17))^IF(AND(ISNUMBER($H17),X$10>=$H17),1+INT(DATEDIF($H17,X$10,"m")/12),0),0)) -> 5294.8008 | Z17: =SUM(M17:X17) -> 62149.653 | AB17: =IF($D17&$E17="","",IF(AND($D17<>"",NOT(ISNUMBER($D17))),"Salary must be a number",IF(AND($D17<>"",$E17=""),"Start month missing",IF(AND(ISNUMBER($E17),ISNUMBER($F17),$F17<$E17),"End is before Start",IF(AND($D17<>"",NOT(ISNUMBER($H17))),"Increase month missing","")))))
B18: Chad Seyfried | C18: Field Technician | D18: 60593 | E18: 46266 | F18: 46722 | G18: 0.03 | H18: =$D$8 -> 46661 | I18: =IF(OR($D18="",$E18="",NOT(ISNUMBER($D18))),"",IF(AND($E18<=I$10,IF($F18="",$X$10,$F18)>=I$10),$D18/12*(1+N($G18))^IF(AND(ISNUMBER($H18),I$10>=$H18),1+INT(DATEDIF($H18,I$10,"m")/12),0),0)) -> 5049.4167 | J18: =IF(OR($D18="",$E18="",NOT(ISNUMBER($D18))),"",IF(AND($E18<=J$10,IF($F18="",$X$10,$F18)>=J$10),$D18/12*(1+N($G18))^IF(AND(ISNUMBER($H18),J$10>=$H18),1+INT(DATEDIF($H18,J$10,"m")/12),0),0)) -> 5049.4167 | K18: =IF(OR($D18="",$E18="",NOT(ISNUMBER($D18))),"",IF(AND($E18<=K$10,IF($F18="",$X$10,$F18)>=K$10),$D18/12*(1+N($G18))^IF(AND(ISNUMBER($H18),K$10>=$H18),1+INT(DATEDIF($H18,K$10,"m")/12),0),0)) -> 5049.4167 | L18: =IF(OR($D18="",$E18="",NOT(ISNUMBER($D18))),"",IF(AND($E18<=L$10,IF($F18="",$X$10,$F18)>=L$10),$D18/12*(1+N($G18))^IF(AND(ISNUMBER($H18),L$10>=$H18),1+INT(DATEDIF($H18,L$10,"m")/12),0),0)) -> 5049.4167 | M18: =IF(OR($D18="",$E18="",NOT(ISNUMBER($D18))),"",IF(AND($E18<=M$10,IF($F18="",$X$10,$F18)>=M$10),$D18/12*(1+N($G18))^IF(AND(ISNUMBER($H18),M$10>=$H18),1+INT(DATEDIF($H18,M$10,"m")/12),0),0)) -> 5049.4167 | N18: =IF(OR($D18="",$E18="",NOT(ISNUMBER($D18))),"",IF(AND($E18<=N$10,IF($F18="",$X$10,$F18)>=N$10),$D18/12*(1+N($G18))^IF(AND(ISNUMBER($H18),N$10>=$H18),1+INT(DATEDIF($H18,N$10,"m")/12),0),0)) -> 5049.4167 | O18: =IF(OR($D18="",$E18="",NOT(ISNUMBER($D18))),"",IF(AND($E18<=O$10,IF($F18="",$X$10,$F18)>=O$10),$D18/12*(1+N($G18))^IF(AND(ISNUMBER($H18),O$10>=$H18),1+INT(DATEDIF($H18,O$10,"m")/12),0),0)) -> 5049.4167 | P18: =IF(OR($D18="",$E18="",NOT(ISNUMBER($D18))),"",IF(AND($E18<=P$10,IF($F18="",$X$10,$F18)>=P$10),$D18/12*(1+N($G18))^IF(AND(ISNUMBER($H18),P$10>=$H18),1+INT(DATEDIF($H18,P$10,"m")/12),0),0)) -> 5049.4167 | ... X18: =IF(OR($D18="",$E18="",NOT(ISNUMBER($D18))),"",IF(AND($E18<=X$10,IF($F18="",$X$10,$F18)>=X$10),$D18/12*(1+N($G18))^IF(AND(ISNUMBER($H18),X$10>=$H18),1+INT(DATEDIF($H18,X$10,"m")/12),0),0)) -> 5200.8992 | Z18: =SUM(M18:X18) -> 61047.448 | AB18: =IF($D18&$E18="","",IF(AND($D18<>"",NOT(ISNUMBER($D18))),"Salary must be a number",IF(AND($D18<>"",$E18=""),"Start month missing",IF(AND(ISNUMBER($E18),ISNUMBER($F18),$F18<$E18),"End is before Start",IF(AND($D18<>"",NOT(ISNUMBER($H18))),"Increase month missing","")))))
B19: Benjamin Phillips | C19: Field Technician | D19: 53092 | E19: 46266 | F19: 46722 | G19: 0.03 | H19: =$D$8 -> 46661 | I19: =IF(OR($D19="",$E19="",NOT(ISNUMBER($D19))),"",IF(AND($E19<=I$10,IF($F19="",$X$10,$F19)>=I$10),$D19/12*(1+N($G19))^IF(AND(ISNUMBER($H19),I$10>=$H19),1+INT(DATEDIF($H19,I$10,"m")/12),0),0)) -> 4424.3333 | J19: =IF(OR($D19="",$E19="",NOT(ISNUMBER($D19))),"",IF(AND($E19<=J$10,IF($F19="",$X$10,$F19)>=J$10),$D19/12*(1+N($G19))^IF(AND(ISNUMBER($H19),J$10>=$H19),1+INT(DATEDIF($H19,J$10,"m")/12),0),0)) -> 4424.3333 | K19: =IF(OR($D19="",$E19="",NOT(ISNUMBER($D19))),"",IF(AND($E19<=K$10,IF($F19="",$X$10,$F19)>=K$10),$D19/12*(1+N($G19))^IF(AND(ISNUMBER($H19),K$10>=$H19),1+INT(DATEDIF($H19,K$10,"m")/12),0),0)) -> 4424.3333 | L19: =IF(OR($D19="",$E19="",NOT(ISNUMBER($D19))),"",IF(AND($E19<=L$10,IF($F19="",$X$10,$F19)>=L$10),$D19/12*(1+N($G19))^IF(AND(ISNUMBER($H19),L$10>=$H19),1+INT(DATEDIF($H19,L$10,"m")/12),0),0)) -> 4424.3333 | M19: =IF(OR($D19="",$E19="",NOT(ISNUMBER($D19))),"",IF(AND($E19<=M$10,IF($F19="",$X$10,$F19)>=M$10),$D19/12*(1+N($G19))^IF(AND(ISNUMBER($H19),M$10>=$H19),1+INT(DATEDIF($H19,M$10,"m")/12),0),0)) -> 4424.3333 | N19: =IF(OR($D19="",$E19="",NOT(ISNUMBER($D19))),"",IF(AND($E19<=N$10,IF($F19="",$X$10,$F19)>=N$10),$D19/12*(1+N($G19))^IF(AND(ISNUMBER($H19),N$10>=$H19),1+INT(DATEDIF($H19,N$10,"m")/12),0),0)) -> 4424.3333 | O19: =IF(OR($D19="",$E19="",NOT(ISNUMBER($D19))),"",IF(AND($E19<=O$10,IF($F19="",$X$10,$F19)>=O$10),$D19/12*(1+N($G19))^IF(AND(ISNUMBER($H19),O$10>=$H19),1+INT(DATEDIF($H19,O$10,"m")/12),0),0)) -> 4424.3333 | P19: =IF(OR($D19="",$E19="",NOT(ISNUMBER($D19))),"",IF(AND($E19<=P$10,IF($F19="",$X$10,$F19)>=P$10),$D19/12*(1+N($G19))^IF(AND(ISNUMBER($H19),P$10>=$H19),1+INT(DATEDIF($H19,P$10,"m")/12),0),0)) -> 4424.3333 | ... X19: =IF(OR($D19="",$E19="",NOT(ISNUMBER($D19))),"",IF(AND($E19<=X$10,IF($F19="",$X$10,$F19)>=X$10),$D19/12*(1+N($G19))^IF(AND(ISNUMBER($H19),X$10>=$H19),1+INT(DATEDIF($H19,X$10,"m")/12),0),0)) -> 4557.0633 | Z19: =SUM(M19:X19) -> 53490.19 | AB19: =IF($D19&$E19="","",IF(AND($D19<>"",NOT(ISNUMBER($D19))),"Salary must be a number",IF(AND($D19<>"",$E19=""),"Start month missing",IF(AND(ISNUMBER($E19),ISNUMBER($F19),$F19<$E19),"End is before Start",IF(AND($D19<>"",NOT(ISNUMBER($H19))),"Increase month missing","")))))
B20: Brian McSween | C20: Field Technician | D20: 59032 | E20: 46266 | F20: 46722 | G20: 0.03 | H20: =$D$8 -> 46661 | I20: =IF(OR($D20="",$E20="",NOT(ISNUMBER($D20))),"",IF(AND($E20<=I$10,IF($F20="",$X$10,$F20)>=I$10),$D20/12*(1+N($G20))^IF(AND(ISNUMBER($H20),I$10>=$H20),1+INT(DATEDIF($H20,I$10,"m")/12),0),0)) -> 4919.3333 | J20: =IF(OR($D20="",$E20="",NOT(ISNUMBER($D20))),"",IF(AND($E20<=J$10,IF($F20="",$X$10,$F20)>=J$10),$D20/12*(1+N($G20))^IF(AND(ISNUMBER($H20),J$10>=$H20),1+INT(DATEDIF($H20,J$10,"m")/12),0),0)) -> 4919.3333 | K20: =IF(OR($D20="",$E20="",NOT(ISNUMBER($D20))),"",IF(AND($E20<=K$10,IF($F20="",$X$10,$F20)>=K$10),$D20/12*(1+N($G20))^IF(AND(ISNUMBER($H20),K$10>=$H20),1+INT(DATEDIF($H20,K$10,"m")/12),0),0)) -> 4919.3333 | L20: =IF(OR($D20="",$E20="",NOT(ISNUMBER($D20))),"",IF(AND($E20<=L$10,IF($F20="",$X$10,$F20)>=L$10),$D20/12*(1+N($G20))^IF(AND(ISNUMBER($H20),L$10>=$H20),1+INT(DATEDIF($H20,L$10,"m")/12),0),0)) -> 4919.3333 | M20: =IF(OR($D20="",$E20="",NOT(ISNUMBER($D20))),"",IF(AND($E20<=M$10,IF($F20="",$X$10,$F20)>=M$10),$D20/12*(1+N($G20))^IF(AND(ISNUMBER($H20),M$10>=$H20),1+INT(DATEDIF($H20,M$10,"m")/12),0),0)) -> 4919.3333 | N20: =IF(OR($D20="",$E20="",NOT(ISNUMBER($D20))),"",IF(AND($E20<=N$10,IF($F20="",$X$10,$F20)>=N$10),$D20/12*(1+N($G20))^IF(AND(ISNUMBER($H20),N$10>=$H20),1+INT(DATEDIF($H20,N$10,"m")/12),0),0)) -> 4919.3333 | O20: =IF(OR($D20="",$E20="",NOT(ISNUMBER($D20))),"",IF(AND($E20<=O$10,IF($F20="",$X$10,$F20)>=O$10),$D20/12*(1+N($G20))^IF(AND(ISNUMBER($H20),O$10>=$H20),1+INT(DATEDIF($H20,O$10,"m")/12),0),0)) -> 4919.3333 | P20: =IF(OR($D20="",$E20="",NOT(ISNUMBER($D20))),"",IF(AND($E20<=P$10,IF($F20="",$X$10,$F20)>=P$10),$D20/12*(1+N($G20))^IF(AND(ISNUMBER($H20),P$10>=$H20),1+INT(DATEDIF($H20,P$10,"m")/12),0),0)) -> 4919.3333 | ... X20: =IF(OR($D20="",$E20="",NOT(ISNUMBER($D20))),"",IF(AND($E20<=X$10,IF($F20="",$X$10,$F20)>=X$10),$D20/12*(1+N($G20))^IF(AND(ISNUMBER($H20),X$10>=$H20),1+INT(DATEDIF($H20,X$10,"m")/12),0),0)) -> 5066.9133 | Z20: =SUM(M20:X20) -> 59474.74 | AB20: =IF($D20&$E20="","",IF(AND($D20<>"",NOT(ISNUMBER($D20))),"Salary must be a number",IF(AND($D20<>"",$E20=""),"Start month missing",IF(AND(ISNUMBER($E20),ISNUMBER($F20),$F20<$E20),"End is before Start",IF(AND($D20<>"",NOT(ISNUMBER($H20))),"Increase month missing","")))))
B21: Rebecca Tien | C21: Operations Coordinator | D21: 76515 | E21: 46266 | F21: 46722 | G21: 0.03 | H21: =$D$8 -> 46661 | I21: =IF(OR($D21="",$E21="",NOT(ISNUMBER($D21))),"",IF(AND($E21<=I$10,IF($F21="",$X$10,$F21)>=I$10),$D21/12*(1+N($G21))^IF(AND(ISNUMBER($H21),I$10>=$H21),1+INT(DATEDIF($H21,I$10,"m")/12),0),0)) -> 6376.25 | J21: =IF(OR($D21="",$E21="",NOT(ISNUMBER($D21))),"",IF(AND($E21<=J$10,IF($F21="",$X$10,$F21)>=J$10),$D21/12*(1+N($G21))^IF(AND(ISNUMBER($H21),J$10>=$H21),1+INT(DATEDIF($H21,J$10,"m")/12),0),0)) -> 6376.25 | K21: =IF(OR($D21="",$E21="",NOT(ISNUMBER($D21))),"",IF(AND($E21<=K$10,IF($F21="",$X$10,$F21)>=K$10),$D21/12*(1+N($G21))^IF(AND(ISNUMBER($H21),K$10>=$H21),1+INT(DATEDIF($H21,K$10,"m")/12),0),0)) -> 6376.25 | L21: =IF(OR($D21="",$E21="",NOT(ISNUMBER($D21))),"",IF(AND($E21<=L$10,IF($F21="",$X$10,$F21)>=L$10),$D21/12*(1+N($G21))^IF(AND(ISNUMBER($H21),L$10>=$H21),1+INT(DATEDIF($H21,L$10,"m")/12),0),0)) -> 6376.25 | M21: =IF(OR($D21="",$E21="",NOT(ISNUMBER($D21))),"",IF(AND($E21<=M$10,IF($F21="",$X$10,$F21)>=M$10),$D21/12*(1+N($G21))^IF(AND(ISNUMBER($H21),M$10>=$H21),1+INT(DATEDIF($H21,M$10,"m")/12),0),0)) -> 6376.25 | N21: =IF(OR($D21="",$E21="",NOT(ISNUMBER($D21))),"",IF(AND($E21<=N$10,IF($F21="",$X$10,$F21)>=N$10),$D21/12*(1+N($G21))^IF(AND(ISNUMBER($H21),N$10>=$H21),1+INT(DATEDIF($H21,N$10,"m")/12),0),0)) -> 6376.25 | O21: =IF(OR($D21="",$E21="",NOT(ISNUMBER($D21))),"",IF(AND($E21<=O$10,IF($F21="",$X$10,$F21)>=O$10),$D21/12*(1+N($G21))^IF(AND(ISNUMBER($H21),O$10>=$H21),1+INT(DATEDIF($H21,O$10,"m")/12),0),0)) -> 6376.25 | P21: =IF(OR($D21="",$E21="",NOT(ISNUMBER($D21))),"",IF(AND($E21<=P$10,IF($F21="",$X$10,$F21)>=P$10),$D21/12*(1+N($G21))^IF(AND(ISNUMBER($H21),P$10>=$H21),1+INT(DATEDIF($H21,P$10,"m")/12),0),0)) -> 6376.25 | ... X21: =IF(OR($D21="",$E21="",NOT(ISNUMBER($D21))),"",IF(AND($E21<=X$10,IF($F21="",$X$10,$F21)>=X$10),$D21/12*(1+N($G21))^IF(AND(ISNUMBER($H21),X$10>=$H21),1+INT(DATEDIF($H21,X$10,"m")/12),0),0)) -> 6567.5375 | Z21: =SUM(M21:X21) -> 77088.863 | AB21: =IF($D21&$E21="","",IF(AND($D21<>"",NOT(ISNUMBER($D21))),"Salary must be a number",IF(AND($D21<>"",$E21=""),"Start month missing",IF(AND(ISNUMBER($E21),ISNUMBER($F21),$F21<$E21),"End is before Start",IF(AND($D21<>"",NOT(ISNUMBER($H21))),"Increase month missing","")))))
B22: Juan Rodriguez | C22: Field Technician | D22: 64522 | E22: 46266 | F22: 46722 | G22: 0.03 | H22: =$D$8 -> 46661 | I22: =IF(OR($D22="",$E22="",NOT(ISNUMBER($D22))),"",IF(AND($E22<=I$10,IF($F22="",$X$10,$F22)>=I$10),$D22/12*(1+N($G22))^IF(AND(ISNUMBER($H22),I$10>=$H22),1+INT(DATEDIF($H22,I$10,"m")/12),0),0)) -> 5376.8333 | J22: =IF(OR($D22="",$E22="",NOT(ISNUMBER($D22))),"",IF(AND($E22<=J$10,IF($F22="",$X$10,$F22)>=J$10),$D22/12*(1+N($G22))^IF(AND(ISNUMBER($H22),J$10>=$H22),1+INT(DATEDIF($H22,J$10,"m")/12),0),0)) -> 5376.8333 | K22: =IF(OR($D22="",$E22="",NOT(ISNUMBER($D22))),"",IF(AND($E22<=K$10,IF($F22="",$X$10,$F22)>=K$10),$D22/12*(1+N($G22))^IF(AND(ISNUMBER($H22),K$10>=$H22),1+INT(DATEDIF($H22,K$10,"m")/12),0),0)) -> 5376.8333 | L22: =IF(OR($D22="",$E22="",NOT(ISNUMBER($D22))),"",IF(AND($E22<=L$10,IF($F22="",$X$10,$F22)>=L$10),$D22/12*(1+N($G22))^IF(AND(ISNUMBER($H22),L$10>=$H22),1+INT(DATEDIF($H22,L$10,"m")/12),0),0)) -> 5376.8333 | M22: =IF(OR($D22="",$E22="",NOT(ISNUMBER($D22))),"",IF(AND($E22<=M$10,IF($F22="",$X$10,$F22)>=M$10),$D22/12*(1+N($G22))^IF(AND(ISNUMBER($H22),M$10>=$H22),1+INT(DATEDIF($H22,M$10,"m")/12),0),0)) -> 5376.8333 | N22: =IF(OR($D22="",$E22="",NOT(ISNUMBER($D22))),"",IF(AND($E22<=N$10,IF($F22="",$X$10,$F22)>=N$10),$D22/12*(1+N($G22))^IF(AND(ISNUMBER($H22),N$10>=$H22),1+INT(DATEDIF($H22,N$10,"m")/12),0),0)) -> 5376.8333 | O22: =IF(OR($D22="",$E22="",NOT(ISNUMBER($D22))),"",IF(AND($E22<=O$10,IF($F22="",$X$10,$F22)>=O$10),$D22/12*(1+N($G22))^IF(AND(ISNUMBER($H22),O$10>=$H22),1+INT(DATEDIF($H22,O$10,"m")/12),0),0)) -> 5376.8333 | P22: =IF(OR($D22="",$E22="",NOT(ISNUMBER($D22))),"",IF(AND($E22<=P$10,IF($F22="",$X$10,$F22)>=P$10),$D22/12*(1+N($G22))^IF(AND(ISNUMBER($H22),P$10>=$H22),1+INT(DATEDIF($H22,P$10,"m")/12),0),0)) -> 5376.8333 | ... X22: =IF(OR($D22="",$E22="",NOT(ISNUMBER($D22))),"",IF(AND($E22<=X$10,IF($F22="",$X$10,$F22)>=X$10),$D22/12*(1+N($G22))^IF(AND(ISNUMBER($H22),X$10>=$H22),1+INT(DATEDIF($H22,X$10,"m")/12),0),0)) -> 5538.1383 | Z22: =SUM(M22:X22) -> 65005.915 | AB22: =IF($D22&$E22="","",IF(AND($D22<>"",NOT(ISNUMBER($D22))),"Salary must be a number",IF(AND($D22<>"",$E22=""),"Start month missing",IF(AND(ISNUMBER($E22),ISNUMBER($F22),$F22<$E22),"End is before Start",IF(AND($D22<>"",NOT(ISNUMBER($H22))),"Increase month missing","")))))
B23: Shanndon Ferguson | C23: Field Technician | D23: 49920 | E23: 46266 | F23: 46722 | G23: 0.03 | H23: =$D$8 -> 46661 | I23: =IF(OR($D23="",$E23="",NOT(ISNUMBER($D23))),"",IF(AND($E23<=I$10,IF($F23="",$X$10,$F23)>=I$10),$D23/12*(1+N($G23))^IF(AND(ISNUMBER($H23),I$10>=$H23),1+INT(DATEDIF($H23,I$10,"m")/12),0),0)) -> 4160 | J23: =IF(OR($D23="",$E23="",NOT(ISNUMBER($D23))),"",IF(AND($E23<=J$10,IF($F23="",$X$10,$F23)>=J$10),$D23/12*(1+N($G23))^IF(AND(ISNUMBER($H23),J$10>=$H23),1+INT(DATEDIF($H23,J$10,"m")/12),0),0)) -> 4160 | K23: =IF(OR($D23="",$E23="",NOT(ISNUMBER($D23))),"",IF(AND($E23<=K$10,IF($F23="",$X$10,$F23)>=K$10),$D23/12*(1+N($G23))^IF(AND(ISNUMBER($H23),K$10>=$H23),1+INT(DATEDIF($H23,K$10,"m")/12),0),0)) -> 4160 | L23: =IF(OR($D23="",$E23="",NOT(ISNUMBER($D23))),"",IF(AND($E23<=L$10,IF($F23="",$X$10,$F23)>=L$10),$D23/12*(1+N($G23))^IF(AND(ISNUMBER($H23),L$10>=$H23),1+INT(DATEDIF($H23,L$10,"m")/12),0),0)) -> 4160 | M23: =IF(OR($D23="",$E23="",NOT(ISNUMBER($D23))),"",IF(AND($E23<=M$10,IF($F23="",$X$10,$F23)>=M$10),$D23/12*(1+N($G23))^IF(AND(ISNUMBER($H23),M$10>=$H23),1+INT(DATEDIF($H23,M$10,"m")/12),0),0)) -> 4160 | N23: =IF(OR($D23="",$E23="",NOT(ISNUMBER($D23))),"",IF(AND($E23<=N$10,IF($F23="",$X$10,$F23)>=N$10),$D23/12*(1+N($G23))^IF(AND(ISNUMBER($H23),N$10>=$H23),1+INT(DATEDIF($H23,N$10,"m")/12),0),0)) -> 4160 | O23: =IF(OR($D23="",$E23="",NOT(ISNUMBER($D23))),"",IF(AND($E23<=O$10,IF($F23="",$X$10,$F23)>=O$10),$D23/12*(1+N($G23))^IF(AND(ISNUMBER($H23),O$10>=$H23),1+INT(DATEDIF($H23,O$10,"m")/12),0),0)) -> 4160 | P23: =IF(OR($D23="",$E23="",NOT(ISNUMBER($D23))),"",IF(AND($E23<=P$10,IF($F23="",$X$10,$F23)>=P$10),$D23/12*(1+N($G23))^IF(AND(ISNUMBER($H23),P$10>=$H23),1+INT(DATEDIF($H23,P$10,"m")/12),0),0)) -> 4160 | ... X23: =IF(OR($D23="",$E23="",NOT(ISNUMBER($D23))),"",IF(AND($E23<=X$10,IF($F23="",$X$10,$F23)>=X$10),$D23/12*(1+N($G23))^IF(AND(ISNUMBER($H23),X$10>=$H23),1+INT(DATEDIF($H23,X$10,"m")/12),0),0)) -> 4284.8 | Z23: =SUM(M23:X23) -> 50294.4 | AB23: =IF($D23&$E23="","",IF(AND($D23<>"",NOT(ISNUMBER($D23))),"Salary must be a number",IF(AND($D23<>"",$E23=""),"Start month missing",IF(AND(ISNUMBER($E23),ISNUMBER($F23),$F23<$E23),"End is before Start",IF(AND($D23<>"",NOT(ISNUMBER($H23))),"Increase month missing","")))))
B24: Bernadette Sanchez | C24: Field Technician | D24: 70720 | E24: 46266 | F24: 46722 | G24: 0.03 | H24: =$D$8 -> 46661 | I24: =IF(OR($D24="",$E24="",NOT(ISNUMBER($D24))),"",IF(AND($E24<=I$10,IF($F24="",$X$10,$F24)>=I$10),$D24/12*(1+N($G24))^IF(AND(ISNUMBER($H24),I$10>=$H24),1+INT(DATEDIF($H24,I$10,"m")/12),0),0)) -> 5893.3333 | J24: =IF(OR($D24="",$E24="",NOT(ISNUMBER($D24))),"",IF(AND($E24<=J$10,IF($F24="",$X$10,$F24)>=J$10),$D24/12*(1+N($G24))^IF(AND(ISNUMBER($H24),J$10>=$H24),1+INT(DATEDIF($H24,J$10,"m")/12),0),0)) -> 5893.3333 | K24: =IF(OR($D24="",$E24="",NOT(ISNUMBER($D24))),"",IF(AND($E24<=K$10,IF($F24="",$X$10,$F24)>=K$10),$D24/12*(1+N($G24))^IF(AND(ISNUMBER($H24),K$10>=$H24),1+INT(DATEDIF($H24,K$10,"m")/12),0),0)) -> 5893.3333 | L24: =IF(OR($D24="",$E24="",NOT(ISNUMBER($D24))),"",IF(AND($E24<=L$10,IF($F24="",$X$10,$F24)>=L$10),$D24/12*(1+N($G24))^IF(AND(ISNUMBER($H24),L$10>=$H24),1+INT(DATEDIF($H24,L$10,"m")/12),0),0)) -> 5893.3333 | M24: =IF(OR($D24="",$E24="",NOT(ISNUMBER($D24))),"",IF(AND($E24<=M$10,IF($F24="",$X$10,$F24)>=M$10),$D24/12*(1+N($G24))^IF(AND(ISNUMBER($H24),M$10>=$H24),1+INT(DATEDIF($H24,M$10,"m")/12),0),0)) -> 5893.3333 | N24: =IF(OR($D24="",$E24="",NOT(ISNUMBER($D24))),"",IF(AND($E24<=N$10,IF($F24="",$X$10,$F24)>=N$10),$D24/12*(1+N($G24))^IF(AND(ISNUMBER($H24),N$10>=$H24),1+INT(DATEDIF($H24,N$10,"m")/12),0),0)) -> 5893.3333 | O24: =IF(OR($D24="",$E24="",NOT(ISNUMBER($D24))),"",IF(AND($E24<=O$10,IF($F24="",$X$10,$F24)>=O$10),$D24/12*(1+N($G24))^IF(AND(ISNUMBER($H24),O$10>=$H24),1+INT(DATEDIF($H24,O$10,"m")/12),0),0)) -> 5893.3333 | P24: =IF(OR($D24="",$E24="",NOT(ISNUMBER($D24))),"",IF(AND($E24<=P$10,IF($F24="",$X$10,$F24)>=P$10),$D24/12*(1+N($G24))^IF(AND(ISNUMBER($H24),P$10>=$H24),1+INT(DATEDIF($H24,P$10,"m")/12),0),0)) -> 5893.3333 | ... X24: =IF(OR($D24="",$E24="",NOT(ISNUMBER($D24))),"",IF(AND($E24<=X$10,IF($F24="",$X$10,$F24)>=X$10),$D24/12*(1+N($G24))^IF(AND(ISNUMBER($H24),X$10>=$H24),1+INT(DATEDIF($H24,X$10,"m")/12),0),0)) -> 6070.1333 | Z24: =SUM(M24:X24) -> 71250.4 | AB24: =IF($D24&$E24="","",IF(AND($D24<>"",NOT(ISNUMBER($D24))),"Salary must be a number",IF(AND($D24<>"",$E24=""),"Start month missing",IF(AND(ISNUMBER($E24),ISNUMBER($F24),$F24<$E24),"End is before Start",IF(AND($D24<>"",NOT(ISNUMBER($H24))),"Increase month missing","")))))
B25: Isaiah Swallow | C25: Field Maintenance Manager | D25: 120000 | E25: 46266 | F25: 46722 | G25: 0.03 | H25: =$D$8 -> 46661 | I25: =IF(OR($D25="",$E25="",NOT(ISNUMBER($D25))),"",IF(AND($E25<=I$10,IF($F25="",$X$10,$F25)>=I$10),$D25/12*(1+N($G25))^IF(AND(ISNUMBER($H25),I$10>=$H25),1+INT(DATEDIF($H25,I$10,"m")/12),0),0)) -> 10000 | J25: =IF(OR($D25="",$E25="",NOT(ISNUMBER($D25))),"",IF(AND($E25<=J$10,IF($F25="",$X$10,$F25)>=J$10),$D25/12*(1+N($G25))^IF(AND(ISNUMBER($H25),J$10>=$H25),1+INT(DATEDIF($H25,J$10,"m")/12),0),0)) -> 10000 | K25: =IF(OR($D25="",$E25="",NOT(ISNUMBER($D25))),"",IF(AND($E25<=K$10,IF($F25="",$X$10,$F25)>=K$10),$D25/12*(1+N($G25))^IF(AND(ISNUMBER($H25),K$10>=$H25),1+INT(DATEDIF($H25,K$10,"m")/12),0),0)) -> 10000 | L25: =IF(OR($D25="",$E25="",NOT(ISNUMBER($D25))),"",IF(AND($E25<=L$10,IF($F25="",$X$10,$F25)>=L$10),$D25/12*(1+N($G25))^IF(AND(ISNUMBER($H25),L$10>=$H25),1+INT(DATEDIF($H25,L$10,"m")/12),0),0)) -> 10000 | M25: =IF(OR($D25="",$E25="",NOT(ISNUMBER($D25))),"",IF(AND($E25<=M$10,IF($F25="",$X$10,$F25)>=M$10),$D25/12*(1+N($G25))^IF(AND(ISNUMBER($H25),M$10>=$H25),1+INT(DATEDIF($H25,M$10,"m")/12),0),0)) -> 10000 | N25: =IF(OR($D25="",$E25="",NOT(ISNUMBER($D25))),"",IF(AND($E25<=N$10,IF($F25="",$X$10,$F25)>=N$10),$D25/12*(1+N($G25))^IF(AND(ISNUMBER($H25),N$10>=$H25),1+INT(DATEDIF($H25,N$10,"m")/12),0),0)) -> 10000 | O25: =IF(OR($D25="",$E25="",NOT(ISNUMBER($D25))),"",IF(AND($E25<=O$10,IF($F25="",$X$10,$F25)>=O$10),$D25/12*(1+N($G25))^IF(AND(ISNUMBER($H25),O$10>=$H25),1+INT(DATEDIF($H25,O$10,"m")/12),0),0)) -> 10000 | P25: =IF(OR($D25="",$E25="",NOT(ISNUMBER($D25))),"",IF(AND($E25<=P$10,IF($F25="",$X$10,$F25)>=P$10),$D25/12*(1+N($G25))^IF(AND(ISNUMBER($H25),P$10>=$H25),1+INT(DATEDIF($H25,P$10,"m")/12),0),0)) -> 10000 | ... X25: =IF(OR($D25="",$E25="",NOT(ISNUMBER($D25))),"",IF(AND($E25<=X$10,IF($F25="",$X$10,$F25)>=X$10),$D25/12*(1+N($G25))^IF(AND(ISNUMBER($H25),X$10>=$H25),1+INT(DATEDIF($H25,X$10,"m")/12),0),0)) -> 10300 | Z25: =SUM(M25:X25) -> 120900 | AB25: =IF($D25&$E25="","",IF(AND($D25<>"",NOT(ISNUMBER($D25))),"Salary must be a number",IF(AND($D25<>"",$E25=""),"Start month missing",IF(AND(ISNUMBER($E25),ISNUMBER($F25),$F25<$E25),"End is before Start",IF(AND($D25<>"",NOT(ISNUMBER($H25))),"Increase month missing","")))))
... B29: Michael Yunker | C29: Field Technician | D29: 66560 | E29: 46266 | F29: 46722 | G29: 0.03 | H29: =$D$8 -> 46661 | I29: =IF(OR($D29="",$E29="",NOT(ISNUMBER($D29))),"",IF(AND($E29<=I$10,IF($F29="",$X$10,$F29)>=I$10),$D29/12*(1+N($G29))^IF(AND(ISNUMBER($H29),I$10>=$H29),1+INT(DATEDIF($H29,I$10,"m")/12),0),0)) -> 5546.6667 | J29: =IF(OR($D29="",$E29="",NOT(ISNUMBER($D29))),"",IF(AND($E29<=J$10,IF($F29="",$X$10,$F29)>=J$10),$D29/12*(1+N($G29))^IF(AND(ISNUMBER($H29),J$10>=$H29),1+INT(DATEDIF($H29,J$10,"m")/12),0),0)) -> 5546.6667 | K29: =IF(OR($D29="",$E29="",NOT(ISNUMBER($D29))),"",IF(AND($E29<=K$10,IF($F29="",$X$10,$F29)>=K$10),$D29/12*(1+N($G29))^IF(AND(ISNUMBER($H29),K$10>=$H29),1+INT(DATEDIF($H29,K$10,"m")/12),0),0)) -> 5546.6667 | L29: =IF(OR($D29="",$E29="",NOT(ISNUMBER($D29))),"",IF(AND($E29<=L$10,IF($F29="",$X$10,$F29)>=L$10),$D29/12*(1+N($G29))^IF(AND(ISNUMBER($H29),L$10>=$H29),1+INT(DATEDIF($H29,L$10,"m")/12),0),0)) -> 5546.6667 | M29: =IF(OR($D29="",$E29="",NOT(ISNUMBER($D29))),"",IF(AND($E29<=M$10,IF($F29="",$X$10,$F29)>=M$10),$D29/12*(1+N($G29))^IF(AND(ISNUMBER($H29),M$10>=$H29),1+INT(DATEDIF($H29,M$10,"m")/12),0),0)) -> 5546.6667 | N29: =IF(OR($D29="",$E29="",NOT(ISNUMBER($D29))),"",IF(AND($E29<=N$10,IF($F29="",$X$10,$F29)>=N$10),$D29/12*(1+N($G29))^IF(AND(ISNUMBER($H29),N$10>=$H29),1+INT(DATEDIF($H29,N$10,"m")/12),0),0)) -> 5546.6667 | O29: =IF(OR($D29="",$E29="",NOT(ISNUMBER($D29))),"",IF(AND($E29<=O$10,IF($F29="",$X$10,$F29)>=O$10),$D29/12*(1+N($G29))^IF(AND(ISNUMBER($H29),O$10>=$H29),1+INT(DATEDIF($H29,O$10,"m")/12),0),0)) -> 5546.6667 | P29: =IF(OR($D29="",$E29="",NOT(ISNUMBER($D29))),"",IF(AND($E29<=P$10,IF($F29="",$X$10,$F29)>=P$10),$D29/12*(1+N($G29))^IF(AND(ISNUMBER($H29),P$10>=$H29),1+INT(DATEDIF($H29,P$10,"m")/12),0),0)) -> 5546.6667 | ... X29: =IF(OR($D29="",$E29="",NOT(ISNUMBER($D29))),"",IF(AND($E29<=X$10,IF($F29="",$X$10,$F29)>=X$10),$D29/12*(1+N($G29))^IF(AND(ISNUMBER($H29),X$10>=$H29),1+INT(DATEDIF($H29,X$10,"m")/12),0),0)) -> 5713.0667 | Z29: =SUM(M29:X29) -> 67059.2 | AB29: =IF($D29&$E29="","",IF(AND($D29<>"",NOT(ISNUMBER($D29))),"Salary must be a number",IF(AND($D29<>"",$E29=""),"Start month missing",IF(AND(ISNUMBER($E29),ISNUMBER($F29),$F29<$E29),"End is before Start",IF(AND($D29<>"",NOT(ISNUMBER($H29))),"Increase month missing","")))))
E30: 46266 | F30: 46722 | G30: 0.03 | H30: =$D$8 -> 46661 | I30: =IF(OR($D30="",$E30="",NOT(ISNUMBER($D30))),"",IF(AND($E30<=I$10,IF($F30="",$X$10,$F30)>=I$10),$D30/12*(1+N($G30))^IF(AND(ISNUMBER($H30),I$10>=$H30),1+INT(DATEDIF($H30,I$10,"m")/12),0),0)) | J30: =IF(OR($D30="",$E30="",NOT(ISNUMBER($D30))),"",IF(AND($E30<=J$10,IF($F30="",$X$10,$F30)>=J$10),$D30/12*(1+N($G30))^IF(AND(ISNUMBER($H30),J$10>=$H30),1+INT(DATEDIF($H30,J$10,"m")/12),0),0)) | K30: =IF(OR($D30="",$E30="",NOT(ISNUMBER($D30))),"",IF(AND($E30<=K$10,IF($F30="",$X$10,$F30)>=K$10),$D30/12*(1+N($G30))^IF(AND(ISNUMBER($H30),K$10>=$H30),1+INT(DATEDIF($H30,K$10,"m")/12),0),0)) | L30: =IF(OR($D30="",$E30="",NOT(ISNUMBER($D30))),"",IF(AND($E30<=L$10,IF($F30="",$X$10,$F30)>=L$10),$D30/12*(1+N($G30))^IF(AND(ISNUMBER($H30),L$10>=$H30),1+INT(DATEDIF($H30,L$10,"m")/12),0),0)) | M30: =IF(OR($D30="",$E30="",NOT(ISNUMBER($D30))),"",IF(AND($E30<=M$10,IF($F30="",$X$10,$F30)>=M$10),$D30/12*(1+N($G30))^IF(AND(ISNUMBER($H30),M$10>=$H30),1+INT(DATEDIF($H30,M$10,"m")/12),0),0)) | N30: =IF(OR($D30="",$E30="",NOT(ISNUMBER($D30))),"",IF(AND($E30<=N$10,IF($F30="",$X$10,$F30)>=N$10),$D30/12*(1+N($G30))^IF(AND(ISNUMBER($H30),N$10>=$H30),1+INT(DATEDIF($H30,N$10,"m")/12),0),0)) | O30: =IF(OR($D30="",$E30="",NOT(ISNUMBER($D30))),"",IF(AND($E30<=O$10,IF($F30="",$X$10,$F30)>=O$10),$D30/12*(1+N($G30))^IF(AND(ISNUMBER($H30),O$10>=$H30),1+INT(DATEDIF($H30,O$10,"m")/12),0),0)) | P30: =IF(OR($D30="",$E30="",NOT(ISNUMBER($D30))),"",IF(AND($E30<=P$10,IF($F30="",$X$10,$F30)>=P$10),$D30/12*(1+N($G30))^IF(AND(ISNUMBER($H30),P$10>=$H30),1+INT(DATEDIF($H30,P$10,"m")/12),0),0)) | ... X30: =IF(OR($D30="",$E30="",NOT(ISNUMBER($D30))),"",IF(AND($E30<=X$10,IF($F30="",$X$10,$F30)>=X$10),$D30/12*(1+N($G30))^IF(AND(ISNUMBER($H30),X$10>=$H30),1+INT(DATEDIF($H30,X$10,"m")/12),0),0)) | Z30: =SUM(M30:X30) -> 0 | AB30: =IF($D30&$E30="","",IF(AND($D30<>"",NOT(ISNUMBER($D30))),"Salary must be a number",IF(AND($D30<>"",$E30=""),"Start month missing",IF(AND(ISNUMBER($E30),ISNUMBER($F30),$F30<$E30),"End is before Start",IF(AND($D30<>"",NOT(ISNUMBER($H30))),"Increase month missing","")))))
E31: 46266 | F31: 46722 | G31: 0.03 | H31: =$D$8 -> 46661 | I31: =IF(OR($D31="",$E31="",NOT(ISNUMBER($D31))),"",IF(AND($E31<=I$10,IF($F31="",$X$10,$F31)>=I$10),$D31/12*(1+N($G31))^IF(AND(ISNUMBER($H31),I$10>=$H31),1+INT(DATEDIF($H31,I$10,"m")/12),0),0)) | J31: =IF(OR($D31="",$E31="",NOT(ISNUMBER($D31))),"",IF(AND($E31<=J$10,IF($F31="",$X$10,$F31)>=J$10),$D31/12*(1+N($G31))^IF(AND(ISNUMBER($H31),J$10>=$H31),1+INT(DATEDIF($H31,J$10,"m")/12),0),0)) | K31: =IF(OR($D31="",$E31="",NOT(ISNUMBER($D31))),"",IF(AND($E31<=K$10,IF($F31="",$X$10,$F31)>=K$10),$D31/12*(1+N($G31))^IF(AND(ISNUMBER($H31),K$10>=$H31),1+INT(DATEDIF($H31,K$10,"m")/12),0),0)) | L31: =IF(OR($D31="",$E31="",NOT(ISNUMBER($D31))),"",IF(AND($E31<=L$10,IF($F31="",$X$10,$F31)>=L$10),$D31/12*(1+N($G31))^IF(AND(ISNUMBER($H31),L$10>=$H31),1+INT(DATEDIF($H31,L$10,"m")/12),0),0)) | M31: =IF(OR($D31="",$E31="",NOT(ISNUMBER($D31))),"",IF(AND($E31<=M$10,IF($F31="",$X$10,$F31)>=M$10),$D31/12*(1+N($G31))^IF(AND(ISNUMBER($H31),M$10>=$H31),1+INT(DATEDIF($H31,M$10,"m")/12),0),0)) | N31: =IF(OR($D31="",$E31="",NOT(ISNUMBER($D31))),"",IF(AND($E31<=N$10,IF($F31="",$X$10,$F31)>=N$10),$D31/12*(1+N($G31))^IF(AND(ISNUMBER($H31),N$10>=$H31),1+INT(DATEDIF($H31,N$10,"m")/12),0),0)) | O31: =IF(OR($D31="",$E31="",NOT(ISNUMBER($D31))),"",IF(AND($E31<=O$10,IF($F31="",$X$10,$F31)>=O$10),$D31/12*(1+N($G31))^IF(AND(ISNUMBER($H31),O$10>=$H31),1+INT(DATEDIF($H31,O$10,"m")/12),0),0)) | P31: =IF(OR($D31="",$E31="",NOT(ISNUMBER($D31))),"",IF(AND($E31<=P$10,IF($F31="",$X$10,$F31)>=P$10),$D31/12*(1+N($G31))^IF(AND(ISNUMBER($H31),P$10>=$H31),1+INT(DATEDIF($H31,P$10,"m")/12),0),0)) | ... X31: =IF(OR($D31="",$E31="",NOT(ISNUMBER($D31))),"",IF(AND($E31<=X$10,IF($F31="",$X$10,$F31)>=X$10),$D31/12*(1+N($G31))^IF(AND(ISNUMBER($H31),X$10>=$H31),1+INT(DATEDIF($H31,X$10,"m")/12),0),0)) | Z31: =SUM(M31:X31) -> 0 | AB31: =IF($D31&$E31="","",IF(AND($D31<>"",NOT(ISNUMBER($D31))),"Salary must be a number",IF(AND($D31<>"",$E31=""),"Start month missing",IF(AND(ISNUMBER($E31),ISNUMBER($F31),$F31<$E31),"End is before Start",IF(AND($D31<>"",NOT(ISNUMBER($H31))),"Increase month missing","")))))
