Workbook

Sheet DeploySum
A1: 2027 Production & Deployment Plan — Summary for COO
A2: Bookings, deployments and production by month (base case). Dollars in $000s. Sep–Dec 26 = remaining 2026 (existing + forecast contracts); FY2027 = Jan–Dec 27.
A3: {="Tie-out to Deploy Detail (bookings $, deployments, production): "&IF(AND(SUMPRODUCT(ABS(B18:Q18-'[1]Deploy Detail'!K172:Z172))+ABS(R18-'[1]Deploy Detail'!AB172)<0.01,SUMPRODUCT(ABS(B24:Q24+B25:Q25+B26:Q26-'[1]Deploy Detail'!K252:Z252))+ABS(SUM(R24:R26)-'[1]Deploy Detail'!AB252)<0.01,SUMPRODUCT(ABS(B13:Q13-'[1]Deploy Detail'!K92:Z92))+ABS(R13-'[1]Deploy Detail'!AB92)<0.5),"OK","CHECK")} -> #ERROR!
B4: ='[1]Revenue Roll-up'!D17 -> #REF! | C4: ='[1]Revenue Roll-up'!E17 -> #REF! | D4: ='[1]Revenue Roll-up'!F17 -> #REF! | E4: ='[1]Revenue Roll-up'!G17 -> #REF! | F4: ='[1]Revenue Roll-up'!H17 -> #REF! | G4: ='[1]Revenue Roll-up'!I17 -> #REF! | H4: ='[1]Revenue Roll-up'!J17 -> #REF! | I4: ='[1]Revenue Roll-up'!K17 -> #REF! | ... Q4: ='[1]Revenue Roll-up'!S17 -> #REF! | R4: FY2027
A5: BOOKINGS
A6: New logos – deals booked (#) | B6: ='[1]Revenue Roll-up'!D51 -> #REF! | C6: ='[1]Revenue Roll-up'!E51 -> #REF! | D6: ='[1]Revenue Roll-up'!F51 -> #REF! | E6: ='[1]Revenue Roll-up'!G51 -> #REF! | F6: ='[1]Revenue Roll-up'!H51 -> #REF! | G6: ='[1]Revenue Roll-up'!I51 -> #REF! | H6: ='[1]Revenue Roll-up'!J51 -> #REF! | I6: ='[1]Revenue Roll-up'!K51 -> #REF! | ... Q6: ='[1]Revenue Roll-up'!S51 -> #REF! | R6: ='[1]Revenue Roll-up'!U51 -> #REF!
A7: New logos – bookings ($000s) | B7: ='[1]Revenue Roll-up'!D50 -> #REF! | C7: ='[1]Revenue Roll-up'!E50 -> #REF! | D7: ='[1]Revenue Roll-up'!F50 -> #REF! | E7: ='[1]Revenue Roll-up'!G50 -> #REF! | F7: ='[1]Revenue Roll-up'!H50 -> #REF! | G7: ='[1]Revenue Roll-up'!I50 -> #REF! | H7: ='[1]Revenue Roll-up'!J50 -> #REF! | I7: ='[1]Revenue Roll-up'!K50 -> #REF! | ... Q7: ='[1]Revenue Roll-up'!S50 -> #REF! | R7: ='[1]Revenue Roll-up'!U50 -> #REF!
A8: Expansion – deals booked (#) | B8: ='[1]Revenue Roll-up'!D65 -> #REF! | C8: ='[1]Revenue Roll-up'!E65 -> #REF! | D8: ='[1]Revenue Roll-up'!F65 -> #REF! | E8: ='[1]Revenue Roll-up'!G65 -> #REF! | F8: ='[1]Revenue Roll-up'!H65 -> #REF! | G8: ='[1]Revenue Roll-up'!I65 -> #REF! | H8: ='[1]Revenue Roll-up'!J65 -> #REF! | I8: ='[1]Revenue Roll-up'!K65 -> #REF! | ... Q8: ='[1]Revenue Roll-up'!S65 -> #REF! | R8: ='[1]Revenue Roll-up'!U65 -> #REF!
A9: Expansion – bookings ($000s) | B9: ='[1]Revenue Roll-up'!D64 -> #REF! | C9: ='[1]Revenue Roll-up'!E64 -> #REF! | D9: ='[1]Revenue Roll-up'!F64 -> #REF! | E9: ='[1]Revenue Roll-up'!G64 -> #REF! | F9: ='[1]Revenue Roll-up'!H64 -> #REF! | G9: ='[1]Revenue Roll-up'!I64 -> #REF! | H9: ='[1]Revenue Roll-up'!J64 -> #REF! | I9: ='[1]Revenue Roll-up'!K64 -> #REF! | ... Q9: ='[1]Revenue Roll-up'!S64 -> #REF! | R9: ='[1]Revenue Roll-up'!U64 -> #REF!
A10: Existing & forecast contracts – booked (#) | B10: =COUNTIF('[1]Deploy Detail'!K21:K62,">0") -> #REF! | C10: =COUNTIF('[1]Deploy Detail'!L21:L62,">0") -> #REF! | D10: =COUNTIF('[1]Deploy Detail'!M21:M62,">0") -> #REF! | E10: =COUNTIF('[1]Deploy Detail'!N21:N62,">0") -> #REF! | F10: =COUNTIF('[1]Deploy Detail'!O21:O62,">0") -> #REF! | G10: =COUNTIF('[1]Deploy Detail'!P21:P62,">0") -> #REF! | H10: =COUNTIF('[1]Deploy Detail'!Q21:Q62,">0") -> #REF! | I10: =COUNTIF('[1]Deploy Detail'!R21:R62,">0") -> #REF! | ... Q10: =COUNTIF('[1]Deploy Detail'!Z21:Z62,">0") -> #REF! | R10: =SUM(F10:Q10) -> #REF!
A11: Existing & forecast contracts – bookings ($000s) | B11: ='[1]Deploy Detail'!K63 -> #REF! | C11: ='[1]Deploy Detail'!L63 -> #REF! | D11: ='[1]Deploy Detail'!M63 -> #REF! | E11: ='[1]Deploy Detail'!N63 -> #REF! | F11: ='[1]Deploy Detail'!O63 -> #REF! | G11: ='[1]Deploy Detail'!P63 -> #REF! | H11: ='[1]Deploy Detail'!Q63 -> #REF! | I11: ='[1]Deploy Detail'!R63 -> #REF! | ... Q11: ='[1]Deploy Detail'!Z63 -> #REF! | R11: ='[1]Deploy Detail'!AB63 -> #REF!
A12: Total bookings (#) | B12: =B6+B8+B10 -> #REF! | C12: =C6+C8+C10 -> #REF! | D12: =D6+D8+D10 -> #REF! | E12: =E6+E8+E10 -> #REF! | F12: =F6+F8+F10 -> #REF! | G12: =G6+G8+G10 -> #REF! | H12: =H6+H8+H10 -> #REF! | I12: =I6+I8+I10 -> #REF! | ... R12: =R6+R8+R10 -> #REF!
A13: Total bookings ($000s) | B13: =B7+B9+B11 -> #REF! | C13: =C7+C9+C11 -> #REF! | D13: =D7+D9+D11 -> #REF! | E13: =E7+E9+E11 -> #REF! | F13: =F7+F9+F11 -> #REF! | G13: =G7+G9+G11 -> #REF! | H13: =H7+H9+H11 -> #REF! | I13: =I7+I9+I11 -> #REF! | ... R13: =R7+R9+R11 -> #REF!
A15: DEPLOYMENTS (deals going live)
A16: SlipLift deployments (#) | B16: =COUNTIFS('[1]2026 Exist New'!$U$9:$U$50,"Yes",'[1]2026 Exist New'!$E$9:$E$50,"SlipLift",'[1]2026 Exist New'!$I$9:$I$50,">"&EOMONTH(B$4,-1),'[1]2026 Exist New'!$I$9:$I$50,"<="&B$4)+[1]Deploy!D36+[1]Deploy!D41 -> #ERROR! | C16: =COUNTIFS('[1]2026 Exist New'!$U$9:$U$50,"Yes",'[1]2026 Exist New'!$E$9:$E$50,"SlipLift",'[1]2026 Exist New'!$I$9:$I$50,">"&EOMONTH(C$4,-1),'[1]2026 Exist New'!$I$9:$I$50,"<="&C$4)+[1]Deploy!E36+[1]Deploy!E41 -> #ERROR! | D16: =COUNTIFS('[1]2026 Exist New'!$U$9:$U$50,"Yes",'[1]2026 Exist New'!$E$9:$E$50,"SlipLift",'[1]2026 Exist New'!$I$9:$I$50,">"&EOMONTH(D$4,-1),'[1]2026 Exist New'!$I$9:$I$50,"<="&D$4)+[1]Deploy!F36+[1]Deploy!F41 -> #ERROR! | E16: =COUNTIFS('[1]2026 Exist New'!$U$9:$U$50,"Yes",'[1]2026 Exist New'!$E$9:$E$50,"SlipLift",'[1]2026 Exist New'!$I$9:$I$50,">"&EOMONTH(E$4,-1),'[1]2026 Exist New'!$I$9:$I$50,"<="&E$4)+[1]Deploy!G36+[1]Deploy!G41 -> #ERROR! | F16: =COUNTIFS('[1]2026 Exist New'!$U$9:$U$50,"Yes",'[1]2026 Exist New'!$E$9:$E$50,"SlipLift",'[1]2026 Exist New'!$I$9:$I$50,">"&EOMONTH(F$4,-1),'[1]2026 Exist New'!$I$9:$I$50,"<="&F$4)+[1]Deploy!H36+[1]Deploy!H41 -> #ERROR! | G16: =COUNTIFS('[1]2026 Exist New'!$U$9:$U$50,"Yes",'[1]2026 Exist New'!$E$9:$E$50,"SlipLift",'[1]2026 Exist New'!$I$9:$I$50,">"&EOMONTH(G$4,-1),'[1]2026 Exist New'!$I$9:$I$50,"<="&G$4)+[1]Deploy!I36+[1]Deploy!I41 -> #ERROR! | H16: =COUNTIFS('[1]2026 Exist New'!$U$9:$U$50,"Yes",'[1]2026 Exist New'!$E$9:$E$50,"SlipLift",'[1]2026 Exist New'!$I$9:$I$50,">"&EOMONTH(H$4,-1),'[1]2026 Exist New'!$I$9:$I$50,"<="&H$4)+[1]Deploy!J36+[1]Deploy!J41 -> #ERROR! | I16: =COUNTIFS('[1]2026 Exist New'!$U$9:$U$50,"Yes",'[1]2026 Exist New'!$E$9:$E$50,"SlipLift",'[1]2026 Exist New'!$I$9:$I$50,">"&EOMONTH(I$4,-1),'[1]2026 Exist New'!$I$9:$I$50,"<="&I$4)+[1]Deploy!K36+[1]Deploy!K41 -> #ERROR! | ... Q16: =COUNTIFS('[1]2026 Exist New'!$U$9:$U$50,"Yes",'[1]2026 Exist New'!$E$9:$E$50,"SlipLift",'[1]2026 Exist New'!$I$9:$I$50,">"&EOMONTH(Q$4,-1),'[1]2026 Exist New'!$I$9:$I$50,"<="&Q$4)+[1]Deploy!S36+[1]Deploy!S41 -> #ERROR! | R16: =COUNTIFS('[1]2026 Exist New'!$U$9:$U$50,"Yes",'[1]2026 Exist New'!$E$9:$E$50,"SlipLift",'[1]2026 Exist New'!$I$9:$I$50,">"&EOMONTH($F$4,-1),'[1]2026 Exist New'!$I$9:$I$50,"<="&$Q$4)+[1]Deploy!U36+[1]Deploy!U41 -> #ERROR!
A17: SlipBot deployments (#) | B17: =COUNTIFS('[1]2026 Exist New'!$U$9:$U$50,"Yes",'[1]2026 Exist New'!$E$9:$E$50,"SlipBot",'[1]2026 Exist New'!$I$9:$I$50,">"&EOMONTH(B$4,-1),'[1]2026 Exist New'!$I$9:$I$50,"<="&B$4) -> 0 | C17: =COUNTIFS('[1]2026 Exist New'!$U$9:$U$50,"Yes",'[1]2026 Exist New'!$E$9:$E$50,"SlipBot",'[1]2026 Exist New'!$I$9:$I$50,">"&EOMONTH(C$4,-1),'[1]2026 Exist New'!$I$9:$I$50,"<="&C$4) -> 0 | D17: =COUNTIFS('[1]2026 Exist New'!$U$9:$U$50,"Yes",'[1]2026 Exist New'!$E$9:$E$50,"SlipBot",'[1]2026 Exist New'!$I$9:$I$50,">"&EOMONTH(D$4,-1),'[1]2026 Exist New'!$I$9:$I$50,"<="&D$4) -> 0 | E17: =COUNTIFS('[1]2026 Exist New'!$U$9:$U$50,"Yes",'[1]2026 Exist New'!$E$9:$E$50,"SlipBot",'[1]2026 Exist New'!$I$9:$I$50,">"&EOMONTH(E$4,-1),'[1]2026 Exist New'!$I$9:$I$50,"<="&E$4) -> 0 | F17: =COUNTIFS('[1]2026 Exist New'!$U$9:$U$50,"Yes",'[1]2026 Exist New'!$E$9:$E$50,"SlipBot",'[1]2026 Exist New'!$I$9:$I$50,">"&EOMONTH(F$4,-1),'[1]2026 Exist New'!$I$9:$I$50,"<="&F$4) -> 0 | G17: =COUNTIFS('[1]2026 Exist New'!$U$9:$U$50,"Yes",'[1]2026 Exist New'!$E$9:$E$50,"SlipBot",'[1]2026 Exist New'!$I$9:$I$50,">"&EOMONTH(G$4,-1),'[1]2026 Exist New'!$I$9:$I$50,"<="&G$4) -> 0 | H17: =COUNTIFS('[1]2026 Exist New'!$U$9:$U$50,"Yes",'[1]2026 Exist New'!$E$9:$E$50,"SlipBot",'[1]2026 Exist New'!$I$9:$I$50,">"&EOMONTH(H$4,-1),'[1]2026 Exist New'!$I$9:$I$50,"<="&H$4) -> 0 | I17: =COUNTIFS('[1]2026 Exist New'!$U$9:$U$50,"Yes",'[1]2026 Exist New'!$E$9:$E$50,"SlipBot",'[1]2026 Exist New'!$I$9:$I$50,">"&EOMONTH(I$4,-1),'[1]2026 Exist New'!$I$9:$I$50,"<="&I$4) -> 0 | ... Q17: =COUNTIFS('[1]2026 Exist New'!$U$9:$U$50,"Yes",'[1]2026 Exist New'!$E$9:$E$50,"SlipBot",'[1]2026 Exist New'!$I$9:$I$50,">"&EOMONTH(Q$4,-1),'[1]2026 Exist New'!$I$9:$I$50,"<="&Q$4) -> 0 | R17: =COUNTIFS('[1]2026 Exist New'!$U$9:$U$50,"Yes",'[1]2026 Exist New'!$E$9:$E$50,"SlipBot",'[1]2026 Exist New'!$I$9:$I$50,">"&EOMONTH($F$4,-1),'[1]2026 Exist New'!$I$9:$I$50,"<="&$Q$4) -> 0
A18: Total deployments (#) | B18: =B16+B17 -> #ERROR! | C18: =C16+C17 -> #ERROR! | D18: =D16+D17 -> #ERROR! | E18: =E16+E17 -> #ERROR! | F18: =F16+F17 -> #ERROR! | G18: =G16+G17 -> #ERROR! | H18: =H16+H17 -> #ERROR! | I18: =I16+I17 -> #ERROR! | ... R18: =R16+R17 -> #ERROR!
A19: SlipLifts going live (units) | B19: =[1]Deploy!D47 -> #ERROR! | C19: =[1]Deploy!E47 -> #ERROR! | D19: =[1]Deploy!F47 -> #ERROR! | E19: =[1]Deploy!G47 -> #ERROR! | F19: =[1]Deploy!H47 -> #ERROR! | G19: =[1]Deploy!I47 -> #ERROR! | H19: =[1]Deploy!J47 -> #ERROR! | I19: =[1]Deploy!K47 -> #ERROR! | ... Q19: =[1]Deploy!S47 -> #ERROR! | R19: =[1]Deploy!U47 -> #ERROR!
A20: SlipTrays going live (units) | B20: =[1]Deploy!D48 -> #ERROR! | C20: =[1]Deploy!E48 -> #ERROR! | D20: =[1]Deploy!F48 -> #ERROR! | E20: =[1]Deploy!G48 -> #ERROR! | F20: =[1]Deploy!H48 -> #ERROR! | G20: =[1]Deploy!I48 -> #ERROR! | H20: =[1]Deploy!J48 -> #ERROR! | I20: =[1]Deploy!K48 -> #ERROR! | ... Q20: =[1]Deploy!S48 -> #ERROR! | R20: =[1]Deploy!U48 -> #ERROR!
A21: SlipBots going live (units) | B21: =[1]Deploy!D49 -> #ERROR! | C21: =[1]Deploy!E49 -> #ERROR! | D21: =[1]Deploy!F49 -> #ERROR! | E21: =[1]Deploy!G49 -> #ERROR! | F21: =[1]Deploy!H49 -> #ERROR! | G21: =[1]Deploy!I49 -> #ERROR! | H21: =[1]Deploy!J49 -> #ERROR! | I21: =[1]Deploy!K49 -> #ERROR! | ... Q21: =[1]Deploy!S49 -> #ERROR! | R21: =[1]Deploy!U49 -> #ERROR!
A23: PRODUCTION (units to build, by production month)
A24: SlipLifts to build | B24: =[1]Deploy!D53 -> #ERROR! | C24: =[1]Deploy!E53 -> #ERROR! | D24: =[1]Deploy!F53 -> #ERROR! | E24: =[1]Deploy!G53 -> #ERROR! | F24: =[1]Deploy!H53 -> #ERROR! | G24: =[1]Deploy!I53 -> #ERROR! | H24: =[1]Deploy!J53 -> #ERROR! | I24: =[1]Deploy!K53 -> #ERROR! | ... Q24: =[1]Deploy!S53 -> #ERROR! | R24: =[1]Deploy!U53 -> #ERROR!
A25: SlipTrays to build | B25: =[1]Deploy!D54 -> #ERROR! | C25: =[1]Deploy!E54 -> #ERROR! | D25: =[1]Deploy!F54 -> #ERROR! | E25: =[1]Deploy!G54 -> #ERROR! | F25: =[1]Deploy!H54 -> #ERROR! | G25: =[1]Deploy!I54 -> #ERROR! | H25: =[1]Deploy!J54 -> #ERROR! | I25: =[1]Deploy!K54 -> #ERROR! | ... Q25: =[1]Deploy!S54 -> #ERROR! | R25: =[1]Deploy!U54 -> #ERROR!
A26: SlipBots to build | B26: =[1]Deploy!D55 -> #ERROR! | C26: =[1]Deploy!E55 -> #ERROR! | D26: =[1]Deploy!F55 -> #ERROR! | E26: =[1]Deploy!G55 -> #ERROR! | F26: =[1]Deploy!H55 -> #ERROR! | G26: =[1]Deploy!I55 -> #ERROR! | H26: =[1]Deploy!J55 -> #ERROR! | I26: =[1]Deploy!K55 -> #ERROR! | ... Q26: =[1]Deploy!S55 -> #ERROR! | R26: =[1]Deploy!U55 -> #ERROR!
A27: SlipLifts – avg per week (units ÷ weeks in month) | B27: =B24/(DAY(B$4)/7) -> #ERROR! | C27: =C24/(DAY(C$4)/7) -> #ERROR! | D27: =D24/(DAY(D$4)/7) -> #ERROR! | E27: =E24/(DAY(E$4)/7) -> #ERROR! | F27: =F24/(DAY(F$4)/7) -> #ERROR! | G27: =G24/(DAY(G$4)/7) -> #ERROR! | H27: =H24/(DAY(H$4)/7) -> #ERROR! | I27: =I24/(DAY(I$4)/7) -> #ERROR! | ... Q27: =Q24/(DAY(Q$4)/7) -> #ERROR! | R27: {=R24/(SUMPRODUCT(DAY($F$4:$Q$4))/7)} -> #ERROR!
A28: SlipTrays – avg per week (units ÷ weeks in month) | B28: =B25/(DAY(B$4)/7) -> #ERROR! | C28: =C25/(DAY(C$4)/7) -> #ERROR! | D28: =D25/(DAY(D$4)/7) -> #ERROR! | E28: =E25/(DAY(E$4)/7) -> #ERROR! | F28: =F25/(DAY(F$4)/7) -> #ERROR! | G28: =G25/(DAY(G$4)/7) -> #ERROR! | H28: =H25/(DAY(H$4)/7) -> #ERROR! | I28: =I25/(DAY(I$4)/7) -> #ERROR! | ... Q28: =Q25/(DAY(Q$4)/7) -> #ERROR! | R28: {=R25/(SUMPRODUCT(DAY($F$4:$Q$4))/7)} -> #ERROR!
A29: Production CapEx ($000s) | B29: =[1]Deploy!D68 -> #ERROR! | C29: =[1]Deploy!E68 -> #ERROR! | D29: =[1]Deploy!F68 -> #ERROR! | E29: =[1]Deploy!G68 -> #ERROR! | F29: =[1]Deploy!H68 -> #ERROR! | G29: =[1]Deploy!I68 -> #ERROR! | H29: =[1]Deploy!J68 -> #ERROR! | I29: =[1]Deploy!K68 -> #ERROR! | ... Q29: =[1]Deploy!S68 -> #ERROR! | R29: =[1]Deploy!U68 -> #ERROR!
A30: Deployment freight – expensed ($000s) | B30: =[1]Deploy!D69 -> #ERROR! | C30: =[1]Deploy!E69 -> #ERROR! | D30: =[1]Deploy!F69 -> #ERROR! | E30: =[1]Deploy!G69 -> #ERROR! | F30: =[1]Deploy!H69 -> #ERROR! | G30: =[1]Deploy!I69 -> #ERROR! | H30: =[1]Deploy!J69 -> #ERROR! | I30: =[1]Deploy!K69 -> #ERROR! | ... Q30: =[1]Deploy!S69 -> #ERROR! | R30: =[1]Deploy!U69 -> #ERROR!
A32: OF WHICH (already included in the production lines above): builds in Nov/Dec-27 for Q1-28 go-lives from Q4-27 bookings
A33: SlipLifts built for 2028 go-lives | B33: =SUMIFS('[1]Deploy Detail'!$G$225:$G$236,'[1]Deploy Detail'!$E$225:$E$236,B$4,'[1]Deploy Detail'!$D$225:$D$236,">"&'[1]Deploy Detail'!$B$13)+SUMIFS('[1]Deploy Detail'!$G$239:$G$250,'[1]Deploy Detail'!$E$239:$E$250,B$4,'[1]Deploy Detail'!$D$239:$D$250,">"&'[1]Deploy Detail'!$B$13) -> #N/A | C33: =SUMIFS('[1]Deploy Detail'!$G$225:$G$236,'[1]Deploy Detail'!$E$225:$E$236,C$4,'[1]Deploy Detail'!$D$225:$D$236,">"&'[1]Deploy Detail'!$B$13)+SUMIFS('[1]Deploy Detail'!$G$239:$G$250,'[1]Deploy Detail'!$E$239:$E$250,C$4,'[1]Deploy Detail'!$D$239:$D$250,">"&'[1]Deploy Detail'!$B$13) -> #N/A | D33: =SUMIFS('[1]Deploy Detail'!$G$225:$G$236,'[1]Deploy Detail'!$E$225:$E$236,D$4,'[1]Deploy Detail'!$D$225:$D$236,">"&'[1]Deploy Detail'!$B$13)+SUMIFS('[1]Deploy Detail'!$G$239:$G$250,'[1]Deploy Detail'!$E$239:$E$250,D$4,'[1]Deploy Detail'!$D$239:$D$250,">"&'[1]Deploy Detail'!$B$13) -> #N/A | E33: =SUMIFS('[1]Deploy Detail'!$G$225:$G$236,'[1]Deploy Detail'!$E$225:$E$236,E$4,'[1]Deploy Detail'!$D$225:$D$236,">"&'[1]Deploy Detail'!$B$13)+SUMIFS('[1]Deploy Detail'!$G$239:$G$250,'[1]Deploy Detail'!$E$239:$E$250,E$4,'[1]Deploy Detail'!$D$239:$D$250,">"&'[1]Deploy Detail'!$B$13) -> #N/A | F33: =SUMIFS('[1]Deploy Detail'!$G$225:$G$236,'[1]Deploy Detail'!$E$225:$E$236,F$4,'[1]Deploy Detail'!$D$225:$D$236,">"&'[1]Deploy Detail'!$B$13)+SUMIFS('[1]Deploy Detail'!$G$239:$G$250,'[1]Deploy Detail'!$E$239:$E$250,F$4,'[1]Deploy Detail'!$D$239:$D$250,">"&'[1]Deploy Detail'!$B$13) -> #N/A | G33: =SUMIFS('[1]Deploy Detail'!$G$225:$G$236,'[1]Deploy Detail'!$E$225:$E$236,G$4,'[1]Deploy Detail'!$D$225:$D$236,">"&'[1]Deploy Detail'!$B$13)+SUMIFS('[1]Deploy Detail'!$G$239:$G$250,'[1]Deploy Detail'!$E$239:$E$250,G$4,'[1]Deploy Detail'!$D$239:$D$250,">"&'[1]Deploy Detail'!$B$13) -> #N/A | H33: =SUMIFS('[1]Deploy Detail'!$G$225:$G$236,'[1]Deploy Detail'!$E$225:$E$236,H$4,'[1]Deploy Detail'!$D$225:$D$236,">"&'[1]Deploy Detail'!$B$13)+SUMIFS('[1]Deploy Detail'!$G$239:$G$250,'[1]Deploy Detail'!$E$239:$E$250,H$4,'[1]Deploy Detail'!$D$239:$D$250,">"&'[1]Deploy Detail'!$B$13) -> #N/A | I33: =SUMIFS('[1]Deploy Detail'!$G$225:$G$236,'[1]Deploy Detail'!$E$225:$E$236,I$4,'[1]Deploy Detail'!$D$225:$D$236,">"&'[1]Deploy Detail'!$B$13)+SUMIFS('[1]Deploy Detail'!$G$239:$G$250,'[1]Deploy Detail'!$E$239:$E$250,I$4,'[1]Deploy Detail'!$D$239:$D$250,">"&'[1]Deploy Detail'!$B$13) -> #N/A | ... Q33: =SUMIFS('[1]Deploy Detail'!$G$225:$G$236,'[1]Deploy Detail'!$E$225:$E$236,Q$4,'[1]Deploy Detail'!$D$225:$D$236,">"&'[1]Deploy Detail'!$B$13)+SUMIFS('[1]Deploy Detail'!$G$239:$G$250,'[1]Deploy Detail'!$E$239:$E$250,Q$4,'[1]Deploy Detail'!$D$239:$D$250,">"&'[1]Deploy Detail'!$B$13) -> #N/A | R33: =SUM(F33:Q33) -> #N/A
A34: SlipTrays built for 2028 go-lives | B34: =SUMIFS('[1]Deploy Detail'!$H$225:$H$236,'[1]Deploy Detail'!$E$225:$E$236,B$4,'[1]Deploy Detail'!$D$225:$D$236,">"&'[1]Deploy Detail'!$B$13)+SUMIFS('[1]Deploy Detail'!$H$239:$H$250,'[1]Deploy Detail'!$E$239:$E$250,B$4,'[1]Deploy Detail'!$D$239:$D$250,">"&'[1]Deploy Detail'!$B$13) -> #N/A | C34: =SUMIFS('[1]Deploy Detail'!$H$225:$H$236,'[1]Deploy Detail'!$E$225:$E$236,C$4,'[1]Deploy Detail'!$D$225:$D$236,">"&'[1]Deploy Detail'!$B$13)+SUMIFS('[1]Deploy Detail'!$H$239:$H$250,'[1]Deploy Detail'!$E$239:$E$250,C$4,'[1]Deploy Detail'!$D$239:$D$250,">"&'[1]Deploy Detail'!$B$13) -> #N/A | D34: =SUMIFS('[1]Deploy Detail'!$H$225:$H$236,'[1]Deploy Detail'!$E$225:$E$236,D$4,'[1]Deploy Detail'!$D$225:$D$236,">"&'[1]Deploy Detail'!$B$13)+SUMIFS('[1]Deploy Detail'!$H$239:$H$250,'[1]Deploy Detail'!$E$239:$E$250,D$4,'[1]Deploy Detail'!$D$239:$D$250,">"&'[1]Deploy Detail'!$B$13) -> #N/A | E34: =SUMIFS('[1]Deploy Detail'!$H$225:$H$236,'[1]Deploy Detail'!$E$225:$E$236,E$4,'[1]Deploy Detail'!$D$225:$D$236,">"&'[1]Deploy Detail'!$B$13)+SUMIFS('[1]Deploy Detail'!$H$239:$H$250,'[1]Deploy Detail'!$E$239:$E$250,E$4,'[1]Deploy Detail'!$D$239:$D$250,">"&'[1]Deploy Detail'!$B$13) -> #N/A | F34: =SUMIFS('[1]Deploy Detail'!$H$225:$H$236,'[1]Deploy Detail'!$E$225:$E$236,F$4,'[1]Deploy Detail'!$D$225:$D$236,">"&'[1]Deploy Detail'!$B$13)+SUMIFS('[1]Deploy Detail'!$H$239:$H$250,'[1]Deploy Detail'!$E$239:$E$250,F$4,'[1]Deploy Detail'!$D$239:$D$250,">"&'[1]Deploy Detail'!$B$13) -> #N/A | G34: =SUMIFS('[1]Deploy Detail'!$H$225:$H$236,'[1]Deploy Detail'!$E$225:$E$236,G$4,'[1]Deploy Detail'!$D$225:$D$236,">"&'[1]Deploy Detail'!$B$13)+SUMIFS('[1]Deploy Detail'!$H$239:$H$250,'[1]Deploy Detail'!$E$239:$E$250,G$4,'[1]Deploy Detail'!$D$239:$D$250,">"&'[1]Deploy Detail'!$B$13) -> #N/A | H34: =SUMIFS('[1]Deploy Detail'!$H$225:$H$236,'[1]Deploy Detail'!$E$225:$E$236,H$4,'[1]Deploy Detail'!$D$225:$D$236,">"&'[1]Deploy Detail'!$B$13)+SUMIFS('[1]Deploy Detail'!$H$239:$H$250,'[1]Deploy Detail'!$E$239:$E$250,H$4,'[1]Deploy Detail'!$D$239:$D$250,">"&'[1]Deploy Detail'!$B$13) -> #N/A | I34: =SUMIFS('[1]Deploy Detail'!$H$225:$H$236,'[1]Deploy Detail'!$E$225:$E$236,I$4,'[1]Deploy Detail'!$D$225:$D$236,">"&'[1]Deploy Detail'!$B$13)+SUMIFS('[1]Deploy Detail'!$H$239:$H$250,'[1]Deploy Detail'!$E$239:$E$250,I$4,'[1]Deploy Detail'!$D$239:$D$250,">"&'[1]Deploy Detail'!$B$13) -> #N/A | ... Q34: =SUMIFS('[1]Deploy Detail'!$H$225:$H$236,'[1]Deploy Detail'!$E$225:$E$236,Q$4,'[1]Deploy Detail'!$D$225:$D$236,">"&'[1]Deploy Detail'!$B$13)+SUMIFS('[1]Deploy Detail'!$H$239:$H$250,'[1]Deploy Detail'!$E$239:$E$250,Q$4,'[1]Deploy Detail'!$D$239:$D$250,">"&'[1]Deploy Detail'!$B$13) -> #N/A | R34: =SUM(F34:Q34) -> #N/A
A35: CapEx for 2028 go-lives – estimate ($000s) | B35: =B33*([1]Deploy!$B$7+[1]Deploy!$B$14)+B34*[1]Deploy!$B$8 -> #ERROR! | C35: =C33*([1]Deploy!$B$7+[1]Deploy!$B$14)+C34*[1]Deploy!$B$8 -> #ERROR! | D35: =D33*([1]Deploy!$B$7+[1]Deploy!$B$14)+D34*[1]Deploy!$B$8 -> #ERROR! | E35: =E33*([1]Deploy!$B$7+[1]Deploy!$B$14)+E34*[1]Deploy!$B$8 -> #ERROR! | F35: =F33*([1]Deploy!$B$7+[1]Deploy!$B$14)+F34*[1]Deploy!$B$8 -> #ERROR! | G35: =G33*([1]Deploy!$B$7+[1]Deploy!$B$14)+G34*[1]Deploy!$B$8 -> #ERROR! | H35: =H33*([1]Deploy!$B$7+[1]Deploy!$B$14)+H34*[1]Deploy!$B$8 -> #ERROR! | I35: =I33*([1]Deploy!$B$7+[1]Deploy!$B$14)+I34*[1]Deploy!$B$8 -> #ERROR! | ... R35: =R33*([1]Deploy!$B$7+[1]Deploy!$B$14)+R34*[1]Deploy!$B$8 -> #ERROR!
A37: OTHER CONTEXT
A38: CARR – end of period ($000s) | B38: ='[1]Revenue Roll-up'!D24 -> #REF! | C38: ='[1]Revenue Roll-up'!E24 -> #REF! | D38: ='[1]Revenue Roll-up'!F24 -> #REF! | E38: ='[1]Revenue Roll-up'!G24 -> #REF! | F38: ='[1]Revenue Roll-up'!H24 -> #REF! | G38: ='[1]Revenue Roll-up'!I24 -> #REF! | H38: ='[1]Revenue Roll-up'!J24 -> #REF! | I38: ='[1]Revenue Roll-up'!K24 -> #REF! | ... Q38: ='[1]Revenue Roll-up'!S24 -> #REF! | R38: ='[1]Revenue Roll-up'!S24 -> #REF!
A39: ARR – end of period ($000s) | B39: ='[1]Revenue Roll-up'!D30 -> #REF! | C39: ='[1]Revenue Roll-up'!E30 -> #REF! | D39: ='[1]Revenue Roll-up'!F30 -> #REF! | E39: ='[1]Revenue Roll-up'!G30 -> #REF! | F39: ='[1]Revenue Roll-up'!H30 -> #REF! | G39: ='[1]Revenue Roll-up'!I30 -> #REF! | H39: ='[1]Revenue Roll-up'!J30 -> #REF! | I39: ='[1]Revenue Roll-up'!K30 -> #REF! | ... Q39: ='[1]Revenue Roll-up'!S30 -> #REF! | R39: ='[1]Revenue Roll-up'!S30 -> #REF!
A40: Recognized revenue ($000s) | B40: ='[1]Revenue Roll-up'!D38 -> #REF! | C40: ='[1]Revenue Roll-up'!E38 -> #REF! | D40: ='[1]Revenue Roll-up'!F38 -> #REF! | E40: ='[1]Revenue Roll-up'!G38 -> #REF! | F40: ='[1]Revenue Roll-up'!H38 -> #REF! | G40: ='[1]Revenue Roll-up'!I38 -> #REF! | H40: ='[1]Revenue Roll-up'!J38 -> #REF! | I40: ='[1]Revenue Roll-up'!K38 -> #REF! | ... Q40: ='[1]Revenue Roll-up'!S38 -> #REF! | R40: ='[1]Revenue Roll-up'!U38 -> #REF!
A41: Billings ($000s) | B41: ='[1]Revenue Roll-up'!D40 -> #REF! | C41: ='[1]Revenue Roll-up'!E40 -> #REF! | D41: ='[1]Revenue Roll-up'!F40 -> #REF! | E41: ='[1]Revenue Roll-up'!G40 -> #REF! | F41: ='[1]Revenue Roll-up'!H40 -> #REF! | G41: ='[1]Revenue Roll-up'!I40 -> #REF! | H41: ='[1]Revenue Roll-up'!J40 -> #REF! | I41: ='[1]Revenue Roll-up'!K40 -> #REF! | ... Q41: ='[1]Revenue Roll-up'!S40 -> #REF! | R41: ='[1]Revenue Roll-up'!U40 -> #REF!
A42: Deferred revenue – end of period ($000s) | B42: ='[1]Revenue Roll-up'!D45 -> #REF! | C42: ='[1]Revenue Roll-up'!E45 -> #REF! | D42: ='[1]Revenue Roll-up'!F45 -> #REF! | E42: ='[1]Revenue Roll-up'!G45 -> #REF! | F42: ='[1]Revenue Roll-up'!H45 -> #REF! | G42: ='[1]Revenue Roll-up'!I45 -> #REF! | H42: ='[1]Revenue Roll-up'!J45 -> #REF! | I42: ='[1]Revenue Roll-up'!K45 -> #REF! | ... Q42: ='[1]Revenue Roll-up'!S45 -> #REF! | R42: ='[1]Revenue Roll-up'!S45 -> #REF!
A44: KEY ASSUMPTIONS & NOTES
A45: ="1. Timing: bookings go live "&'[1]Deploy Detail'!B8&" months after booking (new logos & expansion); units are built "&[1]Deploy!B16&" months before go-live." -> #ERROR!
...

Sheet FO
A1: Field Operations
A2: 2026 Actuals/Forecast & 2027 Budget
B7: Actual | C7: Actual | D7: Actual | E7: Actual | F7: Actual | G7: Actual | H7: Actual | I7: Actual | J7: Forecast | K7: Forecast | L7: Forecast | M7: Forecast | N7: Forecast | O7: Forecast | S7: Annual Input | T7: YOY | U7: Budget | V7: Budget | W7: Budget | X7: Budget | Y7: Budget | Z7: Budget | AA7: Budget | AB7: Budget | AC7: Budget | AD7: Budget | AE7: Budget | AF7: Budget | AG7: Budget | AH7: Budget | AJ7: YOY
B8: Jan | C8: Feb | D8: Mar | E8: Apr | F8: May | G8: Jun | H8: Jul | I8: Aug | J8: Sep | K8: Oct | L8: Nov | M8: Dec | N8: 2026 | O8: % Total Rev | R8: Input Method | S8: "Even" spread | T8: Growth % | U8: Jan | V8: Feb | W8: Mar | X8: Apr | Y8: May | Z8: Jun | AA8: Jul | AB8: Aug | AC8: Sep | AD8: Oct | AE8: Nov | AF8: Dec | AG8: 2027 | AH8: % Total Rev | AJ8: Fav / (Unfav)
A9: Ordinary Income/Expense
A10: Income
A11: 4000 - Sales
A12: 4100 - Subscription/Platform Fees | B12: 0 | C12: 0 | D12: 0 | E12: 0 | F12: 0 | G12: 0 | H12: 0 | I12: 0 | N12: =SUM(B12:M12) -> 0 | O12: =IFERROR(N12/N$16,"") | R12: Even | T12: 0.05 | U12: =IF($R12="Manual","",IFERROR(IF($R12="YOY Growth",$N12*(1+$T12)/12,$S12/12),"")) -> 0 | V12: =IF($R12="Manual","",IFERROR(IF($R12="YOY Growth",$N12*(1+$T12)/12,$S12/12),"")) -> 0 | W12: =IF($R12="Manual","",IFERROR(IF($R12="YOY Growth",$N12*(1+$T12)/12,$S12/12),"")) -> 0 | X12: =IF($R12="Manual","",IFERROR(IF($R12="YOY Growth",$N12*(1+$T12)/12,$S12/12),"")) -> 0 | Y12: =IF($R12="Manual","",IFERROR(IF($R12="YOY Growth",$N12*(1+$T12)/12,$S12/12),"")) -> 0 | Z12: =IF($R12="Manual","",IFERROR(IF($R12="YOY Growth",$N12*(1+$T12)/12,$S12/12),"")) -> 0 | AA12: =IF($R12="Manual","",IFERROR(IF($R12="YOY Growth",$N12*(1+$T12)/12,$S12/12),"")) -> 0 | AB12: =IF($R12="Manual","",IFERROR(IF($R12="YOY Growth",$N12*(1+$T12)/12,$S12/12),"")) -> 0 | ... AF12: =IF($R12="Manual","",IFERROR(IF($R12="YOY Growth",$N12*(1+$T12)/12,$S12/12),"")) -> 0 | AG12: =SUM(U12:AF12) -> 0 | AH12: =IFERROR(AG12/AG$16,"") | AJ12: =AG12-N12 -> 0
A13: 4500 - Implementation Fees | B13: 0 | C13: 0 | D13: 0 | E13: 0 | F13: 0 | G13: 0 | H13: 0 | I13: 0 | N13: =SUM(B13:M13) -> 0 | O13: =IFERROR(N13/N$16,"") | R13: Even | S13: 0 | T13: 0.05 | U13: =IF($R13="Manual","",IFERROR(IF($R13="YOY Growth",$N13*(1+$T13)/12,$S13/12),"")) -> 0 | V13: =IF($R13="Manual","",IFERROR(IF($R13="YOY Growth",$N13*(1+$T13)/12,$S13/12),"")) -> 0 | W13: =IF($R13="Manual","",IFERROR(IF($R13="YOY Growth",$N13*(1+$T13)/12,$S13/12),"")) -> 0 | X13: =IF($R13="Manual","",IFERROR(IF($R13="YOY Growth",$N13*(1+$T13)/12,$S13/12),"")) -> 0 | Y13: =IF($R13="Manual","",IFERROR(IF($R13="YOY Growth",$N13*(1+$T13)/12,$S13/12),"")) -> 0 | Z13: =IF($R13="Manual","",IFERROR(IF($R13="YOY Growth",$N13*(1+$T13)/12,$S13/12),"")) -> 0 | AA13: =IF($R13="Manual","",IFERROR(IF($R13="YOY Growth",$N13*(1+$T13)/12,$S13/12),"")) -> 0 | AB13: =IF($R13="Manual","",IFERROR(IF($R13="YOY Growth",$N13*(1+$T13)/12,$S13/12),"")) -> 0 | ... AF13: =IF($R13="Manual","",IFERROR(IF($R13="YOY Growth",$N13*(1+$T13)/12,$S13/12),"")) -> 0 | AG13: =SUM(U13:AF13) -> 0 | AH13: =IFERROR(AG13/AG$16,"") | AJ13: =AG13-N13 -> 0
A14: Total - 4000 - Sales | B14: =SUM(B12:B13) -> 0 | C14: =SUM(C12:C13) -> 0 | D14: =SUM(D12:D13) -> 0 | E14: =SUM(E12:E13) -> 0 | F14: =SUM(F12:F13) -> 0 | G14: =SUM(G12:G13) -> 0 | H14: =SUM(H12:H13) -> 0 | I14: =SUM(I12:I13) -> 0 | ... M14: =SUM(M12:M13) -> 0 | N14: =SUM(B14:M14) -> 0 | O14: =SUM(O12:O13) -> 0 | U14: =SUM(U12:U13) -> 0 | V14: =SUM(V12:V13) -> 0 | W14: =SUM(W12:W13) -> 0 | X14: =SUM(X12:X13) -> 0 | Y14: =SUM(Y12:Y13) -> 0 | Z14: =SUM(Z12:Z13) -> 0 | AA14: =SUM(AA12:AA13) -> 0 | AB14: =SUM(AB12:AB13) -> 0 | ... AF14: =SUM(AF12:AF13) -> 0 | AG14: =SUM(U14:AF14) -> 0 | AH14: =SUM(AH12:AH13) -> 0 | AJ14: =AG14-N14 -> 0
A15: 4900 - One-Time Revenue | B15: 0 | C15: 0 | D15: 0 | E15: 0 | F15: 0 | G15: 0 | H15: 0 | I15: 0 | N15: =SUM(B15:M15) -> 0 | O15: =IFERROR(N15/N$16,"") | R15: Even | S15: 0 | T15: 0.05 | U15: =IF($R15="Manual","",IFERROR(IF($R15="YOY Growth",$N15*(1+$T15)/12,$S15/12),"")) -> 0 | V15: =IF($R15="Manual","",IFERROR(IF($R15="YOY Growth",$N15*(1+$T15)/12,$S15/12),"")) -> 0 | W15: =IF($R15="Manual","",IFERROR(IF($R15="YOY Growth",$N15*(1+$T15)/12,$S15/12),"")) -> 0 | X15: =IF($R15="Manual","",IFERROR(IF($R15="YOY Growth",$N15*(1+$T15)/12,$S15/12),"")) -> 0 | Y15: =IF($R15="Manual","",IFERROR(IF($R15="YOY Growth",$N15*(1+$T15)/12,$S15/12),"")) -> 0 | Z15: =IF($R15="Manual","",IFERROR(IF($R15="YOY Growth",$N15*(1+$T15)/12,$S15/12),"")) -> 0 | AA15: =IF($R15="Manual","",IFERROR(IF($R15="YOY Growth",$N15*(1+$T15)/12,$S15/12),"")) -> 0 | AB15: =IF($R15="Manual","",IFERROR(IF($R15="YOY Growth",$N15*(1+$T15)/12,$S15/12),"")) -> 0 | ... AF15: =IF($R15="Manual","",IFERROR(IF($R15="YOY Growth",$N15*(1+$T15)/12,$S15/12),"")) -> 0 | AG15: =SUM(U15:AF15) -> 0 | AH15: =IFERROR(AG15/AG$16,"") | AJ15: =AG15-N15 -> 0
A16: Total - Income | B16: =B14+B15 -> 0 | C16: =C14+C15 -> 0 | D16: =D14+D15 -> 0 | E16: =E14+E15 -> 0 | F16: =F14+F15 -> 0 | G16: =G14+G15 -> 0 | H16: =H14+H15 -> 0 | I16: =I14+I15 -> 0 | ... M16: =M14+M15 -> 0 | N16: =SUM(B16:M16) -> 0 | O16: =SUM(O14:O15) -> 0 | U16: =U14+U15 -> 0 | V16: =V14+V15 -> 0 | W16: =W14+W15 -> 0 | X16: =X14+X15 -> 0 | Y16: =Y14+Y15 -> 0 | Z16: =Z14+Z15 -> 0 | AA16: =AA14+AA15 -> 0 | AB16: =AB14+AB15 -> 0 | ... AF16: =AF14+AF15 -> 0 | AG16: =SUM(U16:AF16) -> 0 | AH16: =SUM(AH14:AH15) -> 0 | AJ16: =AG16-N16 -> 0
A17: Cost Of Sales
A18: 5000 - Robot Production and Deployment
A19: 5010 - SlipBot Depreciation | B19: 0 | C19: 0 | D19: 0 | E19: 0 | F19: 0 | G19: 0 | H19: 0 | I19: 0 | N19: =SUM(B19:M19) -> 0 | O19: =IFERROR(N19/N$16,"") | R19: Even | S19: 0 | T19: 0.05 | U19: =IF($R19="Manual","",IFERROR(IF($R19="YOY Growth",$N19*(1+$T19)/12,$S19/12),"")) -> 0 | V19: =IF($R19="Manual","",IFERROR(IF($R19="YOY Growth",$N19*(1+$T19)/12,$S19/12),"")) -> 0 | W19: =IF($R19="Manual","",IFERROR(IF($R19="YOY Growth",$N19*(1+$T19)/12,$S19/12),"")) -> 0 | X19: =IF($R19="Manual","",IFERROR(IF($R19="YOY Growth",$N19*(1+$T19)/12,$S19/12),"")) -> 0 | Y19: =IF($R19="Manual","",IFERROR(IF($R19="YOY Growth",$N19*(1+$T19)/12,$S19/12),"")) -> 0 | Z19: =IF($R19="Manual","",IFERROR(IF($R19="YOY Growth",$N19*(1+$T19)/12,$S19/12),"")) -> 0 | AA19: =IF($R19="Manual","",IFERROR(IF($R19="YOY Growth",$N19*(1+$T19)/12,$S19/12),"")) -> 0 | AB19: =IF($R19="Manual","",IFERROR(IF($R19="YOY Growth",$N19*(1+$T19)/12,$S19/12),"")) -> 0 | ... AF19: =IF($R19="Manual","",IFERROR(IF($R19="YOY Growth",$N19*(1+$T19)/12,$S19/12),"")) -> 0 | AG19: =SUM(U19:AF19) -> 0 | AH19: =IFERROR(AG19/AG$16,"") | AJ19: =N19-AG19 -> 0
A20: 5011 - SlipLift Depreciation | B20: 0 | C20: 0 | D20: 0 | E20: 0 | F20: 0 | G20: 0 | H20: 0 | I20: 0 | N20: =SUM(B20:M20) -> 0 | O20: =IFERROR(N20/N$16,"") | R20: Even | S20: 0 | T20: 0.05 | U20: =IF($R20="Manual","",IFERROR(IF($R20="YOY Growth",$N20*(1+$T20)/12,$S20/12),"")) -> 0 | V20: =IF($R20="Manual","",IFERROR(IF($R20="YOY Growth",$N20*(1+$T20)/12,$S20/12),"")) -> 0 | W20: =IF($R20="Manual","",IFERROR(IF($R20="YOY Growth",$N20*(1+$T20)/12,$S20/12),"")) -> 0 | X20: =IF($R20="Manual","",IFERROR(IF($R20="YOY Growth",$N20*(1+$T20)/12,$S20/12),"")) -> 0 | Y20: =IF($R20="Manual","",IFERROR(IF($R20="YOY Growth",$N20*(1+$T20)/12,$S20/12),"")) -> 0 | Z20: =IF($R20="Manual","",IFERROR(IF($R20="YOY Growth",$N20*(1+$T20)/12,$S20/12),"")) -> 0 | AA20: =IF($R20="Manual","",IFERROR(IF($R20="YOY Growth",$N20*(1+$T20)/12,$S20/12),"")) -> 0 | AB20: =IF($R20="Manual","",IFERROR(IF($R20="YOY Growth",$N20*(1+$T20)/12,$S20/12),"")) -> 0 | ... AF20: =IF($R20="Manual","",IFERROR(IF($R20="YOY Growth",$N20*(1+$T20)/12,$S20/12),"")) -> 0 | AG20: =SUM(U20:AF20) -> 0 | AH20: =IFERROR(AG20/AG$16,"") | AJ20: =N20-AG20 -> 0
A21: 5012 - SlipCarrier Depreciation | B21: 0 | C21: 0 | D21: 0 | E21: 0 | F21: 0 | G21: 0 | H21: 0 | I21: 0 | N21: =SUM(B21:M21) -> 0 | O21: =IFERROR(N21/N$16,"") | R21: Even | S21: 0 | T21: 0.05 | U21: =IF($R21="Manual","",IFERROR(IF($R21="YOY Growth",$N21*(1+$T21)/12,$S21/12),"")) -> 0 | V21: =IF($R21="Manual","",IFERROR(IF($R21="YOY Growth",$N21*(1+$T21)/12,$S21/12),"")) -> 0 | W21: =IF($R21="Manual","",IFERROR(IF($R21="YOY Growth",$N21*(1+$T21)/12,$S21/12),"")) -> 0 | X21: =IF($R21="Manual","",IFERROR(IF($R21="YOY Growth",$N21*(1+$T21)/12,$S21/12),"")) -> 0 | Y21: =IF($R21="Manual","",IFERROR(IF($R21="YOY Growth",$N21*(1+$T21)/12,$S21/12),"")) -> 0 | Z21: =IF($R21="Manual","",IFERROR(IF($R21="YOY Growth",$N21*(1+$T21)/12,$S21/12),"")) -> 0 | AA21: =IF($R21="Manual","",IFERROR(IF($R21="YOY Growth",$N21*(1+$T21)/12,$S21/12),"")) -> 0 | AB21: =IF($R21="Manual","",IFERROR(IF($R21="YOY Growth",$N21*(1+$T21)/12,$S21/12),"")) -> 0 | ... AF21: =IF($R21="Manual","",IFERROR(IF($R21="YOY Growth",$N21*(1+$T21)/12,$S21/12),"")) -> 0 | AG21: =SUM(U21:AF21) -> 0 | AH21: =IFERROR(AG21/AG$16,"") | AJ21: =N21-AG21 -> 0
A22: 5020 - Robot Peripherals Depreciation | B22: 0 | C22: 0 | D22: 0 | E22: 0 | F22: 0 | G22: 0 | H22: 0 | I22: 0 | N22: =SUM(B22:M22) -> 0 | O22: =IFERROR(N22/N$16,"") | R22: Even | S22: 0 | T22: 0.05 | U22: =IF($R22="Manual","",IFERROR(IF($R22="YOY Growth",$N22*(1+$T22)/12,$S22/12),"")) -> 0 | V22: =IF($R22="Manual","",IFERROR(IF($R22="YOY Growth",$N22*(1+$T22)/12,$S22/12),"")) -> 0 | W22: =IF($R22="Manual","",IFERROR(IF($R22="YOY Growth",$N22*(1+$T22)/12,$S22/12),"")) -> 0 | X22: =IF($R22="Manual","",IFERROR(IF($R22="YOY Growth",$N22*(1+$T22)/12,$S22/12),"")) -> 0 | Y22: =IF($R22="Manual","",IFERROR(IF($R22="YOY Growth",$N22*(1+$T22)/12,$S22/12),"")) -> 0 | Z22: =IF($R22="Manual","",IFERROR(IF($R22="YOY Growth",$N22*(1+$T22)/12,$S22/12),"")) -> 0 | AA22: =IF($R22="Manual","",IFERROR(IF($R22="YOY Growth",$N22*(1+$T22)/12,$S22/12),"")) -> 0 | AB22: =IF($R22="Manual","",IFERROR(IF($R22="YOY Growth",$N22*(1+$T22)/12,$S22/12),"")) -> 0 | ... AF22: =IF($R22="Manual","",IFERROR(IF($R22="YOY Growth",$N22*(1+$T22)/12,$S22/12),"")) -> 0 | AG22: =SUM(U22:AF22) -> 0 | AH22: =IFERROR(AG22/AG$16,"") | AJ22: =N22-AG22 -> 0
A23: 5025 - Freight and Delivery - Production (Summary)
A24: 5025 - Freight and Delivery - Production (Summary) | B24: 376 | C24: 850.7 | D24: 783.62 | E24: 1861.07 | F24: 0 | G24: 0 | H24: 0 | I24: 0 | J24: 0 | K24: 0 | L24: 0 | M24: 0 | N24: =SUM(B24:M24) -> 3871.39 | O24: =IFERROR(N24/N$16,"") | R24: Even | S24: 0 | T24: 0.05 | U24: =IF($R24="Manual","",IFERROR(IF($R24="YOY Growth",$N24*(1+$T24)/12,$S24/12),"")) -> 0 | V24: =IF($R24="Manual","",IFERROR(IF($R24="YOY Growth",$N24*(1+$T24)/12,$S24/12),"")) -> 0 | W24: =IF($R24="Manual","",IFERROR(IF($R24="YOY Growth",$N24*(1+$T24)/12,$S24/12),"")) -> 0 | X24: =IF($R24="Manual","",IFERROR(IF($R24="YOY Growth",$N24*(1+$T24)/12,$S24/12),"")) -> 0 | Y24: =IF($R24="Manual","",IFERROR(IF($R24="YOY Growth",$N24*(1+$T24)/12,$S24/12),"")) -> 0 | Z24: =IF($R24="Manual","",IFERROR(IF($R24="YOY Growth",$N24*(1+$T24)/12,$S24/12),"")) -> 0 | AA24: =IF($R24="Manual","",IFERROR(IF($R24="YOY Growth",$N24*(1+$T24)/12,$S24/12),"")) -> 0 | AB24: =IF($R24="Manual","",IFERROR(IF($R24="YOY Growth",$N24*(1+$T24)/12,$S24/12),"")) -> 0 | ... AF24: =IF($R24="Manual","",IFERROR(IF($R24="YOY Growth",$N24*(1+$T24)/12,$S24/12),"")) -> 0 | AG24: =SUM(U24:AF24) -> 0 | AH24: =IFERROR(AG24/AG$16,"") | AJ24: =N24-AG24 -> 3871.39
A25: 5026 - Freight and Delivery - Production - Expedited | B25: 0 | C25: 0 | D25: 0 | E25: 261.8 | F25: 0 | G25: 0 | H25: 0 | I25: 0 | J25: 0 | K25: 0 | L25: 0 | M25: 0 | N25: =SUM(B25:M25) -> 261.8 | O25: =IFERROR(N25/N$16,"") | R25: Even | S25: 0 | T25: 0.05 | U25: =IF($R25="Manual","",IFERROR(IF($R25="YOY Growth",$N25*(1+$T25)/12,$S25/12),"")) -> 0 | V25: =IF($R25="Manual","",IFERROR(IF($R25="YOY Growth",$N25*(1+$T25)/12,$S25/12),"")) -> 0 | W25: =IF($R25="Manual","",IFERROR(IF($R25="YOY Growth",$N25*(1+$T25)/12,$S25/12),"")) -> 0 | X25: =IF($R25="Manual","",IFERROR(IF($R25="YOY Growth",$N25*(1+$T25)/12,$S25/12),"")) -> 0 | Y25: =IF($R25="Manual","",IFERROR(IF($R25="YOY Growth",$N25*(1+$T25)/12,$S25/12),"")) -> 0 | Z25: =IF($R25="Manual","",IFERROR(IF($R25="YOY Growth",$N25*(1+$T25)/12,$S25/12),"")) -> 0 | AA25: =IF($R25="Manual","",IFERROR(IF($R25="YOY Growth",$N25*(1+$T25)/12,$S25/12),"")) -> 0 | AB25: =IF($R25="Manual","",IFERROR(IF($R25="YOY Growth",$N25*(1+$T25)/12,$S25/12),"")) -> 0 | ... AF25: =IF($R25="Manual","",IFERROR(IF($R25="YOY Growth",$N25*(1+$T25)/12,$S25/12),"")) -> 0 | AG25: =SUM(U25:AF25) -> 0 | AH25: =IFERROR(AG25/AG$16,"") | AJ25: =N25-AG25 -> 261.8
A26: 5027 - Freight and Delivery - Production - Standard | B26: 0 | C26: 0 | D26: 0 | E26: 348.38 | F26: 79.47 | G26: 0 | H26: 0 | I26: 250 | J26: 0 | K26: 0 | L26: 0 | M26: 0 | N26: =SUM(B26:M26) -> 677.85 | O26: =IFERROR(N26/N$16,"") | R26: Even | S26: 0 | T26: 0.05 | U26: =IF($R26="Manual","",IFERROR(IF($R26="YOY Growth",$N26*(1+$T26)/12,$S26/12),"")) -> 0 | V26: =IF($R26="Manual","",IFERROR(IF($R26="YOY Growth",$N26*(1+$T26)/12,$S26/12),"")) -> 0 | W26: =IF($R26="Manual","",IFERROR(IF($R26="YOY Growth",$N26*(1+$T26)/12,$S26/12),"")) -> 0 | X26: =IF($R26="Manual","",IFERROR(IF($R26="YOY Growth",$N26*(1+$T26)/12,$S26/12),"")) -> 0 | Y26: =IF($R26="Manual","",IFERROR(IF($R26="YOY Growth",$N26*(1+$T26)/12,$S26/12),"")) -> 0 | Z26: =IF($R26="Manual","",IFERROR(IF($R26="YOY Growth",$N26*(1+$T26)/12,$S26/12),"")) -> 0 | AA26: =IF($R26="Manual","",IFERROR(IF($R26="YOY Growth",$N26*(1+$T26)/12,$S26/12),"")) -> 0 | AB26: =IF($R26="Manual","",IFERROR(IF($R26="YOY Growth",$N26*(1+$T26)/12,$S26/12),"")) -> 0 | ... AF26: =IF($R26="Manual","",IFERROR(IF($R26="YOY Growth",$N26*(1+$T26)/12,$S26/12),"")) -> 0 | AG26: =SUM(U26:AF26) -> 0 | AH26: =IFERROR(AG26/AG$16,"") | AJ26: =N26-AG26 -> 677.85
A27: Total - 5025 - Freight and Delivery - Production (Summary) | B27: =SUM(B24:B26) -> 376 | C27: =SUM(C24:C26) -> 850.7 | D27: =SUM(D24:D26) -> 783.62 | E27: =SUM(E24:E26) -> 2471.25 | F27: =SUM(F24:F26) -> 79.47 | G27: =SUM(G24:G26) -> 0 | H27: =SUM(H24:H26) -> 0 | I27: =SUM(I24:I26) -> 250 | ... M27: =SUM(M24:M26) -> 0 | N27: =SUM(B27:M27) -> 4811.04 | O27: =IFERROR(N27/N$16,"") | U27: =SUM(U24:U26) -> 0 | V27: =SUM(V24:V26) -> 0 | W27: =SUM(W24:W26) -> 0 | X27: =SUM(X24:X26) -> 0 | Y27: =SUM(Y24:Y26) -> 0 | Z27: =SUM(Z24:Z26) -> 0 | AA27: =SUM(AA24:AA26) -> 0 | AB27: =SUM(AB24:AB26) -> 0 | ... AF27: =SUM(AF24:AF26) -> 0 | AG27: =SUM(U27:AF27) -> 0 | AH27: =IFERROR(AG27/AG$16,"") | AJ27: =N27-AG27 -> 4811.04
A28: 5030 - Production Tools and Supplies | B28: 0 | C28: 0 | D28: 0 | E28: 2186.18 | F28: 0 | G28: 0 | H28: 117.53 | I28: 0 | J28: 0 | K28: 0 | L28: 0 | M28: 0 | N28: =SUM(B28:M28) -> 2303.71 | O28: =IFERROR(N28/N$16,"") | R28: Even | S28: 0 | T28: 0.05 | U28: =IF($R28="Manual","",IFERROR(IF($R28="YOY Growth",$N28*(1+$T28)/12,$S28/12),"")) -> 0 | V28: =IF($R28="Manual","",IFERROR(IF($R28="YOY Growth",$N28*(1+$T28)/12,$S28/12),"")) -> 0 | W28: =IF($R28="Manual","",IFERROR(IF($R28="YOY Growth",$N28*(1+$T28)/12,$S28/12),"")) -> 0 | X28: =IF($R28="Manual","",IFERROR(IF($R28="YOY Growth",$N28*(1+$T28)/12,$S28/12),"")) -> 0 | Y28: =IF($R28="Manual","",IFERROR(IF($R28="YOY Growth",$N28*(1+$T28)/12,$S28/12),"")) -> 0 | Z28: =IF($R28="Manual","",IFERROR(IF($R28="YOY Growth",$N28*(1+$T28)/12,$S28/12),"")) -> 0 | AA28: =IF($R28="Manual","",IFERROR(IF($R28="YOY Growth",$N28*(1+$T28)/12,$S28/12),"")) -> 0 | AB28: =IF($R28="Manual","",IFERROR(IF($R28="YOY Growth",$N28*(1+$T28)/12,$S28/12),"")) -> 0 | ... AF28: =IF($R28="Manual","",IFERROR(IF($R28="YOY Growth",$N28*(1+$T28)/12,$S28/12),"")) -> 0 | AG28: =SUM(U28:AF28) -> 0 | AH28: =IFERROR(AG28/AG$16,"") | AJ28: =N28-AG28 -> 2303.71
A29: 5040 - Freight & Delivery - Deployment | B29: 7000 | C29: 5000.95 | D29: 3522.7 | E29: 3294.47 | F29: 0 | G29: 122.59 | H29: 0 | I29: 3240.99 | J29: 15000 | K29: 10000 | L29: 5000 | M29: 5000 | N29: =SUM(B29:M29) -> 57181.7 | O29: =IFERROR(N29/N$16,"") | R29: Manual | S29: 0 | T29: 0.05 | U29: ='Fld Maint Budget'!B89 -> 45000 | V29: ='Fld Maint Budget'!C89 -> 20000 | W29: ='Fld Maint Budget'!D89 -> 0 | X29: ='Fld Maint Budget'!E89 -> 60000 | Y29: ='Fld Maint Budget'!F89 -> 45000 | Z29: ='Fld Maint Budget'!G89 -> 70000 | AA29: ='Fld Maint Budget'!H89 -> 55000 | AB29: ='Fld Maint Budget'!I89 -> 65000 | ... AF29: ='Fld Maint Budget'!M89 -> 110000 | AG29: =SUM(U29:AF29) -> 765000 | AH29: =IFERROR(AG29/AG$16,"") | AJ29: =N29-AG29 -> -707818.3
A30: 5050 - Travel - Deployment | B30: 0 | C30: 0 | D30: 0 | E30: 0 | F30: 0 | G30: 0 | H30: 911.81 | I30: 1772.23 | J30: 0 | K30: 0 | L30: 0 | M30: 0 | N30: =SUM(B30:M30) -> 2684.04 | O30: =IFERROR(N30/N$16,"") | R30: Manual | S30: 0 | T30: 0.05 | U30: ='Fld Maint Budget'!B90 -> 2279.7 | V30: ='Fld Maint Budget'!C90 -> 1519.8 | W30: ='Fld Maint Budget'!D90 -> 0 | X30: ='Fld Maint Budget'!E90 -> 3495.54 | Y30: ='Fld Maint Budget'!F90 -> 2735.64 | Z30: ='Fld Maint Budget'!G90 -> 3951.48 | AA30: ='Fld Maint Budget'!H90 -> 3495.54 | AB30: ='Fld Maint Budget'!I90 -> 4255.44 | ... AF30: ='Fld Maint Budget'!M90 -> 6991.08 | AG30: =SUM(U30:AF30) -> 46353.9 | AH30: =IFERROR(AG30/AG$16,"") | AJ30: =N30-AG30 -> -43669.86
A31: 5060 - Meals - Deployment | B31: 0 | C31: 0 | D31: 0 | E31: 0 | F31: 0 | G31: 20.14 | H31: 0 | I31: 528.6 | J31: 0 | K31: 0 | L31: 0 | M31: 0 | N31: =SUM(B31:M31) -> 548.74 | O31: =IFERROR(N31/N$16,"") | R31: Even | S31: 0 | T31: 0.05 | U31: =IF($R31="Manual","",IFERROR(IF($R31="YOY Growth",$N31*(1+$T31)/12,$S31/12),"")) -> 0 | V31: =IF($R31="Manual","",IFERROR(IF($R31="YOY Growth",$N31*(1+$T31)/12,$S31/12),"")) -> 0 | W31: =IF($R31="Manual","",IFERROR(IF($R31="YOY Growth",$N31*(1+$T31)/12,$S31/12),"")) -> 0 | X31: =IF($R31="Manual","",IFERROR(IF($R31="YOY Growth",$N31*(1+$T31)/12,$S31/12),"")) -> 0 | Y31: =IF($R31="Manual","",IFERROR(IF($R31="YOY Growth",$N31*(1+$T31)/12,$S31/12),"")) -> 0 | Z31: =IF($R31="Manual","",IFERROR(IF($R31="YOY Growth",$N31*(1+$T31)/12,$S31/12),"")) -> 0 | AA31: =IF($R31="Manual","",IFERROR(IF($R31="YOY Growth",$N31*(1+$T31)/12,$S31/12),"")) -> 0 | AB31: =IF($R31="Manual","",IFERROR(IF($R31="YOY Growth",$N31*(1+$T31)/12,$S31/12),"")) -> 0 | ... AF31: =IF($R31="Manual","",IFERROR(IF($R31="YOY Growth",$N31*(1+$T31)/12,$S31/12),"")) -> 0 | AG31: =SUM(U31:AF31) -> 0 | AH31: =IFERROR(AG31/AG$16,"") | AJ31: =N31-AG31 -> 548.74
A32: 5100 - Labor Expense - Production
A33: 5110 - Salaries and Wages - Production | B33: 0 | C33: 0 | D33: 0 | E33: 0 | F33: 0 | G33: 0 | H33: 0 | I33: 0 | J33: 0 | K33: 0 | L33: 0 | M33: 0 | N33: =SUM(B33:M33) -> 0 | O33: =IFERROR(N33/N$16,"") | AG33: =SUM(U33:AF33) -> 0 | AH33: =IFERROR(AG33/AG$16,"") | AJ33: =N33-AG33 -> 0
A34: 5130 - Payroll Taxes - Production | B34: 0 | C34: 0 | D34: 0 | E34: 0 | F34: 0 | G34: 0 | H34: 0 | I34: 0 | J34: 0 | K34: 0 | L34: 0 | M34: 0 | N34: =SUM(B34:M34) -> 0 | O34: =IFERROR(N34/N$16,"") | AG34: =SUM(U34:AF34) -> 0 | AH34: =IFERROR(AG34/AG$16,"") | AJ34: =N34-AG34 -> 0
A35: 5140 - Benefits - Production | B35: 0 | C35: 0 | D35: 0 | E35: 0 | F35: 0 | G35: 0 | H35: 0 | I35: 0 | J35: 0 | K35: 0 | L35: 0 | M35: 0 | N35: =SUM(B35:M35) -> 0 | O35: =IFERROR(N35/N$16,"") | AG35: =SUM(U35:AF35) -> 0 | AH35: =IFERROR(AG35/AG$16,"") | AJ35: =N35-AG35 -> 0
A36: Total - 5100 - Labor Expense - Production | B36: =SUM(B33:B35) -> 0 | C36: =SUM(C33:C35) -> 0 | D36: =SUM(D33:D35) -> 0 | E36: =SUM(E33:E35) -> 0 | F36: =SUM(F33:F35) -> 0 | G36: =SUM(G33:G35) -> 0 | H36: =SUM(H33:H35) -> 0 | I36: =SUM(I33:I35) -> 0 | ... M36: =SUM(M33:M35) -> 0 | N36: =SUM(B36:M36) -> 0 | O36: =IFERROR(N36/N$16,"") | U36: =SUM(U33:U35) -> 0 | V36: =SUM(V33:V35) -> 0 | W36: =SUM(W33:W35) -> 0 | X36: =SUM(X33:X35) -> 0 | Y36: =SUM(Y33:Y35) -> 0 | Z36: =SUM(Z33:Z35) -> 0 | AA36: =SUM(AA33:AA35) -> 0 | AB36: =SUM(AB33:AB35) -> 0 | ... AF36: =SUM(AF33:AF35) -> 0 | AG36: =SUM(U36:AF36) -> 0 | AH36: =IFERROR(AG36/AG$16,"") | AJ36: =N36-AG36 -> 0
A37: Total - 5000 - Robot Production and Deployment | B37: =B19+B22+B27+B28+B29+B30+B31+B36+B20+B21 -> 7376 | C37: =C19+C22+C27+C28+C29+C30+C31+C36+C20+C21 -> 5851.65 | D37: =D19+D22+D27+D28+D29+D30+D31+D36+D20+D21 -> 4306.32 | E37: =E19+E22+E27+E28+E29+E30+E31+E36+E20+E21 -> 7951.9 | F37: =F19+F22+F27+F28+F29+F30+F31+F36+F20+F21 -> 79.47 | G37: =G19+G22+G27+G28+G29+G30+G31+G36+G20+G21 -> 142.73 | H37: =H19+H22+H27+H28+H29+H30+H31+H36+H20+H21 -> 1029.34 | I37: =I19+I22+I27+I28+I29+I30+I31+I36+I20+I21 -> 5791.82 | ... M37: =M19+M22+M27+M28+M29+M30+M31+M36+M20+M21 -> 5000 | N37: =SUM(B37:M37) -> 67529.23 | O37: =IFERROR(N37/N$16,"") | U37: =U19+U22+U27+U28+U29+U30+U31+U36+U20+U21 -> 47279.7 | V37: =V19+V22+V27+V28+V29+V30+V31+V36+V20+V21 -> 21519.8 | W37: =W19+W22+W27+W28+W29+W30+W31+W36+W20+W21 -> 0 | X37: =X19+X22+X27+X28+X29+X30+X31+X36+X20+X21 -> 63495.54 | Y37: =Y19+Y22+Y27+Y28+Y29+Y30+Y31+Y36+Y20+Y21 -> 47735.64 | Z37: =Z19+Z22+Z27+Z28+Z29+Z30+Z31+Z36+Z20+Z21 -> 73951.48 | AA37: =AA19+AA22+AA27+AA28+AA29+AA30+AA31+AA36+AA20+AA21 -> 58495.54 | AB37: =AB19+AB22+AB27+AB28+AB29+AB30+AB31+AB36+AB20+AB21 -> 69255.44 | ... AF37: =AF19+AF22+AF27+AF28+AF29+AF30+AF31+AF36+AF20+AF21 -> 116991.08 | AG37: =SUM(U37:AF37) -> 811353.9 | AH37: =IFERROR(AG37/AG$16,"") | AJ37: =N37-AG37 -> -743824.67
A38: 5015 - Supplies and Materials | B38: 0 | C38: 0 | D38: 0 | E38: 0 | F38: 0 | G38: -352.47 | H38: 0 | I38: 0 | J38: 0 | K38: 0 | L38: 0 | M38: 0 | N38: =SUM(B38:M38) -> -352.47 | O38: =IFERROR(N38/N$16,"") | R38: Even | S38: 0 | T38: 0.05 | U38: =IF($R38="Manual","",IFERROR(IF($R38="YOY Growth",$N38*(1+$T38)/12,$S38/12),"")) -> 0 | V38: =IF($R38="Manual","",IFERROR(IF($R38="YOY Growth",$N38*(1+$T38)/12,$S38/12),"")) -> 0 | W38: =IF($R38="Manual","",IFERROR(IF($R38="YOY Growth",$N38*(1+$T38)/12,$S38/12),"")) -> 0 | X38: =IF($R38="Manual","",IFERROR(IF($R38="YOY Growth",$N38*(1+$T38)/12,$S38/12),"")) -> 0 | Y38: =IF($R38="Manual","",IFERROR(IF($R38="YOY Growth",$N38*(1+$T38)/12,$S38/12),"")) -> 0 | Z38: =IF($R38="Manual","",IFERROR(IF($R38="YOY Growth",$N38*(1+$T38)/12,$S38/12),"")) -> 0 | AA38: =IF($R38="Manual","",IFERROR(IF($R38="YOY Growth",$N38*(1+$T38)/12,$S38/12),"")) -> 0 | AB38: =IF($R38="Manual","",IFERROR(IF($R38="YOY Growth",$N38*(1+$T38)/12,$S38/12),"")) -> 0 | ... AF38: =IF($R38="Manual","",IFERROR(IF($R38="YOY Growth",$N38*(1+$T38)/12,$S38/12),"")) -> 0 | AG38: =SUM(U38:AF38) -> 0 | AH38: =IFERROR(AG38/AG$16,"") | AJ38: =N38-AG38 -> -352.47
A39: 5028 - Duties & Tariffs - Production | B39: 0 | C39: 0 | D39: 0 | E39: 0 | F39: 0 | G39: 0 | H39: 0 | I39: 0 | J39: 0 | K39: 0 | L39: 0 | M39: 0 | N39: =SUM(B39:M39) -> 0 | O39: =IFERROR(N39/N$16,"") | R39: Even | S39: 0 | T39: 0.05 | U39: =IF($R39="Manual","",IFERROR(IF($R39="YOY Growth",$N39*(1+$T39)/12,$S39/12),"")) -> 0 | V39: =IF($R39="Manual","",IFERROR(IF($R39="YOY Growth",$N39*(1+$T39)/12,$S39/12),"")) -> 0 | W39: =IF($R39="Manual","",IFERROR(IF($R39="YOY Growth",$N39*(1+$T39)/12,$S39/12),"")) -> 0 | X39: =IF($R39="Manual","",IFERROR(IF($R39="YOY Growth",$N39*(1+$T39)/12,$S39/12),"")) -> 0 | Y39: =IF($R39="Manual","",IFERROR(IF($R39="YOY Growth",$N39*(1+$T39)/12,$S39/12),"")) -> 0 | Z39: =IF($R39="Manual","",IFERROR(IF($R39="YOY Growth",$N39*(1+$T39)/12,$S39/12),"")) -> 0 | AA39: =IF($R39="Manual","",IFERROR(IF($R39="YOY Growth",$N39*(1+$T39)/12,$S39/12),"")) -> 0 | AB39: =IF($R39="Manual","",IFERROR(IF($R39="YOY Growth",$N39*(1+$T39)/12,$S39/12),"")) -> 0 | ... AF39: =IF($R39="Manual","",IFERROR(IF($R39="YOY Growth",$N39*(1+$T39)/12,$S39/12),"")) -> 0 | AG39: =SUM(U39:AF39) -> 0 | AH39: =IFERROR(AG39/AG$16,"") | AJ39: =N39-AG39 -> 0
A40: 5029 - Processing Fee - Production | B40: 0 | C40: 0 | D40: 0 | E40: 0 | F40: 0 | G40: 0 | H40: 0 | I40: 0 | J40: 0 | K40: 0 | L40: 0 | M40: 0 | N40: =SUM(B40:M40) -> 0 | O40: =IFERROR(N40/N$16,"") | R40: Even | S40: 0 | T40: 0.05 | U40: =IF($R40="Manual","",IFERROR(IF($R40="YOY Growth",$N40*(1+$T40)/12,$S40/12),"")) -> 0 | V40: =IF($R40="Manual","",IFERROR(IF($R40="YOY Growth",$N40*(1+$T40)/12,$S40/12),"")) -> 0 | W40: =IF($R40="Manual","",IFERROR(IF($R40="YOY Growth",$N40*(1+$T40)/12,$S40/12),"")) -> 0 | X40: =IF($R40="Manual","",IFERROR(IF($R40="YOY Growth",$N40*(1+$T40)/12,$S40/12),"")) -> 0 | Y40: =IF($R40="Manual","",IFERROR(IF($R40="YOY Growth",$N40*(1+$T40)/12,$S40/12),"")) -> 0 | Z40: =IF($R40="Manual","",IFERROR(IF($R40="YOY Growth",$N40*(1+$T40)/12,$S40/12),"")) -> 0 | AA40: =IF($R40="Manual","",IFERROR(IF($R40="YOY Growth",$N40*(1+$T40)/12,$S40/12),"")) -> 0 | AB40: =IF($R40="Manual","",IFERROR(IF($R40="YOY Growth",$N40*(1+$T40)/12,$S40/12),"")) -> 0 | ... AF40: =IF($R40="Manual","",IFERROR(IF($R40="YOY Growth",$N40*(1+$T40)/12,$S40/12),"")) -> 0 | AG40: =SUM(U40:AF40) -> 0 | AH40: =IFERROR(AG40/AG$16,"") | AJ40: =N40-AG40 -> 0
A41: 5070 - Scrap | B41: 0 | C41: 0 | D41: 0 | E41: 0 | F41: 0 | G41: 0 | H41: 0 | I41: 0 | N41: =SUM(B41:M41) -> 0 | O41: =IFERROR(N41/N$16,"") | R41: Even | S41: 0 | T41: 0.05 | U41: =IF($R41="Manual","",IFERROR(IF($R41="YOY Growth",$N41*(1+$T41)/12,$S41/12),"")) -> 0 | V41: =IF($R41="Manual","",IFERROR(IF($R41="YOY Growth",$N41*(1+$T41)/12,$S41/12),"")) -> 0 | W41: =IF($R41="Manual","",IFERROR(IF($R41="YOY Growth",$N41*(1+$T41)/12,$S41/12),"")) -> 0 | X41: =IF($R41="Manual","",IFERROR(IF($R41="YOY Growth",$N41*(1+$T41)/12,$S41/12),"")) -> 0 | Y41: =IF($R41="Manual","",IFERROR(IF($R41="YOY Growth",$N41*(1+$T41)/12,$S41/12),"")) -> 0 | Z41: =IF($R41="Manual","",IFERROR(IF($R41="YOY Growth",$N41*(1+$T41)/12,$S41/12),"")) -> 0 | AA41: =IF($R41="Manual","",IFERROR(IF($R41="YOY Growth",$N41*(1+$T41)/12,$S41/12),"")) -> 0 | AB41: =IF($R41="Manual","",IFERROR(IF($R41="YOY Growth",$N41*(1+$T41)/12,$S41/12),"")) -> 0 | ... AF41: =IF($R41="Manual","",IFERROR(IF($R41="YOY Growth",$N41*(1+$T41)/12,$S41/12),"")) -> 0 | AG41: =SUM(U41:AF41) -> 0 | AH41: =IFERROR(AG41/AG$16,"") | AJ41: =N41-AG41 -> 0
A42: 5201 - Inventory Adjustments | B42: 0 | C42: 0 | D42: 0 | E42: 0 | F42: 0 | G42: 0 | H42: 0 | I42: 0 | J42: 0 | K42: 0 | L42: 0 | M42: 0 | N42: =SUM(B42:M42) -> 0 | O42: =IFERROR(N42/N$16,"") | R42: Even | S42: 0 | T42: 0.05 | U42: =IF($R42="Manual","",IFERROR(IF($R42="YOY Growth",$N42*(1+$T42)/12,$S42/12),"")) -> 0 | V42: =IF($R42="Manual","",IFERROR(IF($R42="YOY Growth",$N42*(1+$T42)/12,$S42/12),"")) -> 0 | W42: =IF($R42="Manual","",IFERROR(IF($R42="YOY Growth",$N42*(1+$T42)/12,$S42/12),"")) -> 0 | X42: =IF($R42="Manual","",IFERROR(IF($R42="YOY Growth",$N42*(1+$T42)/12,$S42/12),"")) -> 0 | Y42: =IF($R42="Manual","",IFERROR(IF($R42="YOY Growth",$N42*(1+$T42)/12,$S42/12),"")) -> 0 | Z42: =IF($R42="Manual","",IFERROR(IF($R42="YOY Growth",$N42*(1+$T42)/12,$S42/12),"")) -> 0 | AA42: =IF($R42="Manual","",IFERROR(IF($R42="YOY Growth",$N42*(1+$T42)/12,$S42/12),"")) -> 0 | AB42: =IF($R42="Manual","",IFERROR(IF($R42="YOY Growth",$N42*(1+$T42)/12,$S42/12),"")) -> 0 | ... AF42: =IF($R42="Manual","",IFERROR(IF($R42="YOY Growth",$N42*(1+$T42)/12,$S42/12),"")) -> 0 | AG42: =SUM(U42:AF42) -> 0 | AH42: =IFERROR(AG42/AG$16,"") | AJ42: =N42-AG42 -> 0
A43: 5300 - Maintenance
A44: 5310 - Contractors - Field | B44: 0 | C44: 0 | D44: 0 | E44: 0 | F44: 19808 | G44: 10009 | H44: 10968.52 | I44: 6116.47 | J44: 40350 | K44: 44270 | L44: 48190 | M44: 52110 | N44: =SUM(B44:M44) -> 231821.99 | O44: =IFERROR(N44/N$16,"") | R44: Manual | T44: 0.05 | U44: ='Fld Maint Budget'!B91 -> 37614 | V44: ='Fld Maint Budget'!C91 -> 37614 | W44: ='Fld Maint Budget'!D91 -> 50004 | X44: ='Fld Maint Budget'!E91 -> 50004 | Y44: ='Fld Maint Budget'!F91 -> 50004 | Z44: ='Fld Maint Budget'!G91 -> 50004 | AA44: ='Fld Maint Budget'!H91 -> 50004 | AB44: ='Fld Maint Budget'!I91 -> 50004 | ... AF44: ='Fld Maint Budget'!M91 -> 50004 | AG44: =SUM(U44:AF44) -> 575268 | AH44: =IFERROR(AG44/AG$16,"") | AJ44: =N44-AG44 -> -343446.01
...

Sheet FE
A1: Field Engineering
A2: 2026 Actuals/Forecast & 2027 Budget
B7: Actual | C7: Actual | D7: Actual | E7: Actual | F7: Actual | G7: Actual | H7: Actual | I7: Actual | J7: Forecast | K7: Forecast | L7: Forecast | M7: Forecast | N7: Forecast | O7: Forecast | S7: Annual Input | T7: YOY | U7: Budget | V7: Budget | W7: Budget | X7: Budget | Y7: Budget | Z7: Budget | AA7: Budget | AB7: Budget | AC7: Budget | AD7: Budget | AE7: Budget | AF7: Budget | AG7: Budget | AH7: Budget | AJ7: YOY
B8: Jan | C8: Feb | D8: Mar | E8: Apr | F8: May | G8: Jun | H8: Jul | I8: Aug | J8: Sep | K8: Oct | L8: Nov | M8: Dec | N8: 2026 | O8: % Total Rev | R8: Input Method | S8: "Even" spread | T8: Growth % | U8: Jan | V8: Feb | W8: Mar | X8: Apr | Y8: May | Z8: Jun | AA8: Jul | AB8: Aug | AC8: Sep | AD8: Oct | AE8: Nov | AF8: Dec | AG8: 2027 | AH8: % Total Rev | AJ8: Fav / (Unfav)
A9: Ordinary Income/Expense
A10: Income
A11: 4000 - Sales
A12: 4100 - Subscription/Platform Fees | B12: 0 | C12: 0 | D12: 0 | E12: 0 | F12: 0 | G12: 0 | H12: 0 | I12: 0 | N12: =SUM(B12:M12) -> 0 | O12: =IFERROR(N12/N$16,"") | R12: Even | T12: 0.05 | U12: =IF($R12="Manual","",IFERROR(IF($R12="YOY Growth",$N12*(1+$T12)/12,$S12/12),"")) -> 0 | V12: =IF($R12="Manual","",IFERROR(IF($R12="YOY Growth",$N12*(1+$T12)/12,$S12/12),"")) -> 0 | W12: =IF($R12="Manual","",IFERROR(IF($R12="YOY Growth",$N12*(1+$T12)/12,$S12/12),"")) -> 0 | X12: =IF($R12="Manual","",IFERROR(IF($R12="YOY Growth",$N12*(1+$T12)/12,$S12/12),"")) -> 0 | Y12: =IF($R12="Manual","",IFERROR(IF($R12="YOY Growth",$N12*(1+$T12)/12,$S12/12),"")) -> 0 | Z12: =IF($R12="Manual","",IFERROR(IF($R12="YOY Growth",$N12*(1+$T12)/12,$S12/12),"")) -> 0 | AA12: =IF($R12="Manual","",IFERROR(IF($R12="YOY Growth",$N12*(1+$T12)/12,$S12/12),"")) -> 0 | AB12: =IF($R12="Manual","",IFERROR(IF($R12="YOY Growth",$N12*(1+$T12)/12,$S12/12),"")) -> 0 | ... AF12: =IF($R12="Manual","",IFERROR(IF($R12="YOY Growth",$N12*(1+$T12)/12,$S12/12),"")) -> 0 | AG12: =SUM(U12:AF12) -> 0 | AH12: =IFERROR(AG12/AG$16,"") | AJ12: =AG12-N12 -> 0
A13: 4500 - Implementation Fees | B13: 0 | C13: 0 | D13: 0 | E13: 0 | F13: 0 | G13: 0 | H13: 0 | I13: 0 | N13: =SUM(B13:M13) -> 0 | O13: =IFERROR(N13/N$16,"") | R13: Even | S13: 0 | T13: 0.05 | U13: =IF($R13="Manual","",IFERROR(IF($R13="YOY Growth",$N13*(1+$T13)/12,$S13/12),"")) -> 0 | V13: =IF($R13="Manual","",IFERROR(IF($R13="YOY Growth",$N13*(1+$T13)/12,$S13/12),"")) -> 0 | W13: =IF($R13="Manual","",IFERROR(IF($R13="YOY Growth",$N13*(1+$T13)/12,$S13/12),"")) -> 0 | X13: =IF($R13="Manual","",IFERROR(IF($R13="YOY Growth",$N13*(1+$T13)/12,$S13/12),"")) -> 0 | Y13: =IF($R13="Manual","",IFERROR(IF($R13="YOY Growth",$N13*(1+$T13)/12,$S13/12),"")) -> 0 | Z13: =IF($R13="Manual","",IFERROR(IF($R13="YOY Growth",$N13*(1+$T13)/12,$S13/12),"")) -> 0 | AA13: =IF($R13="Manual","",IFERROR(IF($R13="YOY Growth",$N13*(1+$T13)/12,$S13/12),"")) -> 0 | AB13: =IF($R13="Manual","",IFERROR(IF($R13="YOY Growth",$N13*(1+$T13)/12,$S13/12),"")) -> 0 | ... AF13: =IF($R13="Manual","",IFERROR(IF($R13="YOY Growth",$N13*(1+$T13)/12,$S13/12),"")) -> 0 | AG13: =SUM(U13:AF13) -> 0 | AH13: =IFERROR(AG13/AG$16,"") | AJ13: =AG13-N13 -> 0
A14: Total - 4000 - Sales | B14: =SUM(B12:B13) -> 0 | C14: =SUM(C12:C13) -> 0 | D14: =SUM(D12:D13) -> 0 | E14: =SUM(E12:E13) -> 0 | F14: =SUM(F12:F13) -> 0 | G14: =SUM(G12:G13) -> 0 | H14: =SUM(H12:H13) -> 0 | I14: =SUM(I12:I13) -> 0 | ... M14: =SUM(M12:M13) -> 0 | N14: =SUM(B14:M14) -> 0 | O14: =SUM(O12:O13) -> 0 | U14: =SUM(U12:U13) -> 0 | V14: =SUM(V12:V13) -> 0 | W14: =SUM(W12:W13) -> 0 | X14: =SUM(X12:X13) -> 0 | Y14: =SUM(Y12:Y13) -> 0 | Z14: =SUM(Z12:Z13) -> 0 | AA14: =SUM(AA12:AA13) -> 0 | AB14: =SUM(AB12:AB13) -> 0 | ... AF14: =SUM(AF12:AF13) -> 0 | AG14: =SUM(U14:AF14) -> 0 | AH14: =SUM(AH12:AH13) -> 0 | AJ14: =AG14-N14 -> 0
A15: 4900 - One-Time Revenue | B15: 0 | C15: 0 | D15: 0 | E15: 0 | F15: 0 | G15: 0 | H15: 0 | I15: 0 | N15: =SUM(B15:M15) -> 0 | O15: =IFERROR(N15/N$16,"") | R15: Even | S15: 0 | T15: 0.05 | U15: =IF($R15="Manual","",IFERROR(IF($R15="YOY Growth",$N15*(1+$T15)/12,$S15/12),"")) -> 0 | V15: =IF($R15="Manual","",IFERROR(IF($R15="YOY Growth",$N15*(1+$T15)/12,$S15/12),"")) -> 0 | W15: =IF($R15="Manual","",IFERROR(IF($R15="YOY Growth",$N15*(1+$T15)/12,$S15/12),"")) -> 0 | X15: =IF($R15="Manual","",IFERROR(IF($R15="YOY Growth",$N15*(1+$T15)/12,$S15/12),"")) -> 0 | Y15: =IF($R15="Manual","",IFERROR(IF($R15="YOY Growth",$N15*(1+$T15)/12,$S15/12),"")) -> 0 | Z15: =IF($R15="Manual","",IFERROR(IF($R15="YOY Growth",$N15*(1+$T15)/12,$S15/12),"")) -> 0 | AA15: =IF($R15="Manual","",IFERROR(IF($R15="YOY Growth",$N15*(1+$T15)/12,$S15/12),"")) -> 0 | AB15: =IF($R15="Manual","",IFERROR(IF($R15="YOY Growth",$N15*(1+$T15)/12,$S15/12),"")) -> 0 | ... AF15: =IF($R15="Manual","",IFERROR(IF($R15="YOY Growth",$N15*(1+$T15)/12,$S15/12),"")) -> 0 | AG15: =SUM(U15:AF15) -> 0 | AH15: =IFERROR(AG15/AG$16,"") | AJ15: =AG15-N15 -> 0
A16: Total - Income | B16: =B14+B15 -> 0 | C16: =C14+C15 -> 0 | D16: =D14+D15 -> 0 | E16: =E14+E15 -> 0 | F16: =F14+F15 -> 0 | G16: =G14+G15 -> 0 | H16: =H14+H15 -> 0 | I16: =I14+I15 -> 0 | ... M16: =M14+M15 -> 0 | N16: =SUM(B16:M16) -> 0 | O16: =SUM(O14:O15) -> 0 | U16: =U14+U15 -> 0 | V16: =V14+V15 -> 0 | W16: =W14+W15 -> 0 | X16: =X14+X15 -> 0 | Y16: =Y14+Y15 -> 0 | Z16: =Z14+Z15 -> 0 | AA16: =AA14+AA15 -> 0 | AB16: =AB14+AB15 -> 0 | ... AF16: =AF14+AF15 -> 0 | AG16: =SUM(U16:AF16) -> 0 | AH16: =SUM(AH14:AH15) -> 0 | AJ16: =AG16-N16 -> 0
A17: Cost Of Sales
A18: 5000 - Robot Production and Deployment
A19: 5010 - SlipBot Depreciation | B19: 0 | C19: 0 | D19: 0 | E19: 0 | F19: 0 | G19: 0 | H19: 0 | I19: 0 | N19: =SUM(B19:M19) -> 0 | O19: =IFERROR(N19/N$16,"") | R19: Even | S19: 0 | T19: 0.05 | U19: =IF($R19="Manual","",IFERROR(IF($R19="YOY Growth",$N19*(1+$T19)/12,$S19/12),"")) -> 0 | V19: =IF($R19="Manual","",IFERROR(IF($R19="YOY Growth",$N19*(1+$T19)/12,$S19/12),"")) -> 0 | W19: =IF($R19="Manual","",IFERROR(IF($R19="YOY Growth",$N19*(1+$T19)/12,$S19/12),"")) -> 0 | X19: =IF($R19="Manual","",IFERROR(IF($R19="YOY Growth",$N19*(1+$T19)/12,$S19/12),"")) -> 0 | Y19: =IF($R19="Manual","",IFERROR(IF($R19="YOY Growth",$N19*(1+$T19)/12,$S19/12),"")) -> 0 | Z19: =IF($R19="Manual","",IFERROR(IF($R19="YOY Growth",$N19*(1+$T19)/12,$S19/12),"")) -> 0 | AA19: =IF($R19="Manual","",IFERROR(IF($R19="YOY Growth",$N19*(1+$T19)/12,$S19/12),"")) -> 0 | AB19: =IF($R19="Manual","",IFERROR(IF($R19="YOY Growth",$N19*(1+$T19)/12,$S19/12),"")) -> 0 | ... AF19: =IF($R19="Manual","",IFERROR(IF($R19="YOY Growth",$N19*(1+$T19)/12,$S19/12),"")) -> 0 | AG19: =SUM(U19:AF19) -> 0 | AH19: =IFERROR(AG19/AG$16,"") | AJ19: =N19-AG19 -> 0
A20: 5011 - SlipLift Depreciation | B20: 0 | C20: 0 | D20: 0 | E20: 0 | F20: 0 | G20: 0 | H20: 0 | I20: 0 | N20: =SUM(B20:M20) -> 0 | O20: =IFERROR(N20/N$16,"") | R20: Even | S20: 0 | T20: 0.05 | U20: =IF($R20="Manual","",IFERROR(IF($R20="YOY Growth",$N20*(1+$T20)/12,$S20/12),"")) -> 0 | V20: =IF($R20="Manual","",IFERROR(IF($R20="YOY Growth",$N20*(1+$T20)/12,$S20/12),"")) -> 0 | W20: =IF($R20="Manual","",IFERROR(IF($R20="YOY Growth",$N20*(1+$T20)/12,$S20/12),"")) -> 0 | X20: =IF($R20="Manual","",IFERROR(IF($R20="YOY Growth",$N20*(1+$T20)/12,$S20/12),"")) -> 0 | Y20: =IF($R20="Manual","",IFERROR(IF($R20="YOY Growth",$N20*(1+$T20)/12,$S20/12),"")) -> 0 | Z20: =IF($R20="Manual","",IFERROR(IF($R20="YOY Growth",$N20*(1+$T20)/12,$S20/12),"")) -> 0 | AA20: =IF($R20="Manual","",IFERROR(IF($R20="YOY Growth",$N20*(1+$T20)/12,$S20/12),"")) -> 0 | AB20: =IF($R20="Manual","",IFERROR(IF($R20="YOY Growth",$N20*(1+$T20)/12,$S20/12),"")) -> 0 | ... AF20: =IF($R20="Manual","",IFERROR(IF($R20="YOY Growth",$N20*(1+$T20)/12,$S20/12),"")) -> 0 | AG20: =SUM(U20:AF20) -> 0 | AH20: =IFERROR(AG20/AG$16,"") | AJ20: =N20-AG20 -> 0
A21: 5012 - SlipCarrier Depreciation | B21: 0 | C21: 0 | D21: 0 | E21: 0 | F21: 0 | G21: 0 | H21: 0 | I21: 0 | N21: =SUM(B21:M21) -> 0 | O21: =IFERROR(N21/N$16,"") | R21: Even | S21: 0 | T21: 0.05 | U21: =IF($R21="Manual","",IFERROR(IF($R21="YOY Growth",$N21*(1+$T21)/12,$S21/12),"")) -> 0 | V21: =IF($R21="Manual","",IFERROR(IF($R21="YOY Growth",$N21*(1+$T21)/12,$S21/12),"")) -> 0 | W21: =IF($R21="Manual","",IFERROR(IF($R21="YOY Growth",$N21*(1+$T21)/12,$S21/12),"")) -> 0 | X21: =IF($R21="Manual","",IFERROR(IF($R21="YOY Growth",$N21*(1+$T21)/12,$S21/12),"")) -> 0 | Y21: =IF($R21="Manual","",IFERROR(IF($R21="YOY Growth",$N21*(1+$T21)/12,$S21/12),"")) -> 0 | Z21: =IF($R21="Manual","",IFERROR(IF($R21="YOY Growth",$N21*(1+$T21)/12,$S21/12),"")) -> 0 | AA21: =IF($R21="Manual","",IFERROR(IF($R21="YOY Growth",$N21*(1+$T21)/12,$S21/12),"")) -> 0 | AB21: =IF($R21="Manual","",IFERROR(IF($R21="YOY Growth",$N21*(1+$T21)/12,$S21/12),"")) -> 0 | ... AF21: =IF($R21="Manual","",IFERROR(IF($R21="YOY Growth",$N21*(1+$T21)/12,$S21/12),"")) -> 0 | AG21: =SUM(U21:AF21) -> 0 | AH21: =IFERROR(AG21/AG$16,"") | AJ21: =N21-AG21 -> 0
A22: 5020 - Robot Peripherals Depreciation | B22: 0 | C22: 0 | D22: 0 | E22: 0 | F22: 0 | G22: 0 | H22: 0 | I22: 0 | N22: =SUM(B22:M22) -> 0 | O22: =IFERROR(N22/N$16,"") | R22: Even | S22: 0 | T22: 0.05 | U22: =IF($R22="Manual","",IFERROR(IF($R22="YOY Growth",$N22*(1+$T22)/12,$S22/12),"")) -> 0 | V22: =IF($R22="Manual","",IFERROR(IF($R22="YOY Growth",$N22*(1+$T22)/12,$S22/12),"")) -> 0 | W22: =IF($R22="Manual","",IFERROR(IF($R22="YOY Growth",$N22*(1+$T22)/12,$S22/12),"")) -> 0 | X22: =IF($R22="Manual","",IFERROR(IF($R22="YOY Growth",$N22*(1+$T22)/12,$S22/12),"")) -> 0 | Y22: =IF($R22="Manual","",IFERROR(IF($R22="YOY Growth",$N22*(1+$T22)/12,$S22/12),"")) -> 0 | Z22: =IF($R22="Manual","",IFERROR(IF($R22="YOY Growth",$N22*(1+$T22)/12,$S22/12),"")) -> 0 | AA22: =IF($R22="Manual","",IFERROR(IF($R22="YOY Growth",$N22*(1+$T22)/12,$S22/12),"")) -> 0 | AB22: =IF($R22="Manual","",IFERROR(IF($R22="YOY Growth",$N22*(1+$T22)/12,$S22/12),"")) -> 0 | ... AF22: =IF($R22="Manual","",IFERROR(IF($R22="YOY Growth",$N22*(1+$T22)/12,$S22/12),"")) -> 0 | AG22: =SUM(U22:AF22) -> 0 | AH22: =IFERROR(AG22/AG$16,"") | AJ22: =N22-AG22 -> 0
A23: 5025 - Freight and Delivery - Production (Summary)
